<robot name = "robot">
    <link name="Part0">
        <inertial>
            <origin xyz="0 0 0.32" rpy="0 0 0"/>
            <mass value="1" />
            <inertia ixx="100" ixy="0" ixz="0" iyy="100" iyz="0" izz="100" />
        </inertial>
        <visual>
            <origin xyz="0 0 0.32" rpy="0 0 0"/>
            <geometry>
                <box size="0.29 0.89 0.25" />
            </geometry>
            <material name="Green">
                <color rgba="0.0 1.0 0.0 1.0"/>
            </material>
        </visual>
        <collision>
            <origin xyz="0 0 0.32" rpy="0 0 0"/>
            <geometry>
                <box size="0.29 0.89 0.25" />
            </geometry>
        </collision>
    </link>
    <joint name="Part0_Part1" type="revolute">
       <parent link="Part0"/>
       <child  link="Part1"/>
       <origin rpy="0 0 0" xyz="-0.145 0.0 0.32" />
     <axis xyz="0 0 1"/>
       <limit effort="0.0" lower="-3.14159" upper="3.14159" velocity="0.0"/>
    </joint>
    <link name="Part1">
        <inertial>
            <origin xyz="-0.325 0.0 0.0" rpy="0 0 0"/>
            <mass value="1" />
            <inertia ixx="100" ixy="0" ixz="0" iyy="100" iyz="0" izz="100" />
        </inertial>
        <visual>
            <origin xyz="-0.325 0.0 0.0" rpy="0 0 0"/>
            <geometry>
                <box size="0.65 0.88 0.64" />
            </geometry>
            <material name="Green">
                <color rgba="0.0 1.0 0.0 1.0"/>
            </material>
        </visual>
        <collision>
            <origin xyz="-0.325 0.0 0.0" rpy="0 0 0"/>
            <geometry>
                <box size="0.65 0.88 0.64" />
            </geometry>
        </collision>
    </link>
    <joint name="Part0_Part2" type="revolute">
       <parent link="Part0"/>
       <child  link="Part2"/>
       <origin rpy="0 0 0" xyz="0.145 0.0 0.32" />
     <axis xyz="0 0 1"/>
       <limit effort="0.0" lower="-3.14159" upper="3.14159" velocity="0.0"/>
    </joint>
    <link name="Part2">
        <inertial>
            <origin xyz="0.325 0.0 0.0" rpy="0 0 0"/>
            <mass value="1" />
            <inertia ixx="100" ixy="0" ixz="0" iyy="100" iyz="0" izz="100" />
        </inertial>
        <visual>
            <origin xyz="0.325 0.0 0.0" rpy="0 0 0"/>
            <geometry>
                <box size="0.65 0.88 0.64" />
            </geometry>
            <material name="Green">
                <color rgba="0.0 1.0 0.0 1.0"/>
            </material>
        </visual>
        <collision>
            <origin xyz="0.325 0.0 0.0" rpy="0 0 0"/>
            <geometry>
                <box size="0.65 0.88 0.64" />
            </geometry>
        </collision>
    </link>
</robot>