<robot name = "robot">
    <link name="Part0">
        <inertial>
            <origin xyz="0 0 1.65" rpy="0 0 0"/>
            <mass value="1" />
            <inertia ixx="100" ixy="0" ixz="0" iyy="100" iyz="0" izz="100" />
        </inertial>
        <visual>
            <origin xyz="0 0 1.65" rpy="0 0 0"/>
            <geometry>
                <box size="0.74 0.45 0.26" />
            </geometry>
            <material name="Green">
                <color rgba="0.0 1.0 0.0 1.0"/>
            </material>
        </visual>
        <collision>
            <origin xyz="0 0 1.65" rpy="0 0 0"/>
            <geometry>
                <box size="0.74 0.45 0.26" />
            </geometry>
        </collision>
    </link>
    <joint name="Part0_Part1" type="revolute">
       <parent link="Part0"/>
       <child  link="Part1"/>
       <origin rpy="0 0 0" xyz="0.0 0.0 1.52" />
     <axis xyz="0 0 1"/>
       <limit effort="0.0" lower="-3.14159" upper="3.14159" velocity="0.0"/>
    </joint>
    <link name="Part1">
        <inertial>
            <origin xyz="0.0 0.0 -0.455" rpy="0 0 0"/>
            <mass value="1" />
            <inertia ixx="100" ixy="0" ixz="0" iyy="100" iyz="0" izz="100" />
        </inertial>
        <visual>
            <origin xyz="0.0 0.0 -0.455" rpy="0 0 0"/>
            <geometry>
                <box size="0.72 0.6 0.91" />
            </geometry>
            <material name="Green">
                <color rgba="0.0 1.0 0.0 1.0"/>
            </material>
        </visual>
        <collision>
            <origin xyz="0.0 0.0 -0.455" rpy="0 0 0"/>
            <geometry>
                <box size="0.72 0.6 0.91" />
            </geometry>
        </collision>
    </link>
    <joint name="Part1_Part2" type="revolute">
       <parent link="Part1"/>
       <child  link="Part2"/>
       <origin rpy="0 0 0" xyz="-0.36 0.0 -0.455" />
     <axis xyz="1 0 0"/>
       <limit effort="0.0" lower="-3.14159" upper="3.14159" velocity="0.0"/>
    </joint>
    <link name="Part2">
        <inertial>
            <origin xyz="-0.405 0.0 0.0" rpy="0 0 0"/>
            <mass value="1" />
            <inertia ixx="100" ixy="0" ixz="0" iyy="100" iyz="0" izz="100" />
        </inertial>
        <visual>
            <origin xyz="-0.405 0.0 0.0" rpy="0 0 0"/>
            <geometry>
                <box size="0.81 0.97 0.96" />
            </geometry>
            <material name="Blue">
                <color rgba="0.0 0.5 1.0 1.0"/>
            </material>
        </visual>
        <collision>
            <origin xyz="-0.405 0.0 0.0" rpy="0 0 0"/>
            <geometry>
                <box size="0.81 0.97 0.96" />
            </geometry>
        </collision>
    </link>
    <joint name="Part1_Part3" type="revolute">
       <parent link="Part1"/>
       <child  link="Part3"/>
       <origin rpy="0 0 0" xyz="0.0 0.3 -0.455" />
     <axis xyz="1 0 0"/>
       <limit effort="0.0" lower="-3.14159" upper="3.14159" velocity="0.0"/>
    </joint>
    <link name="Part3">
        <inertial>
            <origin xyz="0.0 0.34 0.0" rpy="0 0 0"/>
            <mass value="1" />
            <inertia ixx="100" ixy="0" ixz="0" iyy="100" iyz="0" izz="100" />
        </inertial>
        <visual>
            <origin xyz="0.0 0.34 0.0" rpy="0 0 0"/>
            <geometry>
                <box size="0.49 0.68 0.4" />
            </geometry>
            <material name="Blue">
                <color rgba="0.0 0.5 1.0 1.0"/>
            </material>
        </visual>
        <collision>
            <origin xyz="0.0 0.34 0.0" rpy="0 0 0"/>
            <geometry>
                <box size="0.49 0.68 0.4" />
            </geometry>
        </collision>
    </link>
    <joint name="Part2_Part4" type="revolute">
       <parent link="Part2"/>
       <child  link="Part4"/>
       <origin rpy="0 0 0" xyz="-0.405 0.0 0.48" />
     <axis xyz="1 0 0"/>
       <limit effort="0.0" lower="-3.14159" upper="3.14159" velocity="0.0"/>
    </joint>
    <link name="Part4">
        <inertial>
            <origin xyz="0.0 0.0 0.29" rpy="0 0 0"/>
            <mass value="1" />
            <inertia ixx="100" ixy="0" ixz="0" iyy="100" iyz="0" izz="100" />
        </inertial>
        <visual>
            <origin xyz="0.0 0.0 0.29" rpy="0 0 0"/>
            <geometry>
                <box size="0.95 0.85 0.58" />
            </geometry>
            <material name="Green">
                <color rgba="0.0 1.0 0.0 1.0"/>
            </material>
        </visual>
        <collision>
            <origin xyz="0.0 0.0 0.29" rpy="0 0 0"/>
            <geometry>
                <box size="0.95 0.85 0.58" />
            </geometry>
        </collision>
    </link>
    <joint name="Part2_Part5" type="revolute">
       <parent link="Part2"/>
       <child  link="Part5"/>
       <origin rpy="0 0 0" xyz="-0.405 0.0 0.48" />
     <axis xyz="0 0 1"/>
       <limit effort="0.0" lower="-3.14159" upper="3.14159" velocity="0.0"/>
    </joint>
    <link name="Part5">
        <inertial>
            <origin xyz="0.0 0.0 0.495" rpy="0 0 0"/>
            <mass value="1" />
            <inertia ixx="100" ixy="0" ixz="0" iyy="100" iyz="0" izz="100" />
        </inertial>
        <visual>
            <origin xyz="0.0 0.0 0.495" rpy="0 0 0"/>
            <geometry>
                <box size="0.47 0.83 0.99" />
            </geometry>
            <material name="Blue">
                <color rgba="0.0 0.5 1.0 1.0"/>
            </material>
        </visual>
        <collision>
            <origin xyz="0.0 0.0 0.495" rpy="0 0 0"/>
            <geometry>
                <box size="0.47 0.83 0.99" />
            </geometry>
        </collision>
    </link>
    <joint name="Part3_Part6" type="revolute">
       <parent link="Part3"/>
       <child  link="Part6"/>
       <origin rpy="0 0 0" xyz="0.0 0.68 0.0" />
     <axis xyz="0 0 1"/>
       <limit effort="0.0" lower="-3.14159" upper="3.14159" velocity="0.0"/>
    </joint>
    <link name="Part6">
        <inertial>
            <origin xyz="0.0 0.44 0.0" rpy="0 0 0"/>
            <mass value="1" />
            <inertia ixx="100" ixy="0" ixz="0" iyy="100" iyz="0" izz="100" />
        </inertial>
        <visual>
            <origin xyz="0.0 0.44 0.0" rpy="0 0 0"/>
            <geometry>
                <box size="0.44 0.88 0.75" />
            </geometry>
            <material name="Blue">
                <color rgba="0.0 0.5 1.0 1.0"/>
            </material>
        </visual>
        <collision>
            <origin xyz="0.0 0.44 0.0" rpy="0 0 0"/>
            <geometry>
                <box size="0.44 0.88 0.75" />
            </geometry>
        </collision>
    </link>
    <joint name="Part1_Part7" type="revolute">
       <parent link="Part1"/>
       <child  link="Part7"/>
       <origin rpy="0 0 0" xyz="0.0 0.0 -0.91" />
     <axis xyz="1 0 0"/>
       <limit effort="0.0" lower="-3.14159" upper="3.14159" velocity="0.0"/>
    </joint>
    <link name="Part7">
        <inertial>
            <origin xyz="0.0 0.0 -0.305" rpy="0 0 0"/>
            <mass value="1" />
            <inertia ixx="100" ixy="0" ixz="0" iyy="100" iyz="0" izz="100" />
        </inertial>
        <visual>
            <origin xyz="0.0 0.0 -0.305" rpy="0 0 0"/>
            <geometry>
                <box size="0.86 0.72 0.61" />
            </geometry>
            <material name="Green">
                <color rgba="0.0 1.0 0.0 1.0"/>
            </material>
        </visual>
        <collision>
            <origin xyz="0.0 0.0 -0.305" rpy="0 0 0"/>
            <geometry>
                <box size="0.86 0.72 0.61" />
            </geometry>
        </collision>
    </link>
    <joint name="Part4_Part8" type="revolute">
       <parent link="Part4"/>
       <child  link="Part8"/>
       <origin rpy="0 0 0" xyz="0.475 0.0 0.29" />
     <axis xyz="0 0 1"/>
       <limit effort="0.0" lower="-3.14159" upper="3.14159" velocity="0.0"/>
    </joint>
    <link name="Part8">
        <inertial>
            <origin xyz="0.415 0.0 0.0" rpy="0 0 0"/>
            <mass value="1" />
            <inertia ixx="100" ixy="0" ixz="0" iyy="100" iyz="0" izz="100" />
        </inertial>
        <visual>
            <origin xyz="0.415 0.0 0.0" rpy="0 0 0"/>
            <geometry>
                <box size="0.83 0.34 0.34" />
            </geometry>
            <material name="Blue">
                <color rgba="0.0 0.5 1.0 1.0"/>
            </material>
        </visual>
        <collision>
            <origin xyz="0.415 0.0 0.0" rpy="0 0 0"/>
            <geometry>
                <box size="0.83 0.34 0.34" />
            </geometry>
        </collision>
    </link>
    <joint name="Part2_Part9" type="revolute">
       <parent link="Part2"/>
       <child  link="Part9"/>
       <origin rpy="0 0 0" xyz="-0.405 -0.485 0.0" />
     <axis xyz="0 0 1"/>
       <limit effort="0.0" lower="-3.14159" upper="3.14159" velocity="0.0"/>
    </joint>
    <link name="Part9">
        <inertial>
            <origin xyz="0.0 -0.44 0.0" rpy="0 0 0"/>
            <mass value="1" />
            <inertia ixx="100" ixy="0" ixz="0" iyy="100" iyz="0" izz="100" />
        </inertial>
        <visual>
            <origin xyz="0.0 -0.44 0.0" rpy="0 0 0"/>
            <geometry>
                <box size="0.72 0.88 0.36" />
            </geometry>
            <material name="Blue">
                <color rgba="0.0 0.5 1.0 1.0"/>
            </material>
        </visual>
        <collision>
            <origin xyz="0.0 -0.44 0.0" rpy="0 0 0"/>
            <geometry>
                <box size="0.72 0.88 0.36" />
            </geometry>
        </collision>
    </link>
</robot>