<robot name = "robot">
    <link name="Part0">
        <inertial>
            <origin xyz="0 0 1.175" rpy="0 0 0"/>
            <mass value="1" />
            <inertia ixx="100" ixy="0" ixz="0" iyy="100" iyz="0" izz="100" />
        </inertial>
        <visual>
            <origin xyz="0 0 1.175" rpy="0 0 0"/>
            <geometry>
                <box size="0.37 0.48 0.62" />
            </geometry>
            <material name="Green">
                <color rgba="0.0 1.0 0.0 1.0"/>
            </material>
        </visual>
        <collision>
            <origin xyz="0 0 1.175" rpy="0 0 0"/>
            <geometry>
                <box size="0.37 0.48 0.62" />
            </geometry>
        </collision>
    </link>
    <joint name="Part0_Part1" type="revolute">
       <parent link="Part0"/>
       <child  link="Part1"/>
       <origin rpy="0 0 0" xyz="-0.185 0.0 1.175" />
     <axis xyz="0 1 0"/>
       <limit effort="0.0" lower="-3.14159" upper="3.14159" velocity="0.0"/>
    </joint>
    <link name="Part1">
        <inertial>
            <origin xyz="-0.445 0.0 0.0" rpy="0 0 0"/>
            <mass value="1" />
            <inertia ixx="100" ixy="0" ixz="0" iyy="100" iyz="0" izz="100" />
        </inertial>
        <visual>
            <origin xyz="-0.445 0.0 0.0" rpy="0 0 0"/>
            <geometry>
                <box size="0.89 0.49 0.63" />
            </geometry>
            <material name="Green">
                <color rgba="0.0 1.0 0.0 1.0"/>
            </material>
        </visual>
        <collision>
            <origin xyz="-0.445 0.0 0.0" rpy="0 0 0"/>
            <geometry>
                <box size="0.89 0.49 0.63" />
            </geometry>
        </collision>
    </link>
    <joint name="Part0_Part2" type="revolute">
       <parent link="Part0"/>
       <child  link="Part2"/>
       <origin rpy="0 0 0" xyz="0.185 0.0 1.175" />
     <axis xyz="0 1 0"/>
       <limit effort="0.0" lower="-3.14159" upper="3.14159" velocity="0.0"/>
    </joint>
    <link name="Part2">
        <inertial>
            <origin xyz="0.445 0.0 0.0" rpy="0 0 0"/>
            <mass value="1" />
            <inertia ixx="100" ixy="0" ixz="0" iyy="100" iyz="0" izz="100" />
        </inertial>
        <visual>
            <origin xyz="0.445 0.0 0.0" rpy="0 0 0"/>
            <geometry>
                <box size="0.89 0.49 0.63" />
            </geometry>
            <material name="Green">
                <color rgba="0.0 1.0 0.0 1.0"/>
            </material>
        </visual>
        <collision>
            <origin xyz="0.445 0.0 0.0" rpy="0 0 0"/>
            <geometry>
                <box size="0.89 0.49 0.63" />
            </geometry>
        </collision>
    </link>
    <joint name="Part1_Part3" type="revolute">
       <parent link="Part1"/>
       <child  link="Part3"/>
       <origin rpy="0 0 0" xyz="-0.445 0.0 0.315" />
     <axis xyz="0 0 1"/>
       <limit effort="0.0" lower="-3.14159" upper="3.14159" velocity="0.0"/>
    </joint>
    <link name="Part3">
        <inertial>
            <origin xyz="0.0 0.0 0.365" rpy="0 0 0"/>
            <mass value="1" />
            <inertia ixx="100" ixy="0" ixz="0" iyy="100" iyz="0" izz="100" />
        </inertial>
        <visual>
            <origin xyz="0.0 0.0 0.365" rpy="0 0 0"/>
            <geometry>
                <box size="0.59 0.37 0.73" />
            </geometry>
            <material name="Blue">
                <color rgba="0.0 0.5 1.0 1.0"/>
            </material>
        </visual>
        <collision>
            <origin xyz="0.0 0.0 0.365" rpy="0 0 0"/>
            <geometry>
                <box size="0.59 0.37 0.73" />
            </geometry>
        </collision>
    </link>
    <joint name="Part2_Part4" type="revolute">
       <parent link="Part2"/>
       <child  link="Part4"/>
       <origin rpy="0 0 0" xyz="0.445 0.0 0.315" />
     <axis xyz="0 0 1"/>
       <limit effort="0.0" lower="-3.14159" upper="3.14159" velocity="0.0"/>
    </joint>
    <link name="Part4">
        <inertial>
            <origin xyz="0.0 0.0 0.365" rpy="0 0 0"/>
            <mass value="1" />
            <inertia ixx="100" ixy="0" ixz="0" iyy="100" iyz="0" izz="100" />
        </inertial>
        <visual>
            <origin xyz="0.0 0.0 0.365" rpy="0 0 0"/>
            <geometry>
                <box size="0.59 0.37 0.73" />
            </geometry>
            <material name="Blue">
                <color rgba="0.0 0.5 1.0 1.0"/>
            </material>
        </visual>
        <collision>
            <origin xyz="0.0 0.0 0.365" rpy="0 0 0"/>
            <geometry>
                <box size="0.59 0.37 0.73" />
            </geometry>
        </collision>
    </link>
    <joint name="Part1_Part5" type="revolute">
       <parent link="Part1"/>
       <child  link="Part5"/>
       <origin rpy="0 0 0" xyz="-0.445 0.0 -0.315" />
     <axis xyz="1 0 0"/>
       <limit effort="0.0" lower="-3.14159" upper="3.14159" velocity="0.0"/>
    </joint>
    <link name="Part5">
        <inertial>
            <origin xyz="0.0 0.0 -0.43" rpy="0 0 0"/>
            <mass value="1" />
            <inertia ixx="100" ixy="0" ixz="0" iyy="100" iyz="0" izz="100" />
        </inertial>
        <visual>
            <origin xyz="0.0 0.0 -0.43" rpy="0 0 0"/>
            <geometry>
                <box size="0.65 0.88 0.86" />
            </geometry>
            <material name="Green">
                <color rgba="0.0 1.0 0.0 1.0"/>
            </material>
        </visual>
        <collision>
            <origin xyz="0.0 0.0 -0.43" rpy="0 0 0"/>
            <geometry>
                <box size="0.65 0.88 0.86" />
            </geometry>
        </collision>
    </link>
    <joint name="Part2_Part6" type="revolute">
       <parent link="Part2"/>
       <child  link="Part6"/>
       <origin rpy="0 0 0" xyz="0.445 0.0 -0.315" />
     <axis xyz="1 0 0"/>
       <limit effort="0.0" lower="-3.14159" upper="3.14159" velocity="0.0"/>
    </joint>
    <link name="Part6">
        <inertial>
            <origin xyz="0.0 0.0 -0.43" rpy="0 0 0"/>
            <mass value="1" />
            <inertia ixx="100" ixy="0" ixz="0" iyy="100" iyz="0" izz="100" />
        </inertial>
        <visual>
            <origin xyz="0.0 0.0 -0.43" rpy="0 0 0"/>
            <geometry>
                <box size="0.65 0.88 0.86" />
            </geometry>
            <material name="Green">
                <color rgba="0.0 1.0 0.0 1.0"/>
            </material>
        </visual>
        <collision>
            <origin xyz="0.0 0.0 -0.43" rpy="0 0 0"/>
            <geometry>
                <box size="0.65 0.88 0.86" />
            </geometry>
        </collision>
    </link>
    <joint name="Part5_Part7" type="revolute">
       <parent link="Part5"/>
       <child  link="Part7"/>
       <origin rpy="0 0 0" xyz="-0.325 0.0 -0.43" />
     <axis xyz="0 0 1"/>
       <limit effort="0.0" lower="-3.14159" upper="3.14159" velocity="0.0"/>
    </joint>
    <link name="Part7">
        <inertial>
            <origin xyz="-0.13 0.0 0.0" rpy="0 0 0"/>
            <mass value="1" />
            <inertia ixx="100" ixy="0" ixz="0" iyy="100" iyz="0" izz="100" />
        </inertial>
        <visual>
            <origin xyz="-0.13 0.0 0.0" rpy="0 0 0"/>
            <geometry>
                <box size="0.26 0.59 0.79" />
            </geometry>
            <material name="Blue">
                <color rgba="0.0 0.5 1.0 1.0"/>
            </material>
        </visual>
        <collision>
            <origin xyz="-0.13 0.0 0.0" rpy="0 0 0"/>
            <geometry>
                <box size="0.26 0.59 0.79" />
            </geometry>
        </collision>
    </link>
    <joint name="Part6_Part8" type="revolute">
       <parent link="Part6"/>
       <child  link="Part8"/>
       <origin rpy="0 0 0" xyz="0.325 0.0 -0.43" />
     <axis xyz="0 0 1"/>
       <limit effort="0.0" lower="-3.14159" upper="3.14159" velocity="0.0"/>
    </joint>
    <link name="Part8">
        <inertial>
            <origin xyz="0.13 0.0 0.0" rpy="0 0 0"/>
            <mass value="1" />
            <inertia ixx="100" ixy="0" ixz="0" iyy="100" iyz="0" izz="100" />
        </inertial>
        <visual>
            <origin xyz="0.13 0.0 0.0" rpy="0 0 0"/>
            <geometry>
                <box size="0.26 0.59 0.79" />
            </geometry>
            <material name="Blue">
                <color rgba="0.0 0.5 1.0 1.0"/>
            </material>
        </visual>
        <collision>
            <origin xyz="0.13 0.0 0.0" rpy="0 0 0"/>
            <geometry>
                <box size="0.26 0.59 0.79" />
            </geometry>
        </collision>
    </link>
</robot>