<robot name = "robot">
    <link name="Part0">
        <inertial>
            <origin xyz="0 0 0.49" rpy="0 0 0"/>
            <mass value="1" />
            <inertia ixx="100" ixy="0" ixz="0" iyy="100" iyz="0" izz="100" />
        </inertial>
        <visual>
            <origin xyz="0 0 0.49" rpy="0 0 0"/>
            <geometry>
                <box size="0.65 0.63 0.43" />
            </geometry>
            <material name="Blue">
                <color rgba="0.0 0.5 1.0 1.0"/>
            </material>
        </visual>
        <collision>
            <origin xyz="0 0 0.49" rpy="0 0 0"/>
            <geometry>
                <box size="0.65 0.63 0.43" />
            </geometry>
        </collision>
    </link>
    <joint name="Part0_Part1" type="revolute">
       <parent link="Part0"/>
       <child  link="Part1"/>
       <origin rpy="0 0 0" xyz="0.0 -0.315 0.49" />
     <axis xyz="1 0 0"/>
       <limit effort="0.0" lower="-3.14159" upper="3.14159" velocity="0.0"/>
    </joint>
    <link name="Part1">
        <inertial>
            <origin xyz="0.0 -0.24 0.0" rpy="0 0 0"/>
            <mass value="1" />
            <inertia ixx="100" ixy="0" ixz="0" iyy="100" iyz="0" izz="100" />
        </inertial>
        <visual>
            <origin xyz="0.0 -0.24 0.0" rpy="0 0 0"/>
            <geometry>
                <box size="0.85 0.48 0.98" />
            </geometry>
            <material name="Green">
                <color rgba="0.0 1.0 0.0 1.0"/>
            </material>
        </visual>
        <collision>
            <origin xyz="0.0 -0.24 0.0" rpy="0 0 0"/>
            <geometry>
                <box size="0.85 0.48 0.98" />
            </geometry>
        </collision>
    </link>
</robot>