<robot name = "robot">
    <link name="Part0">
        <inertial>
            <origin xyz="0 0 0.425" rpy="0 0 0"/>
            <mass value="1" />
            <inertia ixx="100" ixy="0" ixz="0" iyy="100" iyz="0" izz="100" />
        </inertial>
        <visual>
            <origin xyz="0 0 0.425" rpy="0 0 0"/>
            <geometry>
                <box size="0.5 0.25 0.77" />
            </geometry>
            <material name="Green">
                <color rgba="0.0 1.0 0.0 1.0"/>
            </material>
        </visual>
        <collision>
            <origin xyz="0 0 0.425" rpy="0 0 0"/>
            <geometry>
                <box size="0.5 0.25 0.77" />
            </geometry>
        </collision>
    </link>
    <joint name="Part0_Part1" type="revolute">
       <parent link="Part0"/>
       <child  link="Part1"/>
       <origin rpy="0 0 0" xyz="0.25 0.0 0.425" />
     <axis xyz="1 0 0"/>
       <limit effort="0.0" lower="-3.14159" upper="3.14159" velocity="0.0"/>
    </joint>
    <link name="Part1">
        <inertial>
            <origin xyz="0.365 0.0 0.0" rpy="0 0 0"/>
            <mass value="1" />
            <inertia ixx="100" ixy="0" ixz="0" iyy="100" iyz="0" izz="100" />
        </inertial>
        <visual>
            <origin xyz="0.365 0.0 0.0" rpy="0 0 0"/>
            <geometry>
                <box size="0.73 0.87 0.42" />
            </geometry>
            <material name="Blue">
                <color rgba="0.0 0.5 1.0 1.0"/>
            </material>
        </visual>
        <collision>
            <origin xyz="0.365 0.0 0.0" rpy="0 0 0"/>
            <geometry>
                <box size="0.73 0.87 0.42" />
            </geometry>
        </collision>
    </link>
    <joint name="Part1_Part2" type="revolute">
       <parent link="Part1"/>
       <child  link="Part2"/>
       <origin rpy="0 0 0" xyz="0.73 0.0 0.0" />
     <axis xyz="0 0 1"/>
       <limit effort="0.0" lower="-3.14159" upper="3.14159" velocity="0.0"/>
    </joint>
    <link name="Part2">
        <inertial>
            <origin xyz="0.48 0.0 0.0" rpy="0 0 0"/>
            <mass value="1" />
            <inertia ixx="100" ixy="0" ixz="0" iyy="100" iyz="0" izz="100" />
        </inertial>
        <visual>
            <origin xyz="0.48 0.0 0.0" rpy="0 0 0"/>
            <geometry>
                <box size="0.96 0.6 0.42" />
            </geometry>
            <material name="Green">
                <color rgba="0.0 1.0 0.0 1.0"/>
            </material>
        </visual>
        <collision>
            <origin xyz="0.48 0.0 0.0" rpy="0 0 0"/>
            <geometry>
                <box size="0.96 0.6 0.42" />
            </geometry>
        </collision>
    </link>
    <joint name="Part2_Part3" type="revolute">
       <parent link="Part2"/>
       <child  link="Part3"/>
       <origin rpy="0 0 0" xyz="0.48 0.0 0.21" />
     <axis xyz="0 1 0"/>
       <limit effort="0.0" lower="-3.14159" upper="3.14159" velocity="0.0"/>
    </joint>
    <link name="Part3">
        <inertial>
            <origin xyz="0.0 0.0 0.165" rpy="0 0 0"/>
            <mass value="1" />
            <inertia ixx="100" ixy="0" ixz="0" iyy="100" iyz="0" izz="100" />
        </inertial>
        <visual>
            <origin xyz="0.0 0.0 0.165" rpy="0 0 0"/>
            <geometry>
                <box size="0.62 0.4 0.33" />
            </geometry>
            <material name="Blue">
                <color rgba="0.0 0.5 1.0 1.0"/>
            </material>
        </visual>
        <collision>
            <origin xyz="0.0 0.0 0.165" rpy="0 0 0"/>
            <geometry>
                <box size="0.62 0.4 0.33" />
            </geometry>
        </collision>
    </link>
    <joint name="Part0_Part4" type="revolute">
       <parent link="Part0"/>
       <child  link="Part4"/>
       <origin rpy="0 0 0" xyz="-0.25 0.0 0.425" />
     <axis xyz="0 0 1"/>
       <limit effort="0.0" lower="-3.14159" upper="3.14159" velocity="0.0"/>
    </joint>
    <link name="Part4">
        <inertial>
            <origin xyz="-0.18 0.0 0.0" rpy="0 0 0"/>
            <mass value="1" />
            <inertia ixx="100" ixy="0" ixz="0" iyy="100" iyz="0" izz="100" />
        </inertial>
        <visual>
            <origin xyz="-0.18 0.0 0.0" rpy="0 0 0"/>
            <geometry>
                <box size="0.36 0.44 0.67" />
            </geometry>
            <material name="Blue">
                <color rgba="0.0 0.5 1.0 1.0"/>
            </material>
        </visual>
        <collision>
            <origin xyz="-0.18 0.0 0.0" rpy="0 0 0"/>
            <geometry>
                <box size="0.36 0.44 0.67" />
            </geometry>
        </collision>
    </link>
    <joint name="Part2_Part5" type="revolute">
       <parent link="Part2"/>
       <child  link="Part5"/>
       <origin rpy="0 0 0" xyz="0.96 0.0 0.0" />
     <axis xyz="0 1 0"/>
       <limit effort="0.0" lower="-3.14159" upper="3.14159" velocity="0.0"/>
    </joint>
    <link name="Part5">
        <inertial>
            <origin xyz="0.16 0.0 0.0" rpy="0 0 0"/>
            <mass value="1" />
            <inertia ixx="100" ixy="0" ixz="0" iyy="100" iyz="0" izz="100" />
        </inertial>
        <visual>
            <origin xyz="0.16 0.0 0.0" rpy="0 0 0"/>
            <geometry>
                <box size="0.32 0.75 0.85" />
            </geometry>
            <material name="Blue">
                <color rgba="0.0 0.5 1.0 1.0"/>
            </material>
        </visual>
        <collision>
            <origin xyz="0.16 0.0 0.0" rpy="0 0 0"/>
            <geometry>
                <box size="0.32 0.75 0.85" />
            </geometry>
        </collision>
    </link>
    <joint name="Part3_Part6" type="revolute">
       <parent link="Part3"/>
       <child  link="Part6"/>
       <origin rpy="0 0 0" xyz="0.0 0.0 0.33" />
     <axis xyz="0 0 1"/>
       <limit effort="0.0" lower="-3.14159" upper="3.14159" velocity="0.0"/>
    </joint>
    <link name="Part6">
        <inertial>
            <origin xyz="0.0 0.0 0.31" rpy="0 0 0"/>
            <mass value="1" />
            <inertia ixx="100" ixy="0" ixz="0" iyy="100" iyz="0" izz="100" />
        </inertial>
        <visual>
            <origin xyz="0.0 0.0 0.31" rpy="0 0 0"/>
            <geometry>
                <box size="0.54 0.82 0.62" />
            </geometry>
            <material name="Green">
                <color rgba="0.0 1.0 0.0 1.0"/>
            </material>
        </visual>
        <collision>
            <origin xyz="0.0 0.0 0.31" rpy="0 0 0"/>
            <geometry>
                <box size="0.54 0.82 0.62" />
            </geometry>
        </collision>
    </link>
    <joint name="Part5_Part7" type="revolute">
       <parent link="Part5"/>
       <child  link="Part7"/>
       <origin rpy="0 0 0" xyz="0.16 0.375 0.0" />
     <axis xyz="0 1 0"/>
       <limit effort="0.0" lower="-3.14159" upper="3.14159" velocity="0.0"/>
    </joint>
    <link name="Part7">
        <inertial>
            <origin xyz="0.0 0.17 0.0" rpy="0 0 0"/>
            <mass value="1" />
            <inertia ixx="100" ixy="0" ixz="0" iyy="100" iyz="0" izz="100" />
        </inertial>
        <visual>
            <origin xyz="0.0 0.17 0.0" rpy="0 0 0"/>
            <geometry>
                <box size="0.48 0.34 0.76" />
            </geometry>
            <material name="Blue">
                <color rgba="0.0 0.5 1.0 1.0"/>
            </material>
        </visual>
        <collision>
            <origin xyz="0.0 0.17 0.0" rpy="0 0 0"/>
            <geometry>
                <box size="0.48 0.34 0.76" />
            </geometry>
        </collision>
    </link>
    <joint name="Part0_Part8" type="revolute">
       <parent link="Part0"/>
       <child  link="Part8"/>
       <origin rpy="0 0 0" xyz="0.0 0.0 0.81" />
     <axis xyz="1 0 0"/>
       <limit effort="0.0" lower="-3.14159" upper="3.14159" velocity="0.0"/>
    </joint>
    <link name="Part8">
        <inertial>
            <origin xyz="0.0 0.0 0.255" rpy="0 0 0"/>
            <mass value="1" />
            <inertia ixx="100" ixy="0" ixz="0" iyy="100" iyz="0" izz="100" />
        </inertial>
        <visual>
            <origin xyz="0.0 0.0 0.255" rpy="0 0 0"/>
            <geometry>
                <box size="0.85 0.98 0.51" />
            </geometry>
            <material name="Blue">
                <color rgba="0.0 0.5 1.0 1.0"/>
            </material>
        </visual>
        <collision>
            <origin xyz="0.0 0.0 0.255" rpy="0 0 0"/>
            <geometry>
                <box size="0.85 0.98 0.51" />
            </geometry>
        </collision>
    </link>
    <joint name="Part7_Part9" type="revolute">
       <parent link="Part7"/>
       <child  link="Part9"/>
       <origin rpy="0 0 0" xyz="0.0 0.34 0.0" />
     <axis xyz="0 0 1"/>
       <limit effort="0.0" lower="-3.14159" upper="3.14159" velocity="0.0"/>
    </joint>
    <link name="Part9">
        <inertial>
            <origin xyz="0.0 0.395 0.0" rpy="0 0 0"/>
            <mass value="1" />
            <inertia ixx="100" ixy="0" ixz="0" iyy="100" iyz="0" izz="100" />
        </inertial>
        <visual>
            <origin xyz="0.0 0.395 0.0" rpy="0 0 0"/>
            <geometry>
                <box size="0.39 0.79 0.72" />
            </geometry>
            <material name="Green">
                <color rgba="0.0 1.0 0.0 1.0"/>
            </material>
        </visual>
        <collision>
            <origin xyz="0.0 0.395 0.0" rpy="0 0 0"/>
            <geometry>
                <box size="0.39 0.79 0.72" />
            </geometry>
        </collision>
    </link>
    <joint name="Part5_Part10" type="revolute">
       <parent link="Part5"/>
       <child  link="Part10"/>
       <origin rpy="0 0 0" xyz="0.16 -0.375 0.0" />
     <axis xyz="1 0 0"/>
       <limit effort="0.0" lower="-3.14159" upper="3.14159" velocity="0.0"/>
    </joint>
    <link name="Part10">
        <inertial>
            <origin xyz="0.0 -0.41 0.0" rpy="0 0 0"/>
            <mass value="1" />
            <inertia ixx="100" ixy="0" ixz="0" iyy="100" iyz="0" izz="100" />
        </inertial>
        <visual>
            <origin xyz="0.0 -0.41 0.0" rpy="0 0 0"/>
            <geometry>
                <box size="0.97 0.82 0.29" />
            </geometry>
            <material name="Blue">
                <color rgba="0.0 0.5 1.0 1.0"/>
            </material>
        </visual>
        <collision>
            <origin xyz="0.0 -0.41 0.0" rpy="0 0 0"/>
            <geometry>
                <box size="0.97 0.82 0.29" />
            </geometry>
        </collision>
    </link>
    <joint name="Part8_Part11" type="revolute">
       <parent link="Part8"/>
       <child  link="Part11"/>
       <origin rpy="0 0 0" xyz="0.0 0.49 0.255" />
     <axis xyz="1 0 0"/>
       <limit effort="0.0" lower="-3.14159" upper="3.14159" velocity="0.0"/>
    </joint>
    <link name="Part11">
        <inertial>
            <origin xyz="0.0 0.195 0.0" rpy="0 0 0"/>
            <mass value="1" />
            <inertia ixx="100" ixy="0" ixz="0" iyy="100" iyz="0" izz="100" />
        </inertial>
        <visual>
            <origin xyz="0.0 0.195 0.0" rpy="0 0 0"/>
            <geometry>
                <box size="0.32 0.39 0.88" />
            </geometry>
            <material name="Blue">
                <color rgba="0.0 0.5 1.0 1.0"/>
            </material>
        </visual>
        <collision>
            <origin xyz="0.0 0.195 0.0" rpy="0 0 0"/>
            <geometry>
                <box size="0.32 0.39 0.88" />
            </geometry>
        </collision>
    </link>
</robot>