<robot name = "robot">
    <link name="Part0">
        <inertial>
            <origin xyz="0 0 1.5949999999999998" rpy="0 0 0"/>
            <mass value="1" />
            <inertia ixx="100" ixy="0" ixz="0" iyy="100" iyz="0" izz="100" />
        </inertial>
        <visual>
            <origin xyz="0 0 1.5949999999999998" rpy="0 0 0"/>
            <geometry>
                <box size="0.58 0.29 0.25" />
            </geometry>
            <material name="Blue">
                <color rgba="0.0 0.5 1.0 1.0"/>
            </material>
        </visual>
        <collision>
            <origin xyz="0 0 1.5949999999999998" rpy="0 0 0"/>
            <geometry>
                <box size="0.58 0.29 0.25" />
            </geometry>
        </collision>
    </link>
    <joint name="Part0_Part1" type="revolute">
       <parent link="Part0"/>
       <child  link="Part1"/>
       <origin rpy="0 0 0" xyz="0.0 0.145 1.5949999999999998" />
     <axis xyz="0 1 0"/>
       <limit effort="0.0" lower="-3.14159" upper="3.14159" velocity="0.0"/>
    </joint>
    <link name="Part1">
        <inertial>
            <origin xyz="0.0 0.325 0.0" rpy="0 0 0"/>
            <mass value="1" />
            <inertia ixx="100" ixy="0" ixz="0" iyy="100" iyz="0" izz="100" />
        </inertial>
        <visual>
            <origin xyz="0.0 0.325 0.0" rpy="0 0 0"/>
            <geometry>
                <box size="0.72 0.65 0.27" />
            </geometry>
            <material name="Green">
                <color rgba="0.0 1.0 0.0 1.0"/>
            </material>
        </visual>
        <collision>
            <origin xyz="0.0 0.325 0.0" rpy="0 0 0"/>
            <geometry>
                <box size="0.72 0.65 0.27" />
            </geometry>
        </collision>
    </link>
    <joint name="Part1_Part2" type="revolute">
       <parent link="Part1"/>
       <child  link="Part2"/>
       <origin rpy="0 0 0" xyz="0.36 0.325 0.0" />
     <axis xyz="0 0 1"/>
       <limit effort="0.0" lower="-3.14159" upper="3.14159" velocity="0.0"/>
    </joint>
    <link name="Part2">
        <inertial>
            <origin xyz="0.4 0.0 0.0" rpy="0 0 0"/>
            <mass value="1" />
            <inertia ixx="100" ixy="0" ixz="0" iyy="100" iyz="0" izz="100" />
        </inertial>
        <visual>
            <origin xyz="0.4 0.0 0.0" rpy="0 0 0"/>
            <geometry>
                <box size="0.8 0.81 0.72" />
            </geometry>
            <material name="Blue">
                <color rgba="0.0 0.5 1.0 1.0"/>
            </material>
        </visual>
        <collision>
            <origin xyz="0.4 0.0 0.0" rpy="0 0 0"/>
            <geometry>
                <box size="0.8 0.81 0.72" />
            </geometry>
        </collision>
    </link>
    <joint name="Part0_Part3" type="revolute">
       <parent link="Part0"/>
       <child  link="Part3"/>
       <origin rpy="0 0 0" xyz="0.0 -0.145 1.5949999999999998" />
     <axis xyz="0 1 0"/>
       <limit effort="0.0" lower="-3.14159" upper="3.14159" velocity="0.0"/>
    </joint>
    <link name="Part3">
        <inertial>
            <origin xyz="0.0 -0.275 0.0" rpy="0 0 0"/>
            <mass value="1" />
            <inertia ixx="100" ixy="0" ixz="0" iyy="100" iyz="0" izz="100" />
        </inertial>
        <visual>
            <origin xyz="0.0 -0.275 0.0" rpy="0 0 0"/>
            <geometry>
                <box size="0.56 0.55 0.93" />
            </geometry>
            <material name="Green">
                <color rgba="0.0 1.0 0.0 1.0"/>
            </material>
        </visual>
        <collision>
            <origin xyz="0.0 -0.275 0.0" rpy="0 0 0"/>
            <geometry>
                <box size="0.56 0.55 0.93" />
            </geometry>
        </collision>
    </link>
    <joint name="Part1_Part4" type="revolute">
       <parent link="Part1"/>
       <child  link="Part4"/>
       <origin rpy="0 0 0" xyz="-0.36 0.325 0.0" />
     <axis xyz="0 0 1"/>
       <limit effort="0.0" lower="-3.14159" upper="3.14159" velocity="0.0"/>
    </joint>
    <link name="Part4">
        <inertial>
            <origin xyz="-0.435 0.0 0.0" rpy="0 0 0"/>
            <mass value="1" />
            <inertia ixx="100" ixy="0" ixz="0" iyy="100" iyz="0" izz="100" />
        </inertial>
        <visual>
            <origin xyz="-0.435 0.0 0.0" rpy="0 0 0"/>
            <geometry>
                <box size="0.87 0.35 0.43" />
            </geometry>
            <material name="Blue">
                <color rgba="0.0 0.5 1.0 1.0"/>
            </material>
        </visual>
        <collision>
            <origin xyz="-0.435 0.0 0.0" rpy="0 0 0"/>
            <geometry>
                <box size="0.87 0.35 0.43" />
            </geometry>
        </collision>
    </link>
    <joint name="Part2_Part5" type="revolute">
       <parent link="Part2"/>
       <child  link="Part5"/>
       <origin rpy="0 0 0" xyz="0.4 0.0 -0.36" />
     <axis xyz="1 0 0"/>
       <limit effort="0.0" lower="-3.14159" upper="3.14159" velocity="0.0"/>
    </joint>
    <link name="Part5">
        <inertial>
            <origin xyz="0.0 0.0 -0.365" rpy="0 0 0"/>
            <mass value="1" />
            <inertia ixx="100" ixy="0" ixz="0" iyy="100" iyz="0" izz="100" />
        </inertial>
        <visual>
            <origin xyz="0.0 0.0 -0.365" rpy="0 0 0"/>
            <geometry>
                <box size="0.26 0.67 0.73" />
            </geometry>
            <material name="Blue">
                <color rgba="0.0 0.5 1.0 1.0"/>
            </material>
        </visual>
        <collision>
            <origin xyz="0.0 0.0 -0.365" rpy="0 0 0"/>
            <geometry>
                <box size="0.26 0.67 0.73" />
            </geometry>
        </collision>
    </link>
    <joint name="Part5_Part6" type="revolute">
       <parent link="Part5"/>
       <child  link="Part6"/>
       <origin rpy="0 0 0" xyz="0.13 0.0 -0.365" />
     <axis xyz="1 0 0"/>
       <limit effort="0.0" lower="-3.14159" upper="3.14159" velocity="0.0"/>
    </joint>
    <link name="Part6">
        <inertial>
            <origin xyz="0.335 0.0 0.0" rpy="0 0 0"/>
            <mass value="1" />
            <inertia ixx="100" ixy="0" ixz="0" iyy="100" iyz="0" izz="100" />
        </inertial>
        <visual>
            <origin xyz="0.335 0.0 0.0" rpy="0 0 0"/>
            <geometry>
                <box size="0.67 0.93 0.49" />
            </geometry>
            <material name="Green">
                <color rgba="0.0 1.0 0.0 1.0"/>
            </material>
        </visual>
        <collision>
            <origin xyz="0.335 0.0 0.0" rpy="0 0 0"/>
            <geometry>
                <box size="0.67 0.93 0.49" />
            </geometry>
        </collision>
    </link>
    <joint name="Part4_Part7" type="revolute">
       <parent link="Part4"/>
       <child  link="Part7"/>
       <origin rpy="0 0 0" xyz="-0.435 0.0 -0.215" />
     <axis xyz="1 0 0"/>
       <limit effort="0.0" lower="-3.14159" upper="3.14159" velocity="0.0"/>
    </joint>
    <link name="Part7">
        <inertial>
            <origin xyz="0.0 0.0 -0.415" rpy="0 0 0"/>
            <mass value="1" />
            <inertia ixx="100" ixy="0" ixz="0" iyy="100" iyz="0" izz="100" />
        </inertial>
        <visual>
            <origin xyz="0.0 0.0 -0.415" rpy="0 0 0"/>
            <geometry>
                <box size="0.82 0.97 0.83" />
            </geometry>
            <material name="Blue">
                <color rgba="0.0 0.5 1.0 1.0"/>
            </material>
        </visual>
        <collision>
            <origin xyz="0.0 0.0 -0.415" rpy="0 0 0"/>
            <geometry>
                <box size="0.82 0.97 0.83" />
            </geometry>
        </collision>
    </link>
    <joint name="Part4_Part8" type="revolute">
       <parent link="Part4"/>
       <child  link="Part8"/>
       <origin rpy="0 0 0" xyz="-0.87 0.0 0.0" />
     <axis xyz="0 1 0"/>
       <limit effort="0.0" lower="-3.14159" upper="3.14159" velocity="0.0"/>
    </joint>
    <link name="Part8">
        <inertial>
            <origin xyz="-0.22 0.0 0.0" rpy="0 0 0"/>
            <mass value="1" />
            <inertia ixx="100" ixy="0" ixz="0" iyy="100" iyz="0" izz="100" />
        </inertial>
        <visual>
            <origin xyz="-0.22 0.0 0.0" rpy="0 0 0"/>
            <geometry>
                <box size="0.44 0.63 0.66" />
            </geometry>
            <material name="Blue">
                <color rgba="0.0 0.5 1.0 1.0"/>
            </material>
        </visual>
        <collision>
            <origin xyz="-0.22 0.0 0.0" rpy="0 0 0"/>
            <geometry>
                <box size="0.44 0.63 0.66" />
            </geometry>
        </collision>
    </link>
    <joint name="Part3_Part9" type="revolute">
       <parent link="Part3"/>
       <child  link="Part9"/>
       <origin rpy="0 0 0" xyz="0.0 -0.55 0.0" />
     <axis xyz="0 1 0"/>
       <limit effort="0.0" lower="-3.14159" upper="3.14159" velocity="0.0"/>
    </joint>
    <link name="Part9">
        <inertial>
            <origin xyz="0.0 -0.445 0.0" rpy="0 0 0"/>
            <mass value="1" />
            <inertia ixx="100" ixy="0" ixz="0" iyy="100" iyz="0" izz="100" />
        </inertial>
        <visual>
            <origin xyz="0.0 -0.445 0.0" rpy="0 0 0"/>
            <geometry>
                <box size="0.77 0.89 0.95" />
            </geometry>
            <material name="Blue">
                <color rgba="0.0 0.5 1.0 1.0"/>
            </material>
        </visual>
        <collision>
            <origin xyz="0.0 -0.445 0.0" rpy="0 0 0"/>
            <geometry>
                <box size="0.77 0.89 0.95" />
            </geometry>
        </collision>
    </link>
    <joint name="Part7_Part10" type="revolute">
       <parent link="Part7"/>
       <child  link="Part10"/>
       <origin rpy="0 0 0" xyz="0.0 0.0 -0.83" />
     <axis xyz="0 0 1"/>
       <limit effort="0.0" lower="-3.14159" upper="3.14159" velocity="0.0"/>
    </joint>
    <link name="Part10">
        <inertial>
            <origin xyz="0.0 0.0 -0.275" rpy="0 0 0"/>
            <mass value="1" />
            <inertia ixx="100" ixy="0" ixz="0" iyy="100" iyz="0" izz="100" />
        </inertial>
        <visual>
            <origin xyz="0.0 0.0 -0.275" rpy="0 0 0"/>
            <geometry>
                <box size="0.63 0.86 0.55" />
            </geometry>
            <material name="Green">
                <color rgba="0.0 1.0 0.0 1.0"/>
            </material>
        </visual>
        <collision>
            <origin xyz="0.0 0.0 -0.275" rpy="0 0 0"/>
            <geometry>
                <box size="0.63 0.86 0.55" />
            </geometry>
        </collision>
    </link>
    <joint name="Part7_Part11" type="revolute">
       <parent link="Part7"/>
       <child  link="Part11"/>
       <origin rpy="0 0 0" xyz="0.0 0.485 -0.415" />
     <axis xyz="0 0 1"/>
       <limit effort="0.0" lower="-3.14159" upper="3.14159" velocity="0.0"/>
    </joint>
    <link name="Part11">
        <inertial>
            <origin xyz="0.0 0.365 0.0" rpy="0 0 0"/>
            <mass value="1" />
            <inertia ixx="100" ixy="0" ixz="0" iyy="100" iyz="0" izz="100" />
        </inertial>
        <visual>
            <origin xyz="0.0 0.365 0.0" rpy="0 0 0"/>
            <geometry>
                <box size="0.87 0.73 0.42" />
            </geometry>
            <material name="Blue">
                <color rgba="0.0 0.5 1.0 1.0"/>
            </material>
        </visual>
        <collision>
            <origin xyz="0.0 0.365 0.0" rpy="0 0 0"/>
            <geometry>
                <box size="0.87 0.73 0.42" />
            </geometry>
        </collision>
    </link>
</robot>