<robot name = "robot">
    <link name="Part0">
        <inertial>
            <origin xyz="0 0 1.555" rpy="0 0 0"/>
            <mass value="1" />
            <inertia ixx="100" ixy="0" ixz="0" iyy="100" iyz="0" izz="100" />
        </inertial>
        <visual>
            <origin xyz="0 0 1.555" rpy="0 0 0"/>
            <geometry>
                <box size="0.93 0.94 0.37" />
            </geometry>
            <material name="Blue">
                <color rgba="0.0 0.5 1.0 1.0"/>
            </material>
        </visual>
        <collision>
            <origin xyz="0 0 1.555" rpy="0 0 0"/>
            <geometry>
                <box size="0.93 0.94 0.37" />
            </geometry>
        </collision>
    </link>
    <joint name="Part0_Part1" type="revolute">
       <parent link="Part0"/>
       <child  link="Part1"/>
       <origin rpy="0 0 0" xyz="0.465 0.0 1.555" />
     <axis xyz="0 1 0"/>
       <limit effort="0.0" lower="-3.14159" upper="3.14159" velocity="0.0"/>
    </joint>
    <link name="Part1">
        <inertial>
            <origin xyz="0.18 0.0 0.0" rpy="0 0 0"/>
            <mass value="1" />
            <inertia ixx="100" ixy="0" ixz="0" iyy="100" iyz="0" izz="100" />
        </inertial>
        <visual>
            <origin xyz="0.18 0.0 0.0" rpy="0 0 0"/>
            <geometry>
                <box size="0.36 0.79 0.67" />
            </geometry>
            <material name="Green">
                <color rgba="0.0 1.0 0.0 1.0"/>
            </material>
        </visual>
        <collision>
            <origin xyz="0.18 0.0 0.0" rpy="0 0 0"/>
            <geometry>
                <box size="0.36 0.79 0.67" />
            </geometry>
        </collision>
    </link>
    <joint name="Part1_Part2" type="revolute">
       <parent link="Part1"/>
       <child  link="Part2"/>
       <origin rpy="0 0 0" xyz="0.18 0.0 -0.335" />
     <axis xyz="1 0 0"/>
       <limit effort="0.0" lower="-3.14159" upper="3.14159" velocity="0.0"/>
    </joint>
    <link name="Part2">
        <inertial>
            <origin xyz="0.0 0.0 -0.31" rpy="0 0 0"/>
            <mass value="1" />
            <inertia ixx="100" ixy="0" ixz="0" iyy="100" iyz="0" izz="100" />
        </inertial>
        <visual>
            <origin xyz="0.0 0.0 -0.31" rpy="0 0 0"/>
            <geometry>
                <box size="0.87 0.45 0.62" />
            </geometry>
            <material name="Blue">
                <color rgba="0.0 0.5 1.0 1.0"/>
            </material>
        </visual>
        <collision>
            <origin xyz="0.0 0.0 -0.31" rpy="0 0 0"/>
            <geometry>
                <box size="0.87 0.45 0.62" />
            </geometry>
        </collision>
    </link>
    <joint name="Part2_Part3" type="revolute">
       <parent link="Part2"/>
       <child  link="Part3"/>
       <origin rpy="0 0 0" xyz="0.435 0.0 -0.31" />
     <axis xyz="0 0 1"/>
       <limit effort="0.0" lower="-3.14159" upper="3.14159" velocity="0.0"/>
    </joint>
    <link name="Part3">
        <inertial>
            <origin xyz="0.41 0.0 0.0" rpy="0 0 0"/>
            <mass value="1" />
            <inertia ixx="100" ixy="0" ixz="0" iyy="100" iyz="0" izz="100" />
        </inertial>
        <visual>
            <origin xyz="0.41 0.0 0.0" rpy="0 0 0"/>
            <geometry>
                <box size="0.82 0.32 0.48" />
            </geometry>
            <material name="Green">
                <color rgba="0.0 1.0 0.0 1.0"/>
            </material>
        </visual>
        <collision>
            <origin xyz="0.41 0.0 0.0" rpy="0 0 0"/>
            <geometry>
                <box size="0.82 0.32 0.48" />
            </geometry>
        </collision>
    </link>
    <joint name="Part3_Part4" type="revolute">
       <parent link="Part3"/>
       <child  link="Part4"/>
       <origin rpy="0 0 0" xyz="0.41 0.0 0.24" />
     <axis xyz="0 1 0"/>
       <limit effort="0.0" lower="-3.14159" upper="3.14159" velocity="0.0"/>
    </joint>
    <link name="Part4">
        <inertial>
            <origin xyz="0.0 0.0 0.5" rpy="0 0 0"/>
            <mass value="1" />
            <inertia ixx="100" ixy="0" ixz="0" iyy="100" iyz="0" izz="100" />
        </inertial>
        <visual>
            <origin xyz="0.0 0.0 0.5" rpy="0 0 0"/>
            <geometry>
                <box size="0.71 0.67 1.0" />
            </geometry>
            <material name="Blue">
                <color rgba="0.0 0.5 1.0 1.0"/>
            </material>
        </visual>
        <collision>
            <origin xyz="0.0 0.0 0.5" rpy="0 0 0"/>
            <geometry>
                <box size="0.71 0.67 1.0" />
            </geometry>
        </collision>
    </link>
    <joint name="Part4_Part5" type="revolute">
       <parent link="Part4"/>
       <child  link="Part5"/>
       <origin rpy="0 0 0" xyz="0.0 0.335 0.5" />
     <axis xyz="0 0 1"/>
       <limit effort="0.0" lower="-3.14159" upper="3.14159" velocity="0.0"/>
    </joint>
    <link name="Part5">
        <inertial>
            <origin xyz="0.0 0.26 0.0" rpy="0 0 0"/>
            <mass value="1" />
            <inertia ixx="100" ixy="0" ixz="0" iyy="100" iyz="0" izz="100" />
        </inertial>
        <visual>
            <origin xyz="0.0 0.26 0.0" rpy="0 0 0"/>
            <geometry>
                <box size="0.35 0.52 0.86" />
            </geometry>
            <material name="Green">
                <color rgba="0.0 1.0 0.0 1.0"/>
            </material>
        </visual>
        <collision>
            <origin xyz="0.0 0.26 0.0" rpy="0 0 0"/>
            <geometry>
                <box size="0.35 0.52 0.86" />
            </geometry>
        </collision>
    </link>
    <joint name="Part3_Part6" type="revolute">
       <parent link="Part3"/>
       <child  link="Part6"/>
       <origin rpy="0 0 0" xyz="0.41 0.0 -0.24" />
     <axis xyz="0 1 0"/>
       <limit effort="0.0" lower="-3.14159" upper="3.14159" velocity="0.0"/>
    </joint>
    <link name="Part6">
        <inertial>
            <origin xyz="0.0 0.0 -0.295" rpy="0 0 0"/>
            <mass value="1" />
            <inertia ixx="100" ixy="0" ixz="0" iyy="100" iyz="0" izz="100" />
        </inertial>
        <visual>
            <origin xyz="0.0 0.0 -0.295" rpy="0 0 0"/>
            <geometry>
                <box size="0.63 0.37 0.59" />
            </geometry>
            <material name="Blue">
                <color rgba="0.0 0.5 1.0 1.0"/>
            </material>
        </visual>
        <collision>
            <origin xyz="0.0 0.0 -0.295" rpy="0 0 0"/>
            <geometry>
                <box size="0.63 0.37 0.59" />
            </geometry>
        </collision>
    </link>
    <joint name="Part6_Part7" type="revolute">
       <parent link="Part6"/>
       <child  link="Part7"/>
       <origin rpy="0 0 0" xyz="0.0 0.185 -0.295" />
     <axis xyz="0 0 1"/>
       <limit effort="0.0" lower="-3.14159" upper="3.14159" velocity="0.0"/>
    </joint>
    <link name="Part7">
        <inertial>
            <origin xyz="0.0 0.41 0.0" rpy="0 0 0"/>
            <mass value="1" />
            <inertia ixx="100" ixy="0" ixz="0" iyy="100" iyz="0" izz="100" />
        </inertial>
        <visual>
            <origin xyz="0.0 0.41 0.0" rpy="0 0 0"/>
            <geometry>
                <box size="0.26 0.82 0.75" />
            </geometry>
            <material name="Green">
                <color rgba="0.0 1.0 0.0 1.0"/>
            </material>
        </visual>
        <collision>
            <origin xyz="0.0 0.41 0.0" rpy="0 0 0"/>
            <geometry>
                <box size="0.26 0.82 0.75" />
            </geometry>
        </collision>
    </link>
    <joint name="Part3_Part8" type="revolute">
       <parent link="Part3"/>
       <child  link="Part8"/>
       <origin rpy="0 0 0" xyz="0.82 0.0 0.0" />
     <axis xyz="0 0 1"/>
       <limit effort="0.0" lower="-3.14159" upper="3.14159" velocity="0.0"/>
    </joint>
    <link name="Part8">
        <inertial>
            <origin xyz="0.235 0.0 0.0" rpy="0 0 0"/>
            <mass value="1" />
            <inertia ixx="100" ixy="0" ixz="0" iyy="100" iyz="0" izz="100" />
        </inertial>
        <visual>
            <origin xyz="0.235 0.0 0.0" rpy="0 0 0"/>
            <geometry>
                <box size="0.47 0.69 0.37" />
            </geometry>
            <material name="Blue">
                <color rgba="0.0 0.5 1.0 1.0"/>
            </material>
        </visual>
        <collision>
            <origin xyz="0.235 0.0 0.0" rpy="0 0 0"/>
            <geometry>
                <box size="0.47 0.69 0.37" />
            </geometry>
        </collision>
    </link>
    <joint name="Part0_Part9" type="revolute">
       <parent link="Part0"/>
       <child  link="Part9"/>
       <origin rpy="0 0 0" xyz="-0.465 0.0 1.555" />
     <axis xyz="0 0 1"/>
       <limit effort="0.0" lower="-3.14159" upper="3.14159" velocity="0.0"/>
    </joint>
    <link name="Part9">
        <inertial>
            <origin xyz="-0.405 0.0 0.0" rpy="0 0 0"/>
            <mass value="1" />
            <inertia ixx="100" ixy="0" ixz="0" iyy="100" iyz="0" izz="100" />
        </inertial>
        <visual>
            <origin xyz="-0.405 0.0 0.0" rpy="0 0 0"/>
            <geometry>
                <box size="0.81 0.97 0.45" />
            </geometry>
            <material name="Blue">
                <color rgba="0.0 0.5 1.0 1.0"/>
            </material>
        </visual>
        <collision>
            <origin xyz="-0.405 0.0 0.0" rpy="0 0 0"/>
            <geometry>
                <box size="0.81 0.97 0.45" />
            </geometry>
        </collision>
    </link>
    <joint name="Part1_Part10" type="revolute">
       <parent link="Part1"/>
       <child  link="Part10"/>
       <origin rpy="0 0 0" xyz="0.18 0.0 0.335" />
     <axis xyz="0 0 1"/>
       <limit effort="0.0" lower="-3.14159" upper="3.14159" velocity="0.0"/>
    </joint>
    <link name="Part10">
        <inertial>
            <origin xyz="0.0 0.0 0.185" rpy="0 0 0"/>
            <mass value="1" />
            <inertia ixx="100" ixy="0" ixz="0" iyy="100" iyz="0" izz="100" />
        </inertial>
        <visual>
            <origin xyz="0.0 0.0 0.185" rpy="0 0 0"/>
            <geometry>
                <box size="0.47 0.38 0.37" />
            </geometry>
            <material name="Blue">
                <color rgba="0.0 0.5 1.0 1.0"/>
            </material>
        </visual>
        <collision>
            <origin xyz="0.0 0.0 0.185" rpy="0 0 0"/>
            <geometry>
                <box size="0.47 0.38 0.37" />
            </geometry>
        </collision>
    </link>
    <joint name="Part6_Part11" type="revolute">
       <parent link="Part6"/>
       <child  link="Part11"/>
       <origin rpy="0 0 0" xyz="0.315 0.0 -0.295" />
     <axis xyz="1 0 0"/>
       <limit effort="0.0" lower="-3.14159" upper="3.14159" velocity="0.0"/>
    </joint>
    <link name="Part11">
        <inertial>
            <origin xyz="0.255 0.0 0.0" rpy="0 0 0"/>
            <mass value="1" />
            <inertia ixx="100" ixy="0" ixz="0" iyy="100" iyz="0" izz="100" />
        </inertial>
        <visual>
            <origin xyz="0.255 0.0 0.0" rpy="0 0 0"/>
            <geometry>
                <box size="0.51 0.68 0.49" />
            </geometry>
            <material name="Blue">
                <color rgba="0.0 0.5 1.0 1.0"/>
            </material>
        </visual>
        <collision>
            <origin xyz="0.255 0.0 0.0" rpy="0 0 0"/>
            <geometry>
                <box size="0.51 0.68 0.49" />
            </geometry>
        </collision>
    </link>
</robot>