<robot name = "robot">
    <link name="Part0">
        <inertial>
            <origin xyz="0 0 0.46" rpy="0 0 0"/>
            <mass value="1" />
            <inertia ixx="100" ixy="0" ixz="0" iyy="100" iyz="0" izz="100" />
        </inertial>
        <visual>
            <origin xyz="0 0 0.46" rpy="0 0 0"/>
            <geometry>
                <box size="0.57 0.7 0.92" />
            </geometry>
            <material name="Green">
                <color rgba="0.0 1.0 0.0 1.0"/>
            </material>
        </visual>
        <collision>
            <origin xyz="0 0 0.46" rpy="0 0 0"/>
            <geometry>
                <box size="0.57 0.7 0.92" />
            </geometry>
        </collision>
    </link>
    <joint name="Part0_Part1" type="revolute">
       <parent link="Part0"/>
       <child  link="Part1"/>
       <origin rpy="0 0 0" xyz="-0.285 0.0 0.46" />
     <axis xyz="0 1 0"/>
       <limit effort="0.0" lower="-3.14159" upper="3.14159" velocity="0.0"/>
    </joint>
    <link name="Part1">
        <inertial>
            <origin xyz="-0.155 0.0 0.0" rpy="0 0 0"/>
            <mass value="1" />
            <inertia ixx="100" ixy="0" ixz="0" iyy="100" iyz="0" izz="100" />
        </inertial>
        <visual>
            <origin xyz="-0.155 0.0 0.0" rpy="0 0 0"/>
            <geometry>
                <box size="0.31 0.45 0.39" />
            </geometry>
            <material name="Green">
                <color rgba="0.0 1.0 0.0 1.0"/>
            </material>
        </visual>
        <collision>
            <origin xyz="-0.155 0.0 0.0" rpy="0 0 0"/>
            <geometry>
                <box size="0.31 0.45 0.39" />
            </geometry>
        </collision>
    </link>
    <joint name="Part0_Part2" type="revolute">
       <parent link="Part0"/>
       <child  link="Part2"/>
       <origin rpy="0 0 0" xyz="0.285 0.0 0.46" />
     <axis xyz="0 1 0"/>
       <limit effort="0.0" lower="-3.14159" upper="3.14159" velocity="0.0"/>
    </joint>
    <link name="Part2">
        <inertial>
            <origin xyz="0.155 0.0 0.0" rpy="0 0 0"/>
            <mass value="1" />
            <inertia ixx="100" ixy="0" ixz="0" iyy="100" iyz="0" izz="100" />
        </inertial>
        <visual>
            <origin xyz="0.155 0.0 0.0" rpy="0 0 0"/>
            <geometry>
                <box size="0.31 0.45 0.39" />
            </geometry>
            <material name="Green">
                <color rgba="0.0 1.0 0.0 1.0"/>
            </material>
        </visual>
        <collision>
            <origin xyz="0.155 0.0 0.0" rpy="0 0 0"/>
            <geometry>
                <box size="0.31 0.45 0.39" />
            </geometry>
        </collision>
    </link>
    <joint name="Part1_Part3" type="revolute">
       <parent link="Part1"/>
       <child  link="Part3"/>
       <origin rpy="0 0 0" xyz="-0.155 0.225 0.0" />
     <axis xyz="0 1 0"/>
       <limit effort="0.0" lower="-3.14159" upper="3.14159" velocity="0.0"/>
    </joint>
    <link name="Part3">
        <inertial>
            <origin xyz="0.0 0.325 0.0" rpy="0 0 0"/>
            <mass value="1" />
            <inertia ixx="100" ixy="0" ixz="0" iyy="100" iyz="0" izz="100" />
        </inertial>
        <visual>
            <origin xyz="0.0 0.325 0.0" rpy="0 0 0"/>
            <geometry>
                <box size="0.25 0.65 0.35" />
            </geometry>
            <material name="Blue">
                <color rgba="0.0 0.5 1.0 1.0"/>
            </material>
        </visual>
        <collision>
            <origin xyz="0.0 0.325 0.0" rpy="0 0 0"/>
            <geometry>
                <box size="0.25 0.65 0.35" />
            </geometry>
        </collision>
    </link>
    <joint name="Part2_Part4" type="revolute">
       <parent link="Part2"/>
       <child  link="Part4"/>
       <origin rpy="0 0 0" xyz="0.155 0.225 0.0" />
     <axis xyz="0 1 0"/>
       <limit effort="0.0" lower="-3.14159" upper="3.14159" velocity="0.0"/>
    </joint>
    <link name="Part4">
        <inertial>
            <origin xyz="0.0 0.325 0.0" rpy="0 0 0"/>
            <mass value="1" />
            <inertia ixx="100" ixy="0" ixz="0" iyy="100" iyz="0" izz="100" />
        </inertial>
        <visual>
            <origin xyz="0.0 0.325 0.0" rpy="0 0 0"/>
            <geometry>
                <box size="0.25 0.65 0.35" />
            </geometry>
            <material name="Blue">
                <color rgba="0.0 0.5 1.0 1.0"/>
            </material>
        </visual>
        <collision>
            <origin xyz="0.0 0.325 0.0" rpy="0 0 0"/>
            <geometry>
                <box size="0.25 0.65 0.35" />
            </geometry>
        </collision>
    </link>
    <joint name="Part3_Part5" type="revolute">
       <parent link="Part3"/>
       <child  link="Part5"/>
       <origin rpy="0 0 0" xyz="-0.125 0.325 0.0" />
     <axis xyz="1 0 0"/>
       <limit effort="0.0" lower="-3.14159" upper="3.14159" velocity="0.0"/>
    </joint>
    <link name="Part5">
        <inertial>
            <origin xyz="-0.41 0.0 0.0" rpy="0 0 0"/>
            <mass value="1" />
            <inertia ixx="100" ixy="0" ixz="0" iyy="100" iyz="0" izz="100" />
        </inertial>
        <visual>
            <origin xyz="-0.41 0.0 0.0" rpy="0 0 0"/>
            <geometry>
                <box size="0.82 0.51 0.47" />
            </geometry>
            <material name="Green">
                <color rgba="0.0 1.0 0.0 1.0"/>
            </material>
        </visual>
        <collision>
            <origin xyz="-0.41 0.0 0.0" rpy="0 0 0"/>
            <geometry>
                <box size="0.82 0.51 0.47" />
            </geometry>
        </collision>
    </link>
    <joint name="Part4_Part6" type="revolute">
       <parent link="Part4"/>
       <child  link="Part6"/>
       <origin rpy="0 0 0" xyz="0.125 0.325 0.0" />
     <axis xyz="1 0 0"/>
       <limit effort="0.0" lower="-3.14159" upper="3.14159" velocity="0.0"/>
    </joint>
    <link name="Part6">
        <inertial>
            <origin xyz="0.41 0.0 0.0" rpy="0 0 0"/>
            <mass value="1" />
            <inertia ixx="100" ixy="0" ixz="0" iyy="100" iyz="0" izz="100" />
        </inertial>
        <visual>
            <origin xyz="0.41 0.0 0.0" rpy="0 0 0"/>
            <geometry>
                <box size="0.82 0.51 0.47" />
            </geometry>
            <material name="Green">
                <color rgba="0.0 1.0 0.0 1.0"/>
            </material>
        </visual>
        <collision>
            <origin xyz="0.41 0.0 0.0" rpy="0 0 0"/>
            <geometry>
                <box size="0.82 0.51 0.47" />
            </geometry>
        </collision>
    </link>
</robot>