<robot name = "robot">
    <link name="Part0">
        <inertial>
            <origin xyz="0 0 0.9450000000000001" rpy="0 0 0"/>
            <mass value="1" />
            <inertia ixx="100" ixy="0" ixz="0" iyy="100" iyz="0" izz="100" />
        </inertial>
        <visual>
            <origin xyz="0 0 0.9450000000000001" rpy="0 0 0"/>
            <geometry>
                <box size="0.52 0.79 0.28" />
            </geometry>
            <material name="Green">
                <color rgba="0.0 1.0 0.0 1.0"/>
            </material>
        </visual>
        <collision>
            <origin xyz="0 0 0.9450000000000001" rpy="0 0 0"/>
            <geometry>
                <box size="0.52 0.79 0.28" />
            </geometry>
        </collision>
    </link>
    <joint name="Part0_Part1" type="revolute">
       <parent link="Part0"/>
       <child  link="Part1"/>
       <origin rpy="0 0 0" xyz="0.0 0.0 0.8050000000000002" />
     <axis xyz="1 0 0"/>
       <limit effort="0.0" lower="-3.14159" upper="3.14159" velocity="0.0"/>
    </joint>
    <link name="Part1">
        <inertial>
            <origin xyz="0.0 0.0 -0.345" rpy="0 0 0"/>
            <mass value="1" />
            <inertia ixx="100" ixy="0" ixz="0" iyy="100" iyz="0" izz="100" />
        </inertial>
        <visual>
            <origin xyz="0.0 0.0 -0.345" rpy="0 0 0"/>
            <geometry>
                <box size="0.95 0.54 0.69" />
            </geometry>
            <material name="Green">
                <color rgba="0.0 1.0 0.0 1.0"/>
            </material>
        </visual>
        <collision>
            <origin xyz="0.0 0.0 -0.345" rpy="0 0 0"/>
            <geometry>
                <box size="0.95 0.54 0.69" />
            </geometry>
        </collision>
    </link>
    <joint name="Part0_Part2" type="revolute">
       <parent link="Part0"/>
       <child  link="Part2"/>
       <origin rpy="0 0 0" xyz="0.0 0.0 1.0850000000000002" />
     <axis xyz="1 0 0"/>
       <limit effort="0.0" lower="-3.14159" upper="3.14159" velocity="0.0"/>
    </joint>
    <link name="Part2">
        <inertial>
            <origin xyz="0.0 0.0 0.345" rpy="0 0 0"/>
            <mass value="1" />
            <inertia ixx="100" ixy="0" ixz="0" iyy="100" iyz="0" izz="100" />
        </inertial>
        <visual>
            <origin xyz="0.0 0.0 0.345" rpy="0 0 0"/>
            <geometry>
                <box size="0.95 0.54 0.69" />
            </geometry>
            <material name="Green">
                <color rgba="0.0 1.0 0.0 1.0"/>
            </material>
        </visual>
        <collision>
            <origin xyz="0.0 0.0 0.345" rpy="0 0 0"/>
            <geometry>
                <box size="0.95 0.54 0.69" />
            </geometry>
        </collision>
    </link>
    <joint name="Part0_Part3" type="revolute">
       <parent link="Part0"/>
       <child  link="Part3"/>
       <origin rpy="0 0 0" xyz="0.0 -0.395 0.9450000000000001" />
     <axis xyz="0 1 0"/>
       <limit effort="0.0" lower="-3.14159" upper="3.14159" velocity="0.0"/>
    </joint>
    <link name="Part3">
        <inertial>
            <origin xyz="0.0 -0.405 0.0" rpy="0 0 0"/>
            <mass value="1" />
            <inertia ixx="100" ixy="0" ixz="0" iyy="100" iyz="0" izz="100" />
        </inertial>
        <visual>
            <origin xyz="0.0 -0.405 0.0" rpy="0 0 0"/>
            <geometry>
                <box size="0.35 0.81 0.55" />
            </geometry>
            <material name="Blue">
                <color rgba="0.0 0.5 1.0 1.0"/>
            </material>
        </visual>
        <collision>
            <origin xyz="0.0 -0.405 0.0" rpy="0 0 0"/>
            <geometry>
                <box size="0.35 0.81 0.55" />
            </geometry>
        </collision>
    </link>
    <joint name="Part0_Part4" type="revolute">
       <parent link="Part0"/>
       <child  link="Part4"/>
       <origin rpy="0 0 0" xyz="0.0 0.395 0.9450000000000001" />
     <axis xyz="0 1 0"/>
       <limit effort="0.0" lower="-3.14159" upper="3.14159" velocity="0.0"/>
    </joint>
    <link name="Part4">
        <inertial>
            <origin xyz="0.0 0.405 0.0" rpy="0 0 0"/>
            <mass value="1" />
            <inertia ixx="100" ixy="0" ixz="0" iyy="100" iyz="0" izz="100" />
        </inertial>
        <visual>
            <origin xyz="0.0 0.405 0.0" rpy="0 0 0"/>
            <geometry>
                <box size="0.35 0.81 0.55" />
            </geometry>
            <material name="Blue">
                <color rgba="0.0 0.5 1.0 1.0"/>
            </material>
        </visual>
        <collision>
            <origin xyz="0.0 0.405 0.0" rpy="0 0 0"/>
            <geometry>
                <box size="0.35 0.81 0.55" />
            </geometry>
        </collision>
    </link>
    <joint name="Part4_Part5" type="revolute">
       <parent link="Part4"/>
       <child  link="Part5"/>
       <origin rpy="0 0 0" xyz="0.0 0.81 0.0" />
     <axis xyz="0 0 1"/>
       <limit effort="0.0" lower="-3.14159" upper="3.14159" velocity="0.0"/>
    </joint>
    <link name="Part5">
        <inertial>
            <origin xyz="0.0 0.185 0.0" rpy="0 0 0"/>
            <mass value="1" />
            <inertia ixx="100" ixy="0" ixz="0" iyy="100" iyz="0" izz="100" />
        </inertial>
        <visual>
            <origin xyz="0.0 0.185 0.0" rpy="0 0 0"/>
            <geometry>
                <box size="0.67 0.37 0.51" />
            </geometry>
            <material name="Blue">
                <color rgba="0.0 0.5 1.0 1.0"/>
            </material>
        </visual>
        <collision>
            <origin xyz="0.0 0.185 0.0" rpy="0 0 0"/>
            <geometry>
                <box size="0.67 0.37 0.51" />
            </geometry>
        </collision>
    </link>
    <joint name="Part3_Part6" type="revolute">
       <parent link="Part3"/>
       <child  link="Part6"/>
       <origin rpy="0 0 0" xyz="0.0 -0.81 0.0" />
     <axis xyz="0 0 1"/>
       <limit effort="0.0" lower="-3.14159" upper="3.14159" velocity="0.0"/>
    </joint>
    <link name="Part6">
        <inertial>
            <origin xyz="0.0 -0.185 0.0" rpy="0 0 0"/>
            <mass value="1" />
            <inertia ixx="100" ixy="0" ixz="0" iyy="100" iyz="0" izz="100" />
        </inertial>
        <visual>
            <origin xyz="0.0 -0.185 0.0" rpy="0 0 0"/>
            <geometry>
                <box size="0.67 0.37 0.51" />
            </geometry>
            <material name="Blue">
                <color rgba="0.0 0.5 1.0 1.0"/>
            </material>
        </visual>
        <collision>
            <origin xyz="0.0 -0.185 0.0" rpy="0 0 0"/>
            <geometry>
                <box size="0.67 0.37 0.51" />
            </geometry>
        </collision>
    </link>
    <joint name="Part6_Part7" type="revolute">
       <parent link="Part6"/>
       <child  link="Part7"/>
       <origin rpy="0 0 0" xyz="0.0 -0.37 0.0" />
     <axis xyz="1 0 0"/>
       <limit effort="0.0" lower="-3.14159" upper="3.14159" velocity="0.0"/>
    </joint>
    <link name="Part7">
        <inertial>
            <origin xyz="0.0 -0.31 0.0" rpy="0 0 0"/>
            <mass value="1" />
            <inertia ixx="100" ixy="0" ixz="0" iyy="100" iyz="0" izz="100" />
        </inertial>
        <visual>
            <origin xyz="0.0 -0.31 0.0" rpy="0 0 0"/>
            <geometry>
                <box size="0.58 0.62 0.9" />
            </geometry>
            <material name="Green">
                <color rgba="0.0 1.0 0.0 1.0"/>
            </material>
        </visual>
        <collision>
            <origin xyz="0.0 -0.31 0.0" rpy="0 0 0"/>
            <geometry>
                <box size="0.58 0.62 0.9" />
            </geometry>
        </collision>
    </link>
    <joint name="Part5_Part8" type="revolute">
       <parent link="Part5"/>
       <child  link="Part8"/>
       <origin rpy="0 0 0" xyz="0.0 0.37 0.0" />
     <axis xyz="1 0 0"/>
       <limit effort="0.0" lower="-3.14159" upper="3.14159" velocity="0.0"/>
    </joint>
    <link name="Part8">
        <inertial>
            <origin xyz="0.0 0.31 0.0" rpy="0 0 0"/>
            <mass value="1" />
            <inertia ixx="100" ixy="0" ixz="0" iyy="100" iyz="0" izz="100" />
        </inertial>
        <visual>
            <origin xyz="0.0 0.31 0.0" rpy="0 0 0"/>
            <geometry>
                <box size="0.58 0.62 0.9" />
            </geometry>
            <material name="Green">
                <color rgba="0.0 1.0 0.0 1.0"/>
            </material>
        </visual>
        <collision>
            <origin xyz="0.0 0.31 0.0" rpy="0 0 0"/>
            <geometry>
                <box size="0.58 0.62 0.9" />
            </geometry>
        </collision>
    </link>
    <joint name="Part7_Part9" type="revolute">
       <parent link="Part7"/>
       <child  link="Part9"/>
       <origin rpy="0 0 0" xyz="0.0 -0.62 0.0" />
     <axis xyz="1 0 0"/>
       <limit effort="0.0" lower="-3.14159" upper="3.14159" velocity="0.0"/>
    </joint>
    <link name="Part9">
        <inertial>
            <origin xyz="0.0 -0.295 0.0" rpy="0 0 0"/>
            <mass value="1" />
            <inertia ixx="100" ixy="0" ixz="0" iyy="100" iyz="0" izz="100" />
        </inertial>
        <visual>
            <origin xyz="0.0 -0.295 0.0" rpy="0 0 0"/>
            <geometry>
                <box size="0.25 0.59 0.35" />
            </geometry>
            <material name="Blue">
                <color rgba="0.0 0.5 1.0 1.0"/>
            </material>
        </visual>
        <collision>
            <origin xyz="0.0 -0.295 0.0" rpy="0 0 0"/>
            <geometry>
                <box size="0.25 0.59 0.35" />
            </geometry>
        </collision>
    </link>
    <joint name="Part8_Part10" type="revolute">
       <parent link="Part8"/>
       <child  link="Part10"/>
       <origin rpy="0 0 0" xyz="0.0 0.62 0.0" />
     <axis xyz="1 0 0"/>
       <limit effort="0.0" lower="-3.14159" upper="3.14159" velocity="0.0"/>
    </joint>
    <link name="Part10">
        <inertial>
            <origin xyz="0.0 0.295 0.0" rpy="0 0 0"/>
            <mass value="1" />
            <inertia ixx="100" ixy="0" ixz="0" iyy="100" iyz="0" izz="100" />
        </inertial>
        <visual>
            <origin xyz="0.0 0.295 0.0" rpy="0 0 0"/>
            <geometry>
                <box size="0.25 0.59 0.35" />
            </geometry>
            <material name="Blue">
                <color rgba="0.0 0.5 1.0 1.0"/>
            </material>
        </visual>
        <collision>
            <origin xyz="0.0 0.295 0.0" rpy="0 0 0"/>
            <geometry>
                <box size="0.25 0.59 0.35" />
            </geometry>
        </collision>
    </link>
</robot>