<robot name = "robot">
    <link name="Part0">
        <inertial>
            <origin xyz="0 0 1.7" rpy="0 0 0"/>
            <mass value="1" />
            <inertia ixx="100" ixy="0" ixz="0" iyy="100" iyz="0" izz="100" />
        </inertial>
        <visual>
            <origin xyz="0 0 1.7" rpy="0 0 0"/>
            <geometry>
                <box size="0.75 0.31 0.34" />
            </geometry>
            <material name="Green">
                <color rgba="0.0 1.0 0.0 1.0"/>
            </material>
        </visual>
        <collision>
            <origin xyz="0 0 1.7" rpy="0 0 0"/>
            <geometry>
                <box size="0.75 0.31 0.34" />
            </geometry>
        </collision>
    </link>
    <joint name="Part0_Part1" type="revolute">
       <parent link="Part0"/>
       <child  link="Part1"/>
       <origin rpy="0 0 0" xyz="0.0 0.0 1.87" />
     <axis xyz="1 0 0"/>
       <limit effort="0.0" lower="-3.14159" upper="3.14159" velocity="0.0"/>
    </joint>
    <link name="Part1">
        <inertial>
            <origin xyz="0.0 0.0 0.16" rpy="0 0 0"/>
            <mass value="1" />
            <inertia ixx="100" ixy="0" ixz="0" iyy="100" iyz="0" izz="100" />
        </inertial>
        <visual>
            <origin xyz="0.0 0.0 0.16" rpy="0 0 0"/>
            <geometry>
                <box size="0.71 0.99 0.32" />
            </geometry>
            <material name="Blue">
                <color rgba="0.0 0.5 1.0 1.0"/>
            </material>
        </visual>
        <collision>
            <origin xyz="0.0 0.0 0.16" rpy="0 0 0"/>
            <geometry>
                <box size="0.71 0.99 0.32" />
            </geometry>
        </collision>
    </link>
    <joint name="Part1_Part2" type="revolute">
       <parent link="Part1"/>
       <child  link="Part2"/>
       <origin rpy="0 0 0" xyz="0.0 0.0 0.32" />
     <axis xyz="0 0 1"/>
       <limit effort="0.0" lower="-3.14159" upper="3.14159" velocity="0.0"/>
    </joint>
    <link name="Part2">
        <inertial>
            <origin xyz="0.0 0.0 0.3" rpy="0 0 0"/>
            <mass value="1" />
            <inertia ixx="100" ixy="0" ixz="0" iyy="100" iyz="0" izz="100" />
        </inertial>
        <visual>
            <origin xyz="0.0 0.0 0.3" rpy="0 0 0"/>
            <geometry>
                <box size="0.76 0.95 0.6" />
            </geometry>
            <material name="Blue">
                <color rgba="0.0 0.5 1.0 1.0"/>
            </material>
        </visual>
        <collision>
            <origin xyz="0.0 0.0 0.3" rpy="0 0 0"/>
            <geometry>
                <box size="0.76 0.95 0.6" />
            </geometry>
        </collision>
    </link>
    <joint name="Part0_Part3" type="revolute">
       <parent link="Part0"/>
       <child  link="Part3"/>
       <origin rpy="0 0 0" xyz="-0.375 0.0 1.7" />
     <axis xyz="1 0 0"/>
       <limit effort="0.0" lower="-3.14159" upper="3.14159" velocity="0.0"/>
    </joint>
    <link name="Part3">
        <inertial>
            <origin xyz="-0.19 0.0 0.0" rpy="0 0 0"/>
            <mass value="1" />
            <inertia ixx="100" ixy="0" ixz="0" iyy="100" iyz="0" izz="100" />
        </inertial>
        <visual>
            <origin xyz="-0.19 0.0 0.0" rpy="0 0 0"/>
            <geometry>
                <box size="0.38 0.92 0.42" />
            </geometry>
            <material name="Blue">
                <color rgba="0.0 0.5 1.0 1.0"/>
            </material>
        </visual>
        <collision>
            <origin xyz="-0.19 0.0 0.0" rpy="0 0 0"/>
            <geometry>
                <box size="0.38 0.92 0.42" />
            </geometry>
        </collision>
    </link>
    <joint name="Part2_Part4" type="revolute">
       <parent link="Part2"/>
       <child  link="Part4"/>
       <origin rpy="0 0 0" xyz="0.0 0.0 0.6" />
     <axis xyz="0 0 1"/>
       <limit effort="0.0" lower="-3.14159" upper="3.14159" velocity="0.0"/>
    </joint>
    <link name="Part4">
        <inertial>
            <origin xyz="0.0 0.0 0.305" rpy="0 0 0"/>
            <mass value="1" />
            <inertia ixx="100" ixy="0" ixz="0" iyy="100" iyz="0" izz="100" />
        </inertial>
        <visual>
            <origin xyz="0.0 0.0 0.305" rpy="0 0 0"/>
            <geometry>
                <box size="0.88 0.44 0.61" />
            </geometry>
            <material name="Blue">
                <color rgba="0.0 0.5 1.0 1.0"/>
            </material>
        </visual>
        <collision>
            <origin xyz="0.0 0.0 0.305" rpy="0 0 0"/>
            <geometry>
                <box size="0.88 0.44 0.61" />
            </geometry>
        </collision>
    </link>
    <joint name="Part0_Part5" type="revolute">
       <parent link="Part0"/>
       <child  link="Part5"/>
       <origin rpy="0 0 0" xyz="0.375 0.0 1.7" />
     <axis xyz="0 1 0"/>
       <limit effort="0.0" lower="-3.14159" upper="3.14159" velocity="0.0"/>
    </joint>
    <link name="Part5">
        <inertial>
            <origin xyz="0.475 0.0 0.0" rpy="0 0 0"/>
            <mass value="1" />
            <inertia ixx="100" ixy="0" ixz="0" iyy="100" iyz="0" izz="100" />
        </inertial>
        <visual>
            <origin xyz="0.475 0.0 0.0" rpy="0 0 0"/>
            <geometry>
                <box size="0.95 0.5 0.64" />
            </geometry>
            <material name="Blue">
                <color rgba="0.0 0.5 1.0 1.0"/>
            </material>
        </visual>
        <collision>
            <origin xyz="0.475 0.0 0.0" rpy="0 0 0"/>
            <geometry>
                <box size="0.95 0.5 0.64" />
            </geometry>
        </collision>
    </link>
    <joint name="Part5_Part6" type="revolute">
       <parent link="Part5"/>
       <child  link="Part6"/>
       <origin rpy="0 0 0" xyz="0.475 -0.25 0.0" />
     <axis xyz="0 0 1"/>
       <limit effort="0.0" lower="-3.14159" upper="3.14159" velocity="0.0"/>
    </joint>
    <link name="Part6">
        <inertial>
            <origin xyz="0.0 -0.39 0.0" rpy="0 0 0"/>
            <mass value="1" />
            <inertia ixx="100" ixy="0" ixz="0" iyy="100" iyz="0" izz="100" />
        </inertial>
        <visual>
            <origin xyz="0.0 -0.39 0.0" rpy="0 0 0"/>
            <geometry>
                <box size="0.64 0.78 0.31" />
            </geometry>
            <material name="Blue">
                <color rgba="0.0 0.5 1.0 1.0"/>
            </material>
        </visual>
        <collision>
            <origin xyz="0.0 -0.39 0.0" rpy="0 0 0"/>
            <geometry>
                <box size="0.64 0.78 0.31" />
            </geometry>
        </collision>
    </link>
    <joint name="Part4_Part7" type="revolute">
       <parent link="Part4"/>
       <child  link="Part7"/>
       <origin rpy="0 0 0" xyz="0.44 0.0 0.305" />
     <axis xyz="0 1 0"/>
       <limit effort="0.0" lower="-3.14159" upper="3.14159" velocity="0.0"/>
    </joint>
    <link name="Part7">
        <inertial>
            <origin xyz="0.35 0.0 0.0" rpy="0 0 0"/>
            <mass value="1" />
            <inertia ixx="100" ixy="0" ixz="0" iyy="100" iyz="0" izz="100" />
        </inertial>
        <visual>
            <origin xyz="0.35 0.0 0.0" rpy="0 0 0"/>
            <geometry>
                <box size="0.7 0.78 0.78" />
            </geometry>
            <material name="Green">
                <color rgba="0.0 1.0 0.0 1.0"/>
            </material>
        </visual>
        <collision>
            <origin xyz="0.35 0.0 0.0" rpy="0 0 0"/>
            <geometry>
                <box size="0.7 0.78 0.78" />
            </geometry>
        </collision>
    </link>
    <joint name="Part3_Part8" type="revolute">
       <parent link="Part3"/>
       <child  link="Part8"/>
       <origin rpy="0 0 0" xyz="-0.19 0.0 -0.21" />
     <axis xyz="1 0 0"/>
       <limit effort="0.0" lower="-3.14159" upper="3.14159" velocity="0.0"/>
    </joint>
    <link name="Part8">
        <inertial>
            <origin xyz="0.0 0.0 -0.36" rpy="0 0 0"/>
            <mass value="1" />
            <inertia ixx="100" ixy="0" ixz="0" iyy="100" iyz="0" izz="100" />
        </inertial>
        <visual>
            <origin xyz="0.0 0.0 -0.36" rpy="0 0 0"/>
            <geometry>
                <box size="0.79 0.74 0.72" />
            </geometry>
            <material name="Blue">
                <color rgba="0.0 0.5 1.0 1.0"/>
            </material>
        </visual>
        <collision>
            <origin xyz="0.0 0.0 -0.36" rpy="0 0 0"/>
            <geometry>
                <box size="0.79 0.74 0.72" />
            </geometry>
        </collision>
    </link>
    <joint name="Part0_Part9" type="revolute">
       <parent link="Part0"/>
       <child  link="Part9"/>
       <origin rpy="0 0 0" xyz="0.0 0.0 1.5299999999999998" />
     <axis xyz="1 0 0"/>
       <limit effort="0.0" lower="-3.14159" upper="3.14159" velocity="0.0"/>
    </joint>
    <link name="Part9">
        <inertial>
            <origin xyz="0.0 0.0 -0.42" rpy="0 0 0"/>
            <mass value="1" />
            <inertia ixx="100" ixy="0" ixz="0" iyy="100" iyz="0" izz="100" />
        </inertial>
        <visual>
            <origin xyz="0.0 0.0 -0.42" rpy="0 0 0"/>
            <geometry>
                <box size="0.25 0.87 0.84" />
            </geometry>
            <material name="Green">
                <color rgba="0.0 1.0 0.0 1.0"/>
            </material>
        </visual>
        <collision>
            <origin xyz="0.0 0.0 -0.42" rpy="0 0 0"/>
            <geometry>
                <box size="0.25 0.87 0.84" />
            </geometry>
        </collision>
    </link>
    <joint name="Part5_Part10" type="revolute">
       <parent link="Part5"/>
       <child  link="Part10"/>
       <origin rpy="0 0 0" xyz="0.95 0.0 0.0" />
     <axis xyz="0 0 1"/>
       <limit effort="0.0" lower="-3.14159" upper="3.14159" velocity="0.0"/>
    </joint>
    <link name="Part10">
        <inertial>
            <origin xyz="0.38 0.0 0.0" rpy="0 0 0"/>
            <mass value="1" />
            <inertia ixx="100" ixy="0" ixz="0" iyy="100" iyz="0" izz="100" />
        </inertial>
        <visual>
            <origin xyz="0.38 0.0 0.0" rpy="0 0 0"/>
            <geometry>
                <box size="0.76 0.39 0.29" />
            </geometry>
            <material name="Blue">
                <color rgba="0.0 0.5 1.0 1.0"/>
            </material>
        </visual>
        <collision>
            <origin xyz="0.38 0.0 0.0" rpy="0 0 0"/>
            <geometry>
                <box size="0.76 0.39 0.29" />
            </geometry>
        </collision>
    </link>
    <joint name="Part8_Part11" type="revolute">
       <parent link="Part8"/>
       <child  link="Part11"/>
       <origin rpy="0 0 0" xyz="0.0 0.0 -0.72" />
     <axis xyz="0 0 1"/>
       <limit effort="0.0" lower="-3.14159" upper="3.14159" velocity="0.0"/>
    </joint>
    <link name="Part11">
        <inertial>
            <origin xyz="0.0 0.0 -0.385" rpy="0 0 0"/>
            <mass value="1" />
            <inertia ixx="100" ixy="0" ixz="0" iyy="100" iyz="0" izz="100" />
        </inertial>
        <visual>
            <origin xyz="0.0 0.0 -0.385" rpy="0 0 0"/>
            <geometry>
                <box size="0.74 0.83 0.77" />
            </geometry>
            <material name="Blue">
                <color rgba="0.0 0.5 1.0 1.0"/>
            </material>
        </visual>
        <collision>
            <origin xyz="0.0 0.0 -0.385" rpy="0 0 0"/>
            <geometry>
                <box size="0.74 0.83 0.77" />
            </geometry>
        </collision>
    </link>
</robot>