<robot name = "robot">
    <link name="Part0">
        <inertial>
            <origin xyz="0 0 0.175" rpy="0 0 0"/>
            <mass value="1" />
            <inertia ixx="100" ixy="0" ixz="0" iyy="100" iyz="0" izz="100" />
        </inertial>
        <visual>
            <origin xyz="0 0 0.175" rpy="0 0 0"/>
            <geometry>
                <box size="0.45 0.89 0.35" />
            </geometry>
            <material name="Green">
                <color rgba="0.0 1.0 0.0 1.0"/>
            </material>
        </visual>
        <collision>
            <origin xyz="0 0 0.175" rpy="0 0 0"/>
            <geometry>
                <box size="0.45 0.89 0.35" />
            </geometry>
        </collision>
    </link>
    <joint name="Part0_Part1" type="revolute">
       <parent link="Part0"/>
       <child  link="Part1"/>
       <origin rpy="0 0 0" xyz="0.0 0.0 0.35000000000000003" />
     <axis xyz="1 0 0"/>
       <limit effort="0.0" lower="-3.14159" upper="3.14159" velocity="0.0"/>
    </joint>
    <link name="Part1">
        <inertial>
            <origin xyz="0.0 0.0 0.335" rpy="0 0 0"/>
            <mass value="1" />
            <inertia ixx="100" ixy="0" ixz="0" iyy="100" iyz="0" izz="100" />
        </inertial>
        <visual>
            <origin xyz="0.0 0.0 0.335" rpy="0 0 0"/>
            <geometry>
                <box size="0.38 0.93 0.67" />
            </geometry>
            <material name="Blue">
                <color rgba="0.0 0.5 1.0 1.0"/>
            </material>
        </visual>
        <collision>
            <origin xyz="0.0 0.0 0.335" rpy="0 0 0"/>
            <geometry>
                <box size="0.38 0.93 0.67" />
            </geometry>
        </collision>
    </link>
    <joint name="Part1_Part2" type="revolute">
       <parent link="Part1"/>
       <child  link="Part2"/>
       <origin rpy="0 0 0" xyz="0.0 0.465 0.335" />
     <axis xyz="0 0 1"/>
       <limit effort="0.0" lower="-3.14159" upper="3.14159" velocity="0.0"/>
    </joint>
    <link name="Part2">
        <inertial>
            <origin xyz="0.0 0.375 0.0" rpy="0 0 0"/>
            <mass value="1" />
            <inertia ixx="100" ixy="0" ixz="0" iyy="100" iyz="0" izz="100" />
        </inertial>
        <visual>
            <origin xyz="0.0 0.375 0.0" rpy="0 0 0"/>
            <geometry>
                <box size="0.79 0.75 0.45" />
            </geometry>
            <material name="Blue">
                <color rgba="0.0 0.5 1.0 1.0"/>
            </material>
        </visual>
        <collision>
            <origin xyz="0.0 0.375 0.0" rpy="0 0 0"/>
            <geometry>
                <box size="0.79 0.75 0.45" />
            </geometry>
        </collision>
    </link>
    <joint name="Part1_Part3" type="revolute">
       <parent link="Part1"/>
       <child  link="Part3"/>
       <origin rpy="0 0 0" xyz="0.19 0.0 0.335" />
     <axis xyz="0 1 0"/>
       <limit effort="0.0" lower="-3.14159" upper="3.14159" velocity="0.0"/>
    </joint>
    <link name="Part3">
        <inertial>
            <origin xyz="0.37 0.0 0.0" rpy="0 0 0"/>
            <mass value="1" />
            <inertia ixx="100" ixy="0" ixz="0" iyy="100" iyz="0" izz="100" />
        </inertial>
        <visual>
            <origin xyz="0.37 0.0 0.0" rpy="0 0 0"/>
            <geometry>
                <box size="0.74 0.82 0.53" />
            </geometry>
            <material name="Green">
                <color rgba="0.0 1.0 0.0 1.0"/>
            </material>
        </visual>
        <collision>
            <origin xyz="0.37 0.0 0.0" rpy="0 0 0"/>
            <geometry>
                <box size="0.74 0.82 0.53" />
            </geometry>
        </collision>
    </link>
    <joint name="Part2_Part4" type="revolute">
       <parent link="Part2"/>
       <child  link="Part4"/>
       <origin rpy="0 0 0" xyz="0.0 0.375 0.225" />
     <axis xyz="1 0 0"/>
       <limit effort="0.0" lower="-3.14159" upper="3.14159" velocity="0.0"/>
    </joint>
    <link name="Part4">
        <inertial>
            <origin xyz="0.0 0.0 0.455" rpy="0 0 0"/>
            <mass value="1" />
            <inertia ixx="100" ixy="0" ixz="0" iyy="100" iyz="0" izz="100" />
        </inertial>
        <visual>
            <origin xyz="0.0 0.0 0.455" rpy="0 0 0"/>
            <geometry>
                <box size="0.93 0.26 0.91" />
            </geometry>
            <material name="Blue">
                <color rgba="0.0 0.5 1.0 1.0"/>
            </material>
        </visual>
        <collision>
            <origin xyz="0.0 0.0 0.455" rpy="0 0 0"/>
            <geometry>
                <box size="0.93 0.26 0.91" />
            </geometry>
        </collision>
    </link>
    <joint name="Part1_Part5" type="revolute">
       <parent link="Part1"/>
       <child  link="Part5"/>
       <origin rpy="0 0 0" xyz="0.0 0.0 0.67" />
     <axis xyz="0 0 1"/>
       <limit effort="0.0" lower="-3.14159" upper="3.14159" velocity="0.0"/>
    </joint>
    <link name="Part5">
        <inertial>
            <origin xyz="0.0 0.0 0.42" rpy="0 0 0"/>
            <mass value="1" />
            <inertia ixx="100" ixy="0" ixz="0" iyy="100" iyz="0" izz="100" />
        </inertial>
        <visual>
            <origin xyz="0.0 0.0 0.42" rpy="0 0 0"/>
            <geometry>
                <box size="0.76 0.41 0.84" />
            </geometry>
            <material name="Blue">
                <color rgba="0.0 0.5 1.0 1.0"/>
            </material>
        </visual>
        <collision>
            <origin xyz="0.0 0.0 0.42" rpy="0 0 0"/>
            <geometry>
                <box size="0.76 0.41 0.84" />
            </geometry>
        </collision>
    </link>
</robot>