<robot name = "robot">
    <link name="Part0">
        <inertial>
            <origin xyz="0 0 1.9200000000000002" rpy="0 0 0"/>
            <mass value="1" />
            <inertia ixx="100" ixy="0" ixz="0" iyy="100" iyz="0" izz="100" />
        </inertial>
        <visual>
            <origin xyz="0 0 1.9200000000000002" rpy="0 0 0"/>
            <geometry>
                <box size="0.49 0.46 0.64" />
            </geometry>
            <material name="Blue">
                <color rgba="0.0 0.5 1.0 1.0"/>
            </material>
        </visual>
        <collision>
            <origin xyz="0 0 1.9200000000000002" rpy="0 0 0"/>
            <geometry>
                <box size="0.49 0.46 0.64" />
            </geometry>
        </collision>
    </link>
    <joint name="Part0_Part1" type="revolute">
       <parent link="Part0"/>
       <child  link="Part1"/>
       <origin rpy="0 0 0" xyz="0.245 0.0 1.9200000000000002" />
     <axis xyz="1 0 0"/>
       <limit effort="0.0" lower="-3.14159" upper="3.14159" velocity="0.0"/>
    </joint>
    <link name="Part1">
        <inertial>
            <origin xyz="0.34 0.0 0.0" rpy="0 0 0"/>
            <mass value="1" />
            <inertia ixx="100" ixy="0" ixz="0" iyy="100" iyz="0" izz="100" />
        </inertial>
        <visual>
            <origin xyz="0.34 0.0 0.0" rpy="0 0 0"/>
            <geometry>
                <box size="0.68 0.74 0.89" />
            </geometry>
            <material name="Green">
                <color rgba="0.0 1.0 0.0 1.0"/>
            </material>
        </visual>
        <collision>
            <origin xyz="0.34 0.0 0.0" rpy="0 0 0"/>
            <geometry>
                <box size="0.68 0.74 0.89" />
            </geometry>
        </collision>
    </link>
    <joint name="Part0_Part2" type="revolute">
       <parent link="Part0"/>
       <child  link="Part2"/>
       <origin rpy="0 0 0" xyz="-0.245 0.0 1.9200000000000002" />
     <axis xyz="1 0 0"/>
       <limit effort="0.0" lower="-3.14159" upper="3.14159" velocity="0.0"/>
    </joint>
    <link name="Part2">
        <inertial>
            <origin xyz="-0.34 0.0 0.0" rpy="0 0 0"/>
            <mass value="1" />
            <inertia ixx="100" ixy="0" ixz="0" iyy="100" iyz="0" izz="100" />
        </inertial>
        <visual>
            <origin xyz="-0.34 0.0 0.0" rpy="0 0 0"/>
            <geometry>
                <box size="0.68 0.74 0.89" />
            </geometry>
            <material name="Green">
                <color rgba="0.0 1.0 0.0 1.0"/>
            </material>
        </visual>
        <collision>
            <origin xyz="-0.34 0.0 0.0" rpy="0 0 0"/>
            <geometry>
                <box size="0.68 0.74 0.89" />
            </geometry>
        </collision>
    </link>
    <joint name="Part1_Part3" type="revolute">
       <parent link="Part1"/>
       <child  link="Part3"/>
       <origin rpy="0 0 0" xyz="0.34 0.0 -0.445" />
     <axis xyz="0 0 1"/>
       <limit effort="0.0" lower="-3.14159" upper="3.14159" velocity="0.0"/>
    </joint>
    <link name="Part3">
        <inertial>
            <origin xyz="0.0 0.0 -0.315" rpy="0 0 0"/>
            <mass value="1" />
            <inertia ixx="100" ixy="0" ixz="0" iyy="100" iyz="0" izz="100" />
        </inertial>
        <visual>
            <origin xyz="0.0 0.0 -0.315" rpy="0 0 0"/>
            <geometry>
                <box size="0.86 0.53 0.63" />
            </geometry>
            <material name="Blue">
                <color rgba="0.0 0.5 1.0 1.0"/>
            </material>
        </visual>
        <collision>
            <origin xyz="0.0 0.0 -0.315" rpy="0 0 0"/>
            <geometry>
                <box size="0.86 0.53 0.63" />
            </geometry>
        </collision>
    </link>
    <joint name="Part2_Part4" type="revolute">
       <parent link="Part2"/>
       <child  link="Part4"/>
       <origin rpy="0 0 0" xyz="-0.34 0.0 -0.445" />
     <axis xyz="0 0 1"/>
       <limit effort="0.0" lower="-3.14159" upper="3.14159" velocity="0.0"/>
    </joint>
    <link name="Part4">
        <inertial>
            <origin xyz="0.0 0.0 -0.315" rpy="0 0 0"/>
            <mass value="1" />
            <inertia ixx="100" ixy="0" ixz="0" iyy="100" iyz="0" izz="100" />
        </inertial>
        <visual>
            <origin xyz="0.0 0.0 -0.315" rpy="0 0 0"/>
            <geometry>
                <box size="0.86 0.53 0.63" />
            </geometry>
            <material name="Blue">
                <color rgba="0.0 0.5 1.0 1.0"/>
            </material>
        </visual>
        <collision>
            <origin xyz="0.0 0.0 -0.315" rpy="0 0 0"/>
            <geometry>
                <box size="0.86 0.53 0.63" />
            </geometry>
        </collision>
    </link>
    <joint name="Part3_Part5" type="revolute">
       <parent link="Part3"/>
       <child  link="Part5"/>
       <origin rpy="0 0 0" xyz="0.0 -0.265 -0.315" />
     <axis xyz="1 0 0"/>
       <limit effort="0.0" lower="-3.14159" upper="3.14159" velocity="0.0"/>
    </joint>
    <link name="Part5">
        <inertial>
            <origin xyz="0.0 -0.255 0.0" rpy="0 0 0"/>
            <mass value="1" />
            <inertia ixx="100" ixy="0" ixz="0" iyy="100" iyz="0" izz="100" />
        </inertial>
        <visual>
            <origin xyz="0.0 -0.255 0.0" rpy="0 0 0"/>
            <geometry>
                <box size="0.97 0.51 0.46" />
            </geometry>
            <material name="Blue">
                <color rgba="0.0 0.5 1.0 1.0"/>
            </material>
        </visual>
        <collision>
            <origin xyz="0.0 -0.255 0.0" rpy="0 0 0"/>
            <geometry>
                <box size="0.97 0.51 0.46" />
            </geometry>
        </collision>
    </link>
    <joint name="Part4_Part6" type="revolute">
       <parent link="Part4"/>
       <child  link="Part6"/>
       <origin rpy="0 0 0" xyz="0.0 -0.265 -0.315" />
     <axis xyz="1 0 0"/>
       <limit effort="0.0" lower="-3.14159" upper="3.14159" velocity="0.0"/>
    </joint>
    <link name="Part6">
        <inertial>
            <origin xyz="0.0 -0.255 0.0" rpy="0 0 0"/>
            <mass value="1" />
            <inertia ixx="100" ixy="0" ixz="0" iyy="100" iyz="0" izz="100" />
        </inertial>
        <visual>
            <origin xyz="0.0 -0.255 0.0" rpy="0 0 0"/>
            <geometry>
                <box size="0.97 0.51 0.46" />
            </geometry>
            <material name="Blue">
                <color rgba="0.0 0.5 1.0 1.0"/>
            </material>
        </visual>
        <collision>
            <origin xyz="0.0 -0.255 0.0" rpy="0 0 0"/>
            <geometry>
                <box size="0.97 0.51 0.46" />
            </geometry>
        </collision>
    </link>
    <joint name="Part3_Part7" type="revolute">
       <parent link="Part3"/>
       <child  link="Part7"/>
       <origin rpy="0 0 0" xyz="0.0 0.265 -0.315" />
     <axis xyz="0 0 1"/>
       <limit effort="0.0" lower="-3.14159" upper="3.14159" velocity="0.0"/>
    </joint>
    <link name="Part7">
        <inertial>
            <origin xyz="0.0 0.41 0.0" rpy="0 0 0"/>
            <mass value="1" />
            <inertia ixx="100" ixy="0" ixz="0" iyy="100" iyz="0" izz="100" />
        </inertial>
        <visual>
            <origin xyz="0.0 0.41 0.0" rpy="0 0 0"/>
            <geometry>
                <box size="0.42 0.82 0.28" />
            </geometry>
            <material name="Blue">
                <color rgba="0.0 0.5 1.0 1.0"/>
            </material>
        </visual>
        <collision>
            <origin xyz="0.0 0.41 0.0" rpy="0 0 0"/>
            <geometry>
                <box size="0.42 0.82 0.28" />
            </geometry>
        </collision>
    </link>
    <joint name="Part4_Part8" type="revolute">
       <parent link="Part4"/>
       <child  link="Part8"/>
       <origin rpy="0 0 0" xyz="0.0 0.265 -0.315" />
     <axis xyz="0 0 1"/>
       <limit effort="0.0" lower="-3.14159" upper="3.14159" velocity="0.0"/>
    </joint>
    <link name="Part8">
        <inertial>
            <origin xyz="0.0 0.41 0.0" rpy="0 0 0"/>
            <mass value="1" />
            <inertia ixx="100" ixy="0" ixz="0" iyy="100" iyz="0" izz="100" />
        </inertial>
        <visual>
            <origin xyz="0.0 0.41 0.0" rpy="0 0 0"/>
            <geometry>
                <box size="0.42 0.82 0.28" />
            </geometry>
            <material name="Blue">
                <color rgba="0.0 0.5 1.0 1.0"/>
            </material>
        </visual>
        <collision>
            <origin xyz="0.0 0.41 0.0" rpy="0 0 0"/>
            <geometry>
                <box size="0.42 0.82 0.28" />
            </geometry>
        </collision>
    </link>
    <joint name="Part5_Part9" type="revolute">
       <parent link="Part5"/>
       <child  link="Part9"/>
       <origin rpy="0 0 0" xyz="0.0 -0.255 -0.23" />
     <axis xyz="0 1 0"/>
       <limit effort="0.0" lower="-3.14159" upper="3.14159" velocity="0.0"/>
    </joint>
    <link name="Part9">
        <inertial>
            <origin xyz="0.0 0.0 -0.465" rpy="0 0 0"/>
            <mass value="1" />
            <inertia ixx="100" ixy="0" ixz="0" iyy="100" iyz="0" izz="100" />
        </inertial>
        <visual>
            <origin xyz="0.0 0.0 -0.465" rpy="0 0 0"/>
            <geometry>
                <box size="0.65 0.51 0.93" />
            </geometry>
            <material name="Green">
                <color rgba="0.0 1.0 0.0 1.0"/>
            </material>
        </visual>
        <collision>
            <origin xyz="0.0 0.0 -0.465" rpy="0 0 0"/>
            <geometry>
                <box size="0.65 0.51 0.93" />
            </geometry>
        </collision>
    </link>
    <joint name="Part6_Part10" type="revolute">
       <parent link="Part6"/>
       <child  link="Part10"/>
       <origin rpy="0 0 0" xyz="0.0 -0.255 -0.23" />
     <axis xyz="0 1 0"/>
       <limit effort="0.0" lower="-3.14159" upper="3.14159" velocity="0.0"/>
    </joint>
    <link name="Part10">
        <inertial>
            <origin xyz="0.0 0.0 -0.465" rpy="0 0 0"/>
            <mass value="1" />
            <inertia ixx="100" ixy="0" ixz="0" iyy="100" iyz="0" izz="100" />
        </inertial>
        <visual>
            <origin xyz="0.0 0.0 -0.465" rpy="0 0 0"/>
            <geometry>
                <box size="0.65 0.51 0.93" />
            </geometry>
            <material name="Green">
                <color rgba="0.0 1.0 0.0 1.0"/>
            </material>
        </visual>
        <collision>
            <origin xyz="0.0 0.0 -0.465" rpy="0 0 0"/>
            <geometry>
                <box size="0.65 0.51 0.93" />
            </geometry>
        </collision>
    </link>
    <joint name="Part5_Part11" type="revolute">
       <parent link="Part5"/>
       <child  link="Part11"/>
       <origin rpy="0 0 0" xyz="0.485 -0.255 0.0" />
     <axis xyz="1 0 0"/>
       <limit effort="0.0" lower="-3.14159" upper="3.14159" velocity="0.0"/>
    </joint>
    <link name="Part11">
        <inertial>
            <origin xyz="0.42 0.0 0.0" rpy="0 0 0"/>
            <mass value="1" />
            <inertia ixx="100" ixy="0" ixz="0" iyy="100" iyz="0" izz="100" />
        </inertial>
        <visual>
            <origin xyz="0.42 0.0 0.0" rpy="0 0 0"/>
            <geometry>
                <box size="0.84 0.31 0.66" />
            </geometry>
            <material name="Blue">
                <color rgba="0.0 0.5 1.0 1.0"/>
            </material>
        </visual>
        <collision>
            <origin xyz="0.42 0.0 0.0" rpy="0 0 0"/>
            <geometry>
                <box size="0.84 0.31 0.66" />
            </geometry>
        </collision>
    </link>
    <joint name="Part6_Part12" type="revolute">
       <parent link="Part6"/>
       <child  link="Part12"/>
       <origin rpy="0 0 0" xyz="-0.485 -0.255 0.0" />
     <axis xyz="1 0 0"/>
       <limit effort="0.0" lower="-3.14159" upper="3.14159" velocity="0.0"/>
    </joint>
    <link name="Part12">
        <inertial>
            <origin xyz="-0.42 0.0 0.0" rpy="0 0 0"/>
            <mass value="1" />
            <inertia ixx="100" ixy="0" ixz="0" iyy="100" iyz="0" izz="100" />
        </inertial>
        <visual>
            <origin xyz="-0.42 0.0 0.0" rpy="0 0 0"/>
            <geometry>
                <box size="0.84 0.31 0.66" />
            </geometry>
            <material name="Blue">
                <color rgba="0.0 0.5 1.0 1.0"/>
            </material>
        </visual>
        <collision>
            <origin xyz="-0.42 0.0 0.0" rpy="0 0 0"/>
            <geometry>
                <box size="0.84 0.31 0.66" />
            </geometry>
        </collision>
    </link>
</robot>