<robot name = "robot">
    <link name="Part0">
        <inertial>
            <origin xyz="0 0 1.395" rpy="0 0 0"/>
            <mass value="1" />
            <inertia ixx="100" ixy="0" ixz="0" iyy="100" iyz="0" izz="100" />
        </inertial>
        <visual>
            <origin xyz="0 0 1.395" rpy="0 0 0"/>
            <geometry>
                <box size="0.74 0.26 0.33" />
            </geometry>
            <material name="Green">
                <color rgba="0.0 1.0 0.0 1.0"/>
            </material>
        </visual>
        <collision>
            <origin xyz="0 0 1.395" rpy="0 0 0"/>
            <geometry>
                <box size="0.74 0.26 0.33" />
            </geometry>
        </collision>
    </link>
    <joint name="Part0_Part1" type="revolute">
       <parent link="Part0"/>
       <child  link="Part1"/>
       <origin rpy="0 0 0" xyz="-0.37 0.0 1.395" />
     <axis xyz="0 0 1"/>
       <limit effort="0.0" lower="-3.14159" upper="3.14159" velocity="0.0"/>
    </joint>
    <link name="Part1">
        <inertial>
            <origin xyz="-0.14 0.0 0.0" rpy="0 0 0"/>
            <mass value="1" />
            <inertia ixx="100" ixy="0" ixz="0" iyy="100" iyz="0" izz="100" />
        </inertial>
        <visual>
            <origin xyz="-0.14 0.0 0.0" rpy="0 0 0"/>
            <geometry>
                <box size="0.28 0.59 0.85" />
            </geometry>
            <material name="Green">
                <color rgba="0.0 1.0 0.0 1.0"/>
            </material>
        </visual>
        <collision>
            <origin xyz="-0.14 0.0 0.0" rpy="0 0 0"/>
            <geometry>
                <box size="0.28 0.59 0.85" />
            </geometry>
        </collision>
    </link>
    <joint name="Part0_Part2" type="revolute">
       <parent link="Part0"/>
       <child  link="Part2"/>
       <origin rpy="0 0 0" xyz="0.37 0.0 1.395" />
     <axis xyz="0 0 1"/>
       <limit effort="0.0" lower="-3.14159" upper="3.14159" velocity="0.0"/>
    </joint>
    <link name="Part2">
        <inertial>
            <origin xyz="0.14 0.0 0.0" rpy="0 0 0"/>
            <mass value="1" />
            <inertia ixx="100" ixy="0" ixz="0" iyy="100" iyz="0" izz="100" />
        </inertial>
        <visual>
            <origin xyz="0.14 0.0 0.0" rpy="0 0 0"/>
            <geometry>
                <box size="0.28 0.59 0.85" />
            </geometry>
            <material name="Green">
                <color rgba="0.0 1.0 0.0 1.0"/>
            </material>
        </visual>
        <collision>
            <origin xyz="0.14 0.0 0.0" rpy="0 0 0"/>
            <geometry>
                <box size="0.28 0.59 0.85" />
            </geometry>
        </collision>
    </link>
    <joint name="Part2_Part3" type="revolute">
       <parent link="Part2"/>
       <child  link="Part3"/>
       <origin rpy="0 0 0" xyz="0.14 0.0 -0.425" />
     <axis xyz="0 0 1"/>
       <limit effort="0.0" lower="-3.14159" upper="3.14159" velocity="0.0"/>
    </joint>
    <link name="Part3">
        <inertial>
            <origin xyz="0.0 0.0 -0.485" rpy="0 0 0"/>
            <mass value="1" />
            <inertia ixx="100" ixy="0" ixz="0" iyy="100" iyz="0" izz="100" />
        </inertial>
        <visual>
            <origin xyz="0.0 0.0 -0.485" rpy="0 0 0"/>
            <geometry>
                <box size="0.45 0.78 0.97" />
            </geometry>
            <material name="Green">
                <color rgba="0.0 1.0 0.0 1.0"/>
            </material>
        </visual>
        <collision>
            <origin xyz="0.0 0.0 -0.485" rpy="0 0 0"/>
            <geometry>
                <box size="0.45 0.78 0.97" />
            </geometry>
        </collision>
    </link>
    <joint name="Part1_Part4" type="revolute">
       <parent link="Part1"/>
       <child  link="Part4"/>
       <origin rpy="0 0 0" xyz="-0.14 0.0 -0.425" />
     <axis xyz="0 0 1"/>
       <limit effort="0.0" lower="-3.14159" upper="3.14159" velocity="0.0"/>
    </joint>
    <link name="Part4">
        <inertial>
            <origin xyz="0.0 0.0 -0.485" rpy="0 0 0"/>
            <mass value="1" />
            <inertia ixx="100" ixy="0" ixz="0" iyy="100" iyz="0" izz="100" />
        </inertial>
        <visual>
            <origin xyz="0.0 0.0 -0.485" rpy="0 0 0"/>
            <geometry>
                <box size="0.45 0.78 0.97" />
            </geometry>
            <material name="Green">
                <color rgba="0.0 1.0 0.0 1.0"/>
            </material>
        </visual>
        <collision>
            <origin xyz="0.0 0.0 -0.485" rpy="0 0 0"/>
            <geometry>
                <box size="0.45 0.78 0.97" />
            </geometry>
        </collision>
    </link>
    <joint name="Part2_Part5" type="revolute">
       <parent link="Part2"/>
       <child  link="Part5"/>
       <origin rpy="0 0 0" xyz="0.14 0.295 0.0" />
     <axis xyz="1 0 0"/>
       <limit effort="0.0" lower="-3.14159" upper="3.14159" velocity="0.0"/>
    </joint>
    <link name="Part5">
        <inertial>
            <origin xyz="0.0 0.15 0.0" rpy="0 0 0"/>
            <mass value="1" />
            <inertia ixx="100" ixy="0" ixz="0" iyy="100" iyz="0" izz="100" />
        </inertial>
        <visual>
            <origin xyz="0.0 0.15 0.0" rpy="0 0 0"/>
            <geometry>
                <box size="0.46 0.3 0.65" />
            </geometry>
            <material name="Green">
                <color rgba="0.0 1.0 0.0 1.0"/>
            </material>
        </visual>
        <collision>
            <origin xyz="0.0 0.15 0.0" rpy="0 0 0"/>
            <geometry>
                <box size="0.46 0.3 0.65" />
            </geometry>
        </collision>
    </link>
    <joint name="Part1_Part6" type="revolute">
       <parent link="Part1"/>
       <child  link="Part6"/>
       <origin rpy="0 0 0" xyz="-0.14 0.295 0.0" />
     <axis xyz="1 0 0"/>
       <limit effort="0.0" lower="-3.14159" upper="3.14159" velocity="0.0"/>
    </joint>
    <link name="Part6">
        <inertial>
            <origin xyz="0.0 0.15 0.0" rpy="0 0 0"/>
            <mass value="1" />
            <inertia ixx="100" ixy="0" ixz="0" iyy="100" iyz="0" izz="100" />
        </inertial>
        <visual>
            <origin xyz="0.0 0.15 0.0" rpy="0 0 0"/>
            <geometry>
                <box size="0.46 0.3 0.65" />
            </geometry>
            <material name="Green">
                <color rgba="0.0 1.0 0.0 1.0"/>
            </material>
        </visual>
        <collision>
            <origin xyz="0.0 0.15 0.0" rpy="0 0 0"/>
            <geometry>
                <box size="0.46 0.3 0.65" />
            </geometry>
        </collision>
    </link>
    <joint name="Part2_Part7" type="revolute">
       <parent link="Part2"/>
       <child  link="Part7"/>
       <origin rpy="0 0 0" xyz="0.14 0.0 0.425" />
     <axis xyz="0 1 0"/>
       <limit effort="0.0" lower="-3.14159" upper="3.14159" velocity="0.0"/>
    </joint>
    <link name="Part7">
        <inertial>
            <origin xyz="0.0 0.0 0.43" rpy="0 0 0"/>
            <mass value="1" />
            <inertia ixx="100" ixy="0" ixz="0" iyy="100" iyz="0" izz="100" />
        </inertial>
        <visual>
            <origin xyz="0.0 0.0 0.43" rpy="0 0 0"/>
            <geometry>
                <box size="0.82 0.41 0.86" />
            </geometry>
            <material name="Green">
                <color rgba="0.0 1.0 0.0 1.0"/>
            </material>
        </visual>
        <collision>
            <origin xyz="0.0 0.0 0.43" rpy="0 0 0"/>
            <geometry>
                <box size="0.82 0.41 0.86" />
            </geometry>
        </collision>
    </link>
    <joint name="Part1_Part8" type="revolute">
       <parent link="Part1"/>
       <child  link="Part8"/>
       <origin rpy="0 0 0" xyz="-0.14 0.0 0.425" />
     <axis xyz="0 1 0"/>
       <limit effort="0.0" lower="-3.14159" upper="3.14159" velocity="0.0"/>
    </joint>
    <link name="Part8">
        <inertial>
            <origin xyz="0.0 0.0 0.43" rpy="0 0 0"/>
            <mass value="1" />
            <inertia ixx="100" ixy="0" ixz="0" iyy="100" iyz="0" izz="100" />
        </inertial>
        <visual>
            <origin xyz="0.0 0.0 0.43" rpy="0 0 0"/>
            <geometry>
                <box size="0.82 0.41 0.86" />
            </geometry>
            <material name="Green">
                <color rgba="0.0 1.0 0.0 1.0"/>
            </material>
        </visual>
        <collision>
            <origin xyz="0.0 0.0 0.43" rpy="0 0 0"/>
            <geometry>
                <box size="0.82 0.41 0.86" />
            </geometry>
        </collision>
    </link>
    <joint name="Part5_Part9" type="revolute">
       <parent link="Part5"/>
       <child  link="Part9"/>
       <origin rpy="0 0 0" xyz="0.23 0.15 0.0" />
     <axis xyz="0 1 0"/>
       <limit effort="0.0" lower="-3.14159" upper="3.14159" velocity="0.0"/>
    </joint>
    <link name="Part9">
        <inertial>
            <origin xyz="0.495 0.0 0.0" rpy="0 0 0"/>
            <mass value="1" />
            <inertia ixx="100" ixy="0" ixz="0" iyy="100" iyz="0" izz="100" />
        </inertial>
        <visual>
            <origin xyz="0.495 0.0 0.0" rpy="0 0 0"/>
            <geometry>
                <box size="0.99 0.4 0.9" />
            </geometry>
            <material name="Green">
                <color rgba="0.0 1.0 0.0 1.0"/>
            </material>
        </visual>
        <collision>
            <origin xyz="0.495 0.0 0.0" rpy="0 0 0"/>
            <geometry>
                <box size="0.99 0.4 0.9" />
            </geometry>
        </collision>
    </link>
    <joint name="Part6_Part10" type="revolute">
       <parent link="Part6"/>
       <child  link="Part10"/>
       <origin rpy="0 0 0" xyz="-0.23 0.15 0.0" />
     <axis xyz="0 1 0"/>
       <limit effort="0.0" lower="-3.14159" upper="3.14159" velocity="0.0"/>
    </joint>
    <link name="Part10">
        <inertial>
            <origin xyz="-0.495 0.0 0.0" rpy="0 0 0"/>
            <mass value="1" />
            <inertia ixx="100" ixy="0" ixz="0" iyy="100" iyz="0" izz="100" />
        </inertial>
        <visual>
            <origin xyz="-0.495 0.0 0.0" rpy="0 0 0"/>
            <geometry>
                <box size="0.99 0.4 0.9" />
            </geometry>
            <material name="Green">
                <color rgba="0.0 1.0 0.0 1.0"/>
            </material>
        </visual>
        <collision>
            <origin xyz="-0.495 0.0 0.0" rpy="0 0 0"/>
            <geometry>
                <box size="0.99 0.4 0.9" />
            </geometry>
        </collision>
    </link>
    <joint name="Part8_Part11" type="revolute">
       <parent link="Part8"/>
       <child  link="Part11"/>
       <origin rpy="0 0 0" xyz="-0.41 0.0 0.43" />
     <axis xyz="0 1 0"/>
       <limit effort="0.0" lower="-3.14159" upper="3.14159" velocity="0.0"/>
    </joint>
    <link name="Part11">
        <inertial>
            <origin xyz="-0.125 0.0 0.0" rpy="0 0 0"/>
            <mass value="1" />
            <inertia ixx="100" ixy="0" ixz="0" iyy="100" iyz="0" izz="100" />
        </inertial>
        <visual>
            <origin xyz="-0.125 0.0 0.0" rpy="0 0 0"/>
            <geometry>
                <box size="0.25 0.32 0.9" />
            </geometry>
            <material name="Blue">
                <color rgba="0.0 0.5 1.0 1.0"/>
            </material>
        </visual>
        <collision>
            <origin xyz="-0.125 0.0 0.0" rpy="0 0 0"/>
            <geometry>
                <box size="0.25 0.32 0.9" />
            </geometry>
        </collision>
    </link>
    <joint name="Part7_Part12" type="revolute">
       <parent link="Part7"/>
       <child  link="Part12"/>
       <origin rpy="0 0 0" xyz="0.41 0.0 0.43" />
     <axis xyz="0 1 0"/>
       <limit effort="0.0" lower="-3.14159" upper="3.14159" velocity="0.0"/>
    </joint>
    <link name="Part12">
        <inertial>
            <origin xyz="0.125 0.0 0.0" rpy="0 0 0"/>
            <mass value="1" />
            <inertia ixx="100" ixy="0" ixz="0" iyy="100" iyz="0" izz="100" />
        </inertial>
        <visual>
            <origin xyz="0.125 0.0 0.0" rpy="0 0 0"/>
            <geometry>
                <box size="0.25 0.32 0.9" />
            </geometry>
            <material name="Blue">
                <color rgba="0.0 0.5 1.0 1.0"/>
            </material>
        </visual>
        <collision>
            <origin xyz="0.125 0.0 0.0" rpy="0 0 0"/>
            <geometry>
                <box size="0.25 0.32 0.9" />
            </geometry>
        </collision>
    </link>
</robot>