<robot name = "robot">
    <link name="Part0">
        <inertial>
            <origin xyz="0 0 0.665" rpy="0 0 0"/>
            <mass value="1" />
            <inertia ixx="100" ixy="0" ixz="0" iyy="100" iyz="0" izz="100" />
        </inertial>
        <visual>
            <origin xyz="0 0 0.665" rpy="0 0 0"/>
            <geometry>
                <box size="0.26 0.91 0.9" />
            </geometry>
            <material name="Green">
                <color rgba="0.0 1.0 0.0 1.0"/>
            </material>
        </visual>
        <collision>
            <origin xyz="0 0 0.665" rpy="0 0 0"/>
            <geometry>
                <box size="0.26 0.91 0.9" />
            </geometry>
        </collision>
    </link>
    <joint name="Part0_Part1" type="revolute">
       <parent link="Part0"/>
       <child  link="Part1"/>
       <origin rpy="0 0 0" xyz="0.13 0.0 0.665" />
     <axis xyz="1 0 0"/>
       <limit effort="0.0" lower="-3.14159" upper="3.14159" velocity="0.0"/>
    </joint>
    <link name="Part1">
        <inertial>
            <origin xyz="0.245 0.0 0.0" rpy="0 0 0"/>
            <mass value="1" />
            <inertia ixx="100" ixy="0" ixz="0" iyy="100" iyz="0" izz="100" />
        </inertial>
        <visual>
            <origin xyz="0.245 0.0 0.0" rpy="0 0 0"/>
            <geometry>
                <box size="0.49 0.5 0.83" />
            </geometry>
            <material name="Green">
                <color rgba="0.0 1.0 0.0 1.0"/>
            </material>
        </visual>
        <collision>
            <origin xyz="0.245 0.0 0.0" rpy="0 0 0"/>
            <geometry>
                <box size="0.49 0.5 0.83" />
            </geometry>
        </collision>
    </link>
    <joint name="Part1_Part2" type="revolute">
       <parent link="Part1"/>
       <child  link="Part2"/>
       <origin rpy="0 0 0" xyz="0.245 0.25 0.0" />
     <axis xyz="1 0 0"/>
       <limit effort="0.0" lower="-3.14159" upper="3.14159" velocity="0.0"/>
    </joint>
    <link name="Part2">
        <inertial>
            <origin xyz="0.0 0.465 0.0" rpy="0 0 0"/>
            <mass value="1" />
            <inertia ixx="100" ixy="0" ixz="0" iyy="100" iyz="0" izz="100" />
        </inertial>
        <visual>
            <origin xyz="0.0 0.465 0.0" rpy="0 0 0"/>
            <geometry>
                <box size="0.63 0.93 0.82" />
            </geometry>
            <material name="Green">
                <color rgba="0.0 1.0 0.0 1.0"/>
            </material>
        </visual>
        <collision>
            <origin xyz="0.0 0.465 0.0" rpy="0 0 0"/>
            <geometry>
                <box size="0.63 0.93 0.82" />
            </geometry>
        </collision>
    </link>
    <joint name="Part2_Part3" type="revolute">
       <parent link="Part2"/>
       <child  link="Part3"/>
       <origin rpy="0 0 0" xyz="0.315 0.465 0.0" />
     <axis xyz="1 0 0"/>
       <limit effort="0.0" lower="-3.14159" upper="3.14159" velocity="0.0"/>
    </joint>
    <link name="Part3">
        <inertial>
            <origin xyz="0.275 0.0 0.0" rpy="0 0 0"/>
            <mass value="1" />
            <inertia ixx="100" ixy="0" ixz="0" iyy="100" iyz="0" izz="100" />
        </inertial>
        <visual>
            <origin xyz="0.275 0.0 0.0" rpy="0 0 0"/>
            <geometry>
                <box size="0.55 0.64 0.55" />
            </geometry>
            <material name="Blue">
                <color rgba="0.0 0.5 1.0 1.0"/>
            </material>
        </visual>
        <collision>
            <origin xyz="0.275 0.0 0.0" rpy="0 0 0"/>
            <geometry>
                <box size="0.55 0.64 0.55" />
            </geometry>
        </collision>
    </link>
    <joint name="Part2_Part4" type="revolute">
       <parent link="Part2"/>
       <child  link="Part4"/>
       <origin rpy="0 0 0" xyz="0.315 0.465 0.0" />
     <axis xyz="0 1 0"/>
       <limit effort="0.0" lower="-3.14159" upper="3.14159" velocity="0.0"/>
    </joint>
    <link name="Part4">
        <inertial>
            <origin xyz="0.16 0.0 0.0" rpy="0 0 0"/>
            <mass value="1" />
            <inertia ixx="100" ixy="0" ixz="0" iyy="100" iyz="0" izz="100" />
        </inertial>
        <visual>
            <origin xyz="0.16 0.0 0.0" rpy="0 0 0"/>
            <geometry>
                <box size="0.32 0.51 0.46" />
            </geometry>
            <material name="Blue">
                <color rgba="0.0 0.5 1.0 1.0"/>
            </material>
        </visual>
        <collision>
            <origin xyz="0.16 0.0 0.0" rpy="0 0 0"/>
            <geometry>
                <box size="0.32 0.51 0.46" />
            </geometry>
        </collision>
    </link>
    <joint name="Part2_Part5" type="revolute">
       <parent link="Part2"/>
       <child  link="Part5"/>
       <origin rpy="0 0 0" xyz="-0.315 0.465 0.0" />
     <axis xyz="0 0 1"/>
       <limit effort="0.0" lower="-3.14159" upper="3.14159" velocity="0.0"/>
    </joint>
    <link name="Part5">
        <inertial>
            <origin xyz="-0.245 0.0 0.0" rpy="0 0 0"/>
            <mass value="1" />
            <inertia ixx="100" ixy="0" ixz="0" iyy="100" iyz="0" izz="100" />
        </inertial>
        <visual>
            <origin xyz="-0.245 0.0 0.0" rpy="0 0 0"/>
            <geometry>
                <box size="0.49 0.77 0.86" />
            </geometry>
            <material name="Blue">
                <color rgba="0.0 0.5 1.0 1.0"/>
            </material>
        </visual>
        <collision>
            <origin xyz="-0.245 0.0 0.0" rpy="0 0 0"/>
            <geometry>
                <box size="0.49 0.77 0.86" />
            </geometry>
        </collision>
    </link>
    <joint name="Part5_Part6" type="revolute">
       <parent link="Part5"/>
       <child  link="Part6"/>
       <origin rpy="0 0 0" xyz="-0.49 0.0 0.0" />
     <axis xyz="0 1 0"/>
       <limit effort="0.0" lower="-3.14159" upper="3.14159" velocity="0.0"/>
    </joint>
    <link name="Part6">
        <inertial>
            <origin xyz="-0.135 0.0 0.0" rpy="0 0 0"/>
            <mass value="1" />
            <inertia ixx="100" ixy="0" ixz="0" iyy="100" iyz="0" izz="100" />
        </inertial>
        <visual>
            <origin xyz="-0.135 0.0 0.0" rpy="0 0 0"/>
            <geometry>
                <box size="0.27 0.86 0.38" />
            </geometry>
            <material name="Green">
                <color rgba="0.0 1.0 0.0 1.0"/>
            </material>
        </visual>
        <collision>
            <origin xyz="-0.135 0.0 0.0" rpy="0 0 0"/>
            <geometry>
                <box size="0.27 0.86 0.38" />
            </geometry>
        </collision>
    </link>
    <joint name="Part1_Part7" type="revolute">
       <parent link="Part1"/>
       <child  link="Part7"/>
       <origin rpy="0 0 0" xyz="0.245 -0.25 0.0" />
     <axis xyz="0 1 0"/>
       <limit effort="0.0" lower="-3.14159" upper="3.14159" velocity="0.0"/>
    </joint>
    <link name="Part7">
        <inertial>
            <origin xyz="0.0 -0.26 0.0" rpy="0 0 0"/>
            <mass value="1" />
            <inertia ixx="100" ixy="0" ixz="0" iyy="100" iyz="0" izz="100" />
        </inertial>
        <visual>
            <origin xyz="0.0 -0.26 0.0" rpy="0 0 0"/>
            <geometry>
                <box size="0.33 0.52 0.59" />
            </geometry>
            <material name="Blue">
                <color rgba="0.0 0.5 1.0 1.0"/>
            </material>
        </visual>
        <collision>
            <origin xyz="0.0 -0.26 0.0" rpy="0 0 0"/>
            <geometry>
                <box size="0.33 0.52 0.59" />
            </geometry>
        </collision>
    </link>
    <joint name="Part2_Part8" type="revolute">
       <parent link="Part2"/>
       <child  link="Part8"/>
       <origin rpy="0 0 0" xyz="0.0 0.465 0.41" />
     <axis xyz="0 0 1"/>
       <limit effort="0.0" lower="-3.14159" upper="3.14159" velocity="0.0"/>
    </joint>
    <link name="Part8">
        <inertial>
            <origin xyz="0.0 0.0 0.3" rpy="0 0 0"/>
            <mass value="1" />
            <inertia ixx="100" ixy="0" ixz="0" iyy="100" iyz="0" izz="100" />
        </inertial>
        <visual>
            <origin xyz="0.0 0.0 0.3" rpy="0 0 0"/>
            <geometry>
                <box size="1.0 0.58 0.6" />
            </geometry>
            <material name="Blue">
                <color rgba="0.0 0.5 1.0 1.0"/>
            </material>
        </visual>
        <collision>
            <origin xyz="0.0 0.0 0.3" rpy="0 0 0"/>
            <geometry>
                <box size="1.0 0.58 0.6" />
            </geometry>
        </collision>
    </link>
    <joint name="Part3_Part9" type="revolute">
       <parent link="Part3"/>
       <child  link="Part9"/>
       <origin rpy="0 0 0" xyz="0.55 0.0 0.0" />
     <axis xyz="1 0 0"/>
       <limit effort="0.0" lower="-3.14159" upper="3.14159" velocity="0.0"/>
    </joint>
    <link name="Part9">
        <inertial>
            <origin xyz="0.19 0.0 0.0" rpy="0 0 0"/>
            <mass value="1" />
            <inertia ixx="100" ixy="0" ixz="0" iyy="100" iyz="0" izz="100" />
        </inertial>
        <visual>
            <origin xyz="0.19 0.0 0.0" rpy="0 0 0"/>
            <geometry>
                <box size="0.38 0.47 0.73" />
            </geometry>
            <material name="Green">
                <color rgba="0.0 1.0 0.0 1.0"/>
            </material>
        </visual>
        <collision>
            <origin xyz="0.19 0.0 0.0" rpy="0 0 0"/>
            <geometry>
                <box size="0.38 0.47 0.73" />
            </geometry>
        </collision>
    </link>
    <joint name="Part6_Part10" type="revolute">
       <parent link="Part6"/>
       <child  link="Part10"/>
       <origin rpy="0 0 0" xyz="-0.27 0.0 0.0" />
     <axis xyz="1 0 0"/>
       <limit effort="0.0" lower="-3.14159" upper="3.14159" velocity="0.0"/>
    </joint>
    <link name="Part10">
        <inertial>
            <origin xyz="-0.395 0.0 0.0" rpy="0 0 0"/>
            <mass value="1" />
            <inertia ixx="100" ixy="0" ixz="0" iyy="100" iyz="0" izz="100" />
        </inertial>
        <visual>
            <origin xyz="-0.395 0.0 0.0" rpy="0 0 0"/>
            <geometry>
                <box size="0.79 1.0 0.53" />
            </geometry>
            <material name="Blue">
                <color rgba="0.0 0.5 1.0 1.0"/>
            </material>
        </visual>
        <collision>
            <origin xyz="-0.395 0.0 0.0" rpy="0 0 0"/>
            <geometry>
                <box size="0.79 1.0 0.53" />
            </geometry>
        </collision>
    </link>
    <joint name="Part10_Part11" type="revolute">
       <parent link="Part10"/>
       <child  link="Part11"/>
       <origin rpy="0 0 0" xyz="-0.79 0.0 0.0" />
     <axis xyz="0 1 0"/>
       <limit effort="0.0" lower="-3.14159" upper="3.14159" velocity="0.0"/>
    </joint>
    <link name="Part11">
        <inertial>
            <origin xyz="-0.35 0.0 0.0" rpy="0 0 0"/>
            <mass value="1" />
            <inertia ixx="100" ixy="0" ixz="0" iyy="100" iyz="0" izz="100" />
        </inertial>
        <visual>
            <origin xyz="-0.35 0.0 0.0" rpy="0 0 0"/>
            <geometry>
                <box size="0.7 0.76 0.71" />
            </geometry>
            <material name="Blue">
                <color rgba="0.0 0.5 1.0 1.0"/>
            </material>
        </visual>
        <collision>
            <origin xyz="-0.35 0.0 0.0" rpy="0 0 0"/>
            <geometry>
                <box size="0.7 0.76 0.71" />
            </geometry>
        </collision>
    </link>
    <joint name="Part11_Part12" type="revolute">
       <parent link="Part11"/>
       <child  link="Part12"/>
       <origin rpy="0 0 0" xyz="-0.35 0.0 -0.355" />
     <axis xyz="1 0 0"/>
       <limit effort="0.0" lower="-3.14159" upper="3.14159" velocity="0.0"/>
    </joint>
    <link name="Part12">
        <inertial>
            <origin xyz="0.0 0.0 -0.155" rpy="0 0 0"/>
            <mass value="1" />
            <inertia ixx="100" ixy="0" ixz="0" iyy="100" iyz="0" izz="100" />
        </inertial>
        <visual>
            <origin xyz="0.0 0.0 -0.155" rpy="0 0 0"/>
            <geometry>
                <box size="0.88 0.52 0.31" />
            </geometry>
            <material name="Blue">
                <color rgba="0.0 0.5 1.0 1.0"/>
            </material>
        </visual>
        <collision>
            <origin xyz="0.0 0.0 -0.155" rpy="0 0 0"/>
            <geometry>
                <box size="0.88 0.52 0.31" />
            </geometry>
        </collision>
    </link>
</robot>