<robot name = "robot">
    <link name="Part0">
        <inertial>
            <origin xyz="0 0 0.405" rpy="0 0 0"/>
            <mass value="1" />
            <inertia ixx="100" ixy="0" ixz="0" iyy="100" iyz="0" izz="100" />
        </inertial>
        <visual>
            <origin xyz="0 0 0.405" rpy="0 0 0"/>
            <geometry>
                <box size="0.8 0.41 0.81" />
            </geometry>
            <material name="Blue">
                <color rgba="0.0 0.5 1.0 1.0"/>
            </material>
        </visual>
        <collision>
            <origin xyz="0 0 0.405" rpy="0 0 0"/>
            <geometry>
                <box size="0.8 0.41 0.81" />
            </geometry>
        </collision>
    </link>
    <joint name="Part0_Part1" type="revolute">
       <parent link="Part0"/>
       <child  link="Part1"/>
       <origin rpy="0 0 0" xyz="0.0 0.0 0.81" />
     <axis xyz="0 1 0"/>
       <limit effort="0.0" lower="-3.14159" upper="3.14159" velocity="0.0"/>
    </joint>
    <link name="Part1">
        <inertial>
            <origin xyz="0.0 0.0 0.34" rpy="0 0 0"/>
            <mass value="1" />
            <inertia ixx="100" ixy="0" ixz="0" iyy="100" iyz="0" izz="100" />
        </inertial>
        <visual>
            <origin xyz="0.0 0.0 0.34" rpy="0 0 0"/>
            <geometry>
                <box size="0.85 0.3 0.68" />
            </geometry>
            <material name="Green">
                <color rgba="0.0 1.0 0.0 1.0"/>
            </material>
        </visual>
        <collision>
            <origin xyz="0.0 0.0 0.34" rpy="0 0 0"/>
            <geometry>
                <box size="0.85 0.3 0.68" />
            </geometry>
        </collision>
    </link>
    <joint name="Part1_Part2" type="revolute">
       <parent link="Part1"/>
       <child  link="Part2"/>
       <origin rpy="0 0 0" xyz="0.0 0.0 0.68" />
     <axis xyz="0 1 0"/>
       <limit effort="0.0" lower="-3.14159" upper="3.14159" velocity="0.0"/>
    </joint>
    <link name="Part2">
        <inertial>
            <origin xyz="0.0 0.0 0.36" rpy="0 0 0"/>
            <mass value="1" />
            <inertia ixx="100" ixy="0" ixz="0" iyy="100" iyz="0" izz="100" />
        </inertial>
        <visual>
            <origin xyz="0.0 0.0 0.36" rpy="0 0 0"/>
            <geometry>
                <box size="0.69 0.85 0.72" />
            </geometry>
            <material name="Blue">
                <color rgba="0.0 0.5 1.0 1.0"/>
            </material>
        </visual>
        <collision>
            <origin xyz="0.0 0.0 0.36" rpy="0 0 0"/>
            <geometry>
                <box size="0.69 0.85 0.72" />
            </geometry>
        </collision>
    </link>
    <joint name="Part2_Part3" type="revolute">
       <parent link="Part2"/>
       <child  link="Part3"/>
       <origin rpy="0 0 0" xyz="0.0 0.425 0.36" />
     <axis xyz="0 1 0"/>
       <limit effort="0.0" lower="-3.14159" upper="3.14159" velocity="0.0"/>
    </joint>
    <link name="Part3">
        <inertial>
            <origin xyz="0.0 0.475 0.0" rpy="0 0 0"/>
            <mass value="1" />
            <inertia ixx="100" ixy="0" ixz="0" iyy="100" iyz="0" izz="100" />
        </inertial>
        <visual>
            <origin xyz="0.0 0.475 0.0" rpy="0 0 0"/>
            <geometry>
                <box size="0.83 0.95 0.4" />
            </geometry>
            <material name="Blue">
                <color rgba="0.0 0.5 1.0 1.0"/>
            </material>
        </visual>
        <collision>
            <origin xyz="0.0 0.475 0.0" rpy="0 0 0"/>
            <geometry>
                <box size="0.83 0.95 0.4" />
            </geometry>
        </collision>
    </link>
    <joint name="Part3_Part4" type="revolute">
       <parent link="Part3"/>
       <child  link="Part4"/>
       <origin rpy="0 0 0" xyz="0.0 0.95 0.0" />
     <axis xyz="0 0 1"/>
       <limit effort="0.0" lower="-3.14159" upper="3.14159" velocity="0.0"/>
    </joint>
    <link name="Part4">
        <inertial>
            <origin xyz="0.0 0.38 0.0" rpy="0 0 0"/>
            <mass value="1" />
            <inertia ixx="100" ixy="0" ixz="0" iyy="100" iyz="0" izz="100" />
        </inertial>
        <visual>
            <origin xyz="0.0 0.38 0.0" rpy="0 0 0"/>
            <geometry>
                <box size="0.51 0.76 0.49" />
            </geometry>
            <material name="Green">
                <color rgba="0.0 1.0 0.0 1.0"/>
            </material>
        </visual>
        <collision>
            <origin xyz="0.0 0.38 0.0" rpy="0 0 0"/>
            <geometry>
                <box size="0.51 0.76 0.49" />
            </geometry>
        </collision>
    </link>
    <joint name="Part3_Part5" type="revolute">
       <parent link="Part3"/>
       <child  link="Part5"/>
       <origin rpy="0 0 0" xyz="-0.415 0.475 0.0" />
     <axis xyz="1 0 0"/>
       <limit effort="0.0" lower="-3.14159" upper="3.14159" velocity="0.0"/>
    </joint>
    <link name="Part5">
        <inertial>
            <origin xyz="-0.38 0.0 0.0" rpy="0 0 0"/>
            <mass value="1" />
            <inertia ixx="100" ixy="0" ixz="0" iyy="100" iyz="0" izz="100" />
        </inertial>
        <visual>
            <origin xyz="-0.38 0.0 0.0" rpy="0 0 0"/>
            <geometry>
                <box size="0.76 0.27 0.59" />
            </geometry>
            <material name="Blue">
                <color rgba="0.0 0.5 1.0 1.0"/>
            </material>
        </visual>
        <collision>
            <origin xyz="-0.38 0.0 0.0" rpy="0 0 0"/>
            <geometry>
                <box size="0.76 0.27 0.59" />
            </geometry>
        </collision>
    </link>
</robot>