<robot name = "robot">
    <link name="Part0">
        <inertial>
            <origin xyz="0 0 0.83" rpy="0 0 0"/>
            <mass value="1" />
            <inertia ixx="100" ixy="0" ixz="0" iyy="100" iyz="0" izz="100" />
        </inertial>
        <visual>
            <origin xyz="0 0 0.83" rpy="0 0 0"/>
            <geometry>
                <box size="0.52 0.79 0.28" />
            </geometry>
            <material name="Green">
                <color rgba="0.0 1.0 0.0 1.0"/>
            </material>
        </visual>
        <collision>
            <origin xyz="0 0 0.83" rpy="0 0 0"/>
            <geometry>
                <box size="0.52 0.79 0.28" />
            </geometry>
        </collision>
    </link>
    <joint name="Part0_Part1" type="revolute">
       <parent link="Part0"/>
       <child  link="Part1"/>
       <origin rpy="0 0 0" xyz="0.0 0.0 0.69" />
     <axis xyz="1 0 0"/>
       <limit effort="0.0" lower="-3.14159" upper="3.14159" velocity="0.0"/>
    </joint>
    <link name="Part1">
        <inertial>
            <origin xyz="0.0 0.0 -0.345" rpy="0 0 0"/>
            <mass value="1" />
            <inertia ixx="100" ixy="0" ixz="0" iyy="100" iyz="0" izz="100" />
        </inertial>
        <visual>
            <origin xyz="0.0 0.0 -0.345" rpy="0 0 0"/>
            <geometry>
                <box size="0.95 0.54 0.69" />
            </geometry>
            <material name="Green">
                <color rgba="0.0 1.0 0.0 1.0"/>
            </material>
        </visual>
        <collision>
            <origin xyz="0.0 0.0 -0.345" rpy="0 0 0"/>
            <geometry>
                <box size="0.95 0.54 0.69" />
            </geometry>
        </collision>
    </link>
    <joint name="Part0_Part2" type="revolute">
       <parent link="Part0"/>
       <child  link="Part2"/>
       <origin rpy="0 0 0" xyz="0.0 0.0 0.97" />
     <axis xyz="1 0 0"/>
       <limit effort="0.0" lower="-3.14159" upper="3.14159" velocity="0.0"/>
    </joint>
    <link name="Part2">
        <inertial>
            <origin xyz="0.0 0.0 0.345" rpy="0 0 0"/>
            <mass value="1" />
            <inertia ixx="100" ixy="0" ixz="0" iyy="100" iyz="0" izz="100" />
        </inertial>
        <visual>
            <origin xyz="0.0 0.0 0.345" rpy="0 0 0"/>
            <geometry>
                <box size="0.95 0.54 0.69" />
            </geometry>
            <material name="Green">
                <color rgba="0.0 1.0 0.0 1.0"/>
            </material>
        </visual>
        <collision>
            <origin xyz="0.0 0.0 0.345" rpy="0 0 0"/>
            <geometry>
                <box size="0.95 0.54 0.69" />
            </geometry>
        </collision>
    </link>
    <joint name="Part2_Part3" type="revolute">
       <parent link="Part2"/>
       <child  link="Part3"/>
       <origin rpy="0 0 0" xyz="0.0 0.27 0.345" />
     <axis xyz="1 0 0"/>
       <limit effort="0.0" lower="-3.14159" upper="3.14159" velocity="0.0"/>
    </joint>
    <link name="Part3">
        <inertial>
            <origin xyz="0.0 0.32 0.0" rpy="0 0 0"/>
            <mass value="1" />
            <inertia ixx="100" ixy="0" ixz="0" iyy="100" iyz="0" izz="100" />
        </inertial>
        <visual>
            <origin xyz="0.0 0.32 0.0" rpy="0 0 0"/>
            <geometry>
                <box size="0.51 0.64 0.5" />
            </geometry>
            <material name="Green">
                <color rgba="0.0 1.0 0.0 1.0"/>
            </material>
        </visual>
        <collision>
            <origin xyz="0.0 0.32 0.0" rpy="0 0 0"/>
            <geometry>
                <box size="0.51 0.64 0.5" />
            </geometry>
        </collision>
    </link>
    <joint name="Part1_Part4" type="revolute">
       <parent link="Part1"/>
       <child  link="Part4"/>
       <origin rpy="0 0 0" xyz="0.0 0.27 -0.345" />
     <axis xyz="1 0 0"/>
       <limit effort="0.0" lower="-3.14159" upper="3.14159" velocity="0.0"/>
    </joint>
    <link name="Part4">
        <inertial>
            <origin xyz="0.0 0.32 0.0" rpy="0 0 0"/>
            <mass value="1" />
            <inertia ixx="100" ixy="0" ixz="0" iyy="100" iyz="0" izz="100" />
        </inertial>
        <visual>
            <origin xyz="0.0 0.32 0.0" rpy="0 0 0"/>
            <geometry>
                <box size="0.51 0.64 0.5" />
            </geometry>
            <material name="Green">
                <color rgba="0.0 1.0 0.0 1.0"/>
            </material>
        </visual>
        <collision>
            <origin xyz="0.0 0.32 0.0" rpy="0 0 0"/>
            <geometry>
                <box size="0.51 0.64 0.5" />
            </geometry>
        </collision>
    </link>
</robot>