<robot name = "robot">
    <link name="Part0">
        <inertial>
            <origin xyz="0 0 4.015" rpy="0 0 0"/>
            <mass value="1" />
            <inertia ixx="100" ixy="0" ixz="0" iyy="100" iyz="0" izz="100" />
        </inertial>
        <visual>
            <origin xyz="0 0 4.015" rpy="0 0 0"/>
            <geometry>
                <box size="1.04 0.98 1.17" />
            </geometry>
            <material name="Red">
                <color rgba="1.0 0.5 0.0 1.0"/>
            </material>
        </visual>
        <collision>
            <origin xyz="0 0 4.015" rpy="0 0 0"/>
            <geometry>
                <box size="1.04 0.98 1.17" />
            </geometry>
        </collision>
    </link>
    <joint name="Part0_Part1" type="revolute">
       <parent link="Part0"/>
       <child  link="Part1"/>
       <origin rpy="0 0 0" xyz="0.0 0.0 3.4299999999999997" />
     <axis xyz="0 0 1"/>
       <limit effort="0.0" lower="-3.14159" upper="3.14159" velocity="0.0"/>
    </joint>
    <link name="Part1">
        <inertial>
            <origin xyz="0.0 0.0 -0.57" rpy="0 0 0"/>
            <mass value="1" />
            <inertia ixx="100" ixy="0" ixz="0" iyy="100" iyz="0" izz="100" />
        </inertial>
        <visual>
            <origin xyz="0.0 0.0 -0.57" rpy="0 0 0"/>
            <geometry>
                <box size="1.03 0.86 1.14" />
            </geometry>
            <material name="Blue">
                <color rgba="0.0 0.5 1.0 1.0"/>
            </material>
        </visual>
        <collision>
            <origin xyz="0.0 0.0 -0.57" rpy="0 0 0"/>
            <geometry>
                <box size="1.03 0.86 1.14" />
            </geometry>
        </collision>
    </link>
    <joint name="Part0_Part2" type="revolute">
       <parent link="Part0"/>
       <child  link="Part2"/>
       <origin rpy="0 0 0" xyz="0.0 0.49 4.015" />
     <axis xyz="1 0 0"/>
       <limit effort="0.0" lower="-3.14159" upper="3.14159" velocity="0.0"/>
    </joint>
    <link name="Part2">
        <inertial>
            <origin xyz="0.0 0.57 0.0" rpy="0 0 0"/>
            <mass value="1" />
            <inertia ixx="100" ixy="0" ixz="0" iyy="100" iyz="0" izz="100" />
        </inertial>
        <visual>
            <origin xyz="0.0 0.57 0.0" rpy="0 0 0"/>
            <geometry>
                <box size="1.19 1.14 1.17" />
            </geometry>
            <material name="Blue">
                <color rgba="0.0 0.5 1.0 1.0"/>
            </material>
        </visual>
        <collision>
            <origin xyz="0.0 0.57 0.0" rpy="0 0 0"/>
            <geometry>
                <box size="1.19 1.14 1.17" />
            </geometry>
        </collision>
    </link>
    <joint name="Part1_Part3" type="revolute">
       <parent link="Part1"/>
       <child  link="Part3"/>
       <origin rpy="0 0 0" xyz="0.0 0.0 -1.14" />
     <axis xyz="1 0 0"/>
       <limit effort="0.0" lower="-3.14159" upper="3.14159" velocity="0.0"/>
    </joint>
    <link name="Part3">
        <inertial>
            <origin xyz="0.0 0.0 -0.46" rpy="0 0 0"/>
            <mass value="1" />
            <inertia ixx="100" ixy="0" ixz="0" iyy="100" iyz="0" izz="100" />
        </inertial>
        <visual>
            <origin xyz="0.0 0.0 -0.46" rpy="0 0 0"/>
            <geometry>
                <box size="0.75 1.02 0.92" />
            </geometry>
            <material name="Blue">
                <color rgba="0.0 0.5 1.0 1.0"/>
            </material>
        </visual>
        <collision>
            <origin xyz="0.0 0.0 -0.46" rpy="0 0 0"/>
            <geometry>
                <box size="0.75 1.02 0.92" />
            </geometry>
        </collision>
    </link>
    <joint name="Part1_Part4" type="revolute">
       <parent link="Part1"/>
       <child  link="Part4"/>
       <origin rpy="0 0 0" xyz="0.0 -0.43 -0.57" />
     <axis xyz="1 0 0"/>
       <limit effort="0.0" lower="-3.14159" upper="3.14159" velocity="0.0"/>
    </joint>
    <link name="Part4">
        <inertial>
            <origin xyz="0.0 -0.395 0.0" rpy="0 0 0"/>
            <mass value="1" />
            <inertia ixx="100" ixy="0" ixz="0" iyy="100" iyz="0" izz="100" />
        </inertial>
        <visual>
            <origin xyz="0.0 -0.395 0.0" rpy="0 0 0"/>
            <geometry>
                <box size="1.02 0.79 1.1" />
            </geometry>
            <material name="Blue">
                <color rgba="0.0 0.5 1.0 1.0"/>
            </material>
        </visual>
        <collision>
            <origin xyz="0.0 -0.395 0.0" rpy="0 0 0"/>
            <geometry>
                <box size="1.02 0.79 1.1" />
            </geometry>
        </collision>
    </link>
    <joint name="Part1_Part5" type="revolute">
       <parent link="Part1"/>
       <child  link="Part5"/>
       <origin rpy="0 0 0" xyz="0.0 0.0 -1.14" />
     <axis xyz="1 0 0"/>
       <limit effort="0.0" lower="-3.14159" upper="3.14159" velocity="0.0"/>
    </joint>
    <link name="Part5">
        <inertial>
            <origin xyz="0.0 0.0 -0.605" rpy="0 0 0"/>
            <mass value="1" />
            <inertia ixx="100" ixy="0" ixz="0" iyy="100" iyz="0" izz="100" />
        </inertial>
        <visual>
            <origin xyz="0.0 0.0 -0.605" rpy="0 0 0"/>
            <geometry>
                <box size="1.25 1.13 1.21" />
            </geometry>
            <material name="Blue">
                <color rgba="0.0 0.5 1.0 1.0"/>
            </material>
        </visual>
        <collision>
            <origin xyz="0.0 0.0 -0.605" rpy="0 0 0"/>
            <geometry>
                <box size="1.25 1.13 1.21" />
            </geometry>
        </collision>
    </link>
    <joint name="Part1_Part6" type="revolute">
       <parent link="Part1"/>
       <child  link="Part6"/>
       <origin rpy="0 0 0" xyz="-0.515 0.0 -0.57" />
     <axis xyz="1 0 0"/>
       <limit effort="0.0" lower="-3.14159" upper="3.14159" velocity="0.0"/>
    </joint>
    <link name="Part6">
        <inertial>
            <origin xyz="-0.38 0.0 0.0" rpy="0 0 0"/>
            <mass value="1" />
            <inertia ixx="100" ixy="0" ixz="0" iyy="100" iyz="0" izz="100" />
        </inertial>
        <visual>
            <origin xyz="-0.38 0.0 0.0" rpy="0 0 0"/>
            <geometry>
                <box size="0.76 1.18 1.03" />
            </geometry>
            <material name="Green">
                <color rgba="0.0 1.0 0.0 1.0"/>
            </material>
        </visual>
        <collision>
            <origin xyz="-0.38 0.0 0.0" rpy="0 0 0"/>
            <geometry>
                <box size="0.76 1.18 1.03" />
            </geometry>
        </collision>
    </link>
    <joint name="Part2_Part7" type="revolute">
       <parent link="Part2"/>
       <child  link="Part7"/>
       <origin rpy="0 0 0" xyz="0.0 1.14 0.0" />
     <axis xyz="0 1 0"/>
       <limit effort="0.0" lower="-3.14159" upper="3.14159" velocity="0.0"/>
    </joint>
    <link name="Part7">
        <inertial>
            <origin xyz="0.0 0.61 0.0" rpy="0 0 0"/>
            <mass value="1" />
            <inertia ixx="100" ixy="0" ixz="0" iyy="100" iyz="0" izz="100" />
        </inertial>
        <visual>
            <origin xyz="0.0 0.61 0.0" rpy="0 0 0"/>
            <geometry>
                <box size="0.91 1.22 0.76" />
            </geometry>
            <material name="Blue">
                <color rgba="0.0 0.5 1.0 1.0"/>
            </material>
        </visual>
        <collision>
            <origin xyz="0.0 0.61 0.0" rpy="0 0 0"/>
            <geometry>
                <box size="0.91 1.22 0.76" />
            </geometry>
        </collision>
    </link>
    <joint name="Part4_Part8" type="revolute">
       <parent link="Part4"/>
       <child  link="Part8"/>
       <origin rpy="0 0 0" xyz="0.0 -0.79 0.0" />
     <axis xyz="0 0 1"/>
       <limit effort="0.0" lower="-3.14159" upper="3.14159" velocity="0.0"/>
    </joint>
    <link name="Part8">
        <inertial>
            <origin xyz="0.0 -0.62 0.0" rpy="0 0 0"/>
            <mass value="1" />
            <inertia ixx="100" ixy="0" ixz="0" iyy="100" iyz="0" izz="100" />
        </inertial>
        <visual>
            <origin xyz="0.0 -0.62 0.0" rpy="0 0 0"/>
            <geometry>
                <box size="1.19 1.24 1.16" />
            </geometry>
            <material name="Blue">
                <color rgba="0.0 0.5 1.0 1.0"/>
            </material>
        </visual>
        <collision>
            <origin xyz="0.0 -0.62 0.0" rpy="0 0 0"/>
            <geometry>
                <box size="1.19 1.24 1.16" />
            </geometry>
        </collision>
    </link>
    <joint name="Part5_Part9" type="revolute">
       <parent link="Part5"/>
       <child  link="Part9"/>
       <origin rpy="0 0 0" xyz="0.0 0.0 -1.21" />
     <axis xyz="0 0 1"/>
       <limit effort="0.0" lower="-3.14159" upper="3.14159" velocity="0.0"/>
    </joint>
    <link name="Part9">
        <inertial>
            <origin xyz="0.0 0.0 -0.54" rpy="0 0 0"/>
            <mass value="1" />
            <inertia ixx="100" ixy="0" ixz="0" iyy="100" iyz="0" izz="100" />
        </inertial>
        <visual>
            <origin xyz="0.0 0.0 -0.54" rpy="0 0 0"/>
            <geometry>
                <box size="0.81 0.9 1.08" />
            </geometry>
            <material name="Blue">
                <color rgba="0.0 0.5 1.0 1.0"/>
            </material>
        </visual>
        <collision>
            <origin xyz="0.0 0.0 -0.54" rpy="0 0 0"/>
            <geometry>
                <box size="0.81 0.9 1.08" />
            </geometry>
        </collision>
    </link>
    <joint name="Part1_Part10" type="revolute">
       <parent link="Part1"/>
       <child  link="Part10"/>
       <origin rpy="0 0 0" xyz="0.0 0.43 -0.57" />
     <axis xyz="0 0 1"/>
       <limit effort="0.0" lower="-3.14159" upper="3.14159" velocity="0.0"/>
    </joint>
    <link name="Part10">
        <inertial>
            <origin xyz="0.0 0.465 0.0" rpy="0 0 0"/>
            <mass value="1" />
            <inertia ixx="100" ixy="0" ixz="0" iyy="100" iyz="0" izz="100" />
        </inertial>
        <visual>
            <origin xyz="0.0 0.465 0.0" rpy="0 0 0"/>
            <geometry>
                <box size="0.98 0.93 0.87" />
            </geometry>
            <material name="Blue">
                <color rgba="0.0 0.5 1.0 1.0"/>
            </material>
        </visual>
        <collision>
            <origin xyz="0.0 0.465 0.0" rpy="0 0 0"/>
            <geometry>
                <box size="0.98 0.93 0.87" />
            </geometry>
        </collision>
    </link>
    <joint name="Part0_Part11" type="revolute">
       <parent link="Part0"/>
       <child  link="Part11"/>
       <origin rpy="0 0 0" xyz="0.0 0.0 4.6" />
     <axis xyz="1 0 0"/>
       <limit effort="0.0" lower="-3.14159" upper="3.14159" velocity="0.0"/>
    </joint>
    <link name="Part11">
        <inertial>
            <origin xyz="0.0 0.0 0.62" rpy="0 0 0"/>
            <mass value="1" />
            <inertia ixx="100" ixy="0" ixz="0" iyy="100" iyz="0" izz="100" />
        </inertial>
        <visual>
            <origin xyz="0.0 0.0 0.62" rpy="0 0 0"/>
            <geometry>
                <box size="1.0 1.02 1.24" />
            </geometry>
            <material name="Green">
                <color rgba="0.0 1.0 0.0 1.0"/>
            </material>
        </visual>
        <collision>
            <origin xyz="0.0 0.0 0.62" rpy="0 0 0"/>
            <geometry>
                <box size="1.0 1.02 1.24" />
            </geometry>
        </collision>
    </link>
    <joint name="Part1_Part12" type="revolute">
       <parent link="Part1"/>
       <child  link="Part12"/>
       <origin rpy="0 0 0" xyz="0.515 0.0 -0.57" />
     <axis xyz="1 0 0"/>
       <limit effort="0.0" lower="-3.14159" upper="3.14159" velocity="0.0"/>
    </joint>
    <link name="Part12">
        <inertial>
            <origin xyz="0.555 0.0 0.0" rpy="0 0 0"/>
            <mass value="1" />
            <inertia ixx="100" ixy="0" ixz="0" iyy="100" iyz="0" izz="100" />
        </inertial>
        <visual>
            <origin xyz="0.555 0.0 0.0" rpy="0 0 0"/>
            <geometry>
                <box size="1.11 0.98 1.1" />
            </geometry>
            <material name="Blue">
                <color rgba="0.0 0.5 1.0 1.0"/>
            </material>
        </visual>
        <collision>
            <origin xyz="0.555 0.0 0.0" rpy="0 0 0"/>
            <geometry>
                <box size="1.11 0.98 1.1" />
            </geometry>
        </collision>
    </link>
    <joint name="Part4_Part13" type="revolute">
       <parent link="Part4"/>
       <child  link="Part13"/>
       <origin rpy="0 0 0" xyz="-0.51 -0.395 0.0" />
     <axis xyz="1 0 0"/>
       <limit effort="0.0" lower="-3.14159" upper="3.14159" velocity="0.0"/>
    </joint>
    <link name="Part13">
        <inertial>
            <origin xyz="-0.495 0.0 0.0" rpy="0 0 0"/>
            <mass value="1" />
            <inertia ixx="100" ixy="0" ixz="0" iyy="100" iyz="0" izz="100" />
        </inertial>
        <visual>
            <origin xyz="-0.495 0.0 0.0" rpy="0 0 0"/>
            <geometry>
                <box size="0.99 0.93 0.85" />
            </geometry>
            <material name="Blue">
                <color rgba="0.0 0.5 1.0 1.0"/>
            </material>
        </visual>
        <collision>
            <origin xyz="-0.495 0.0 0.0" rpy="0 0 0"/>
            <geometry>
                <box size="0.99 0.93 0.85" />
            </geometry>
        </collision>
    </link>
</robot>