<robot name = "robot">
    <link name="Part0">
        <inertial>
            <origin xyz="0 0 0.27" rpy="0 0 0"/>
            <mass value="1" />
            <inertia ixx="100" ixy="0" ixz="0" iyy="100" iyz="0" izz="100" />
        </inertial>
        <visual>
            <origin xyz="0 0 0.27" rpy="0 0 0"/>
            <geometry>
                <box size="0.81 0.46 0.54" />
            </geometry>
            <material name="Green">
                <color rgba="0.0 1.0 0.0 1.0"/>
            </material>
        </visual>
        <collision>
            <origin xyz="0 0 0.27" rpy="0 0 0"/>
            <geometry>
                <box size="0.81 0.46 0.54" />
            </geometry>
        </collision>
    </link>
    <joint name="Part0_Part1" type="revolute">
       <parent link="Part0"/>
       <child  link="Part1"/>
       <origin rpy="0 0 0" xyz="0.0 0.0 0.54" />
     <axis xyz="1 0 0"/>
       <limit effort="0.0" lower="-3.14159" upper="3.14159" velocity="0.0"/>
    </joint>
    <link name="Part1">
        <inertial>
            <origin xyz="0.0 0.0 0.425" rpy="0 0 0"/>
            <mass value="1" />
            <inertia ixx="100" ixy="0" ixz="0" iyy="100" iyz="0" izz="100" />
        </inertial>
        <visual>
            <origin xyz="0.0 0.0 0.425" rpy="0 0 0"/>
            <geometry>
                <box size="0.43 0.87 0.85" />
            </geometry>
            <material name="Green">
                <color rgba="0.0 1.0 0.0 1.0"/>
            </material>
        </visual>
        <collision>
            <origin xyz="0.0 0.0 0.425" rpy="0 0 0"/>
            <geometry>
                <box size="0.43 0.87 0.85" />
            </geometry>
        </collision>
    </link>
    <joint name="Part1_Part2" type="revolute">
       <parent link="Part1"/>
       <child  link="Part2"/>
       <origin rpy="0 0 0" xyz="0.0 0.435 0.425" />
     <axis xyz="0 1 0"/>
       <limit effort="0.0" lower="-3.14159" upper="3.14159" velocity="0.0"/>
    </joint>
    <link name="Part2">
        <inertial>
            <origin xyz="0.0 0.47 0.0" rpy="0 0 0"/>
            <mass value="1" />
            <inertia ixx="100" ixy="0" ixz="0" iyy="100" iyz="0" izz="100" />
        </inertial>
        <visual>
            <origin xyz="0.0 0.47 0.0" rpy="0 0 0"/>
            <geometry>
                <box size="0.28 0.94 0.97" />
            </geometry>
            <material name="Blue">
                <color rgba="0.0 0.5 1.0 1.0"/>
            </material>
        </visual>
        <collision>
            <origin xyz="0.0 0.47 0.0" rpy="0 0 0"/>
            <geometry>
                <box size="0.28 0.94 0.97" />
            </geometry>
        </collision>
    </link>
    <joint name="Part1_Part3" type="revolute">
       <parent link="Part1"/>
       <child  link="Part3"/>
       <origin rpy="0 0 0" xyz="-0.215 0.0 0.425" />
     <axis xyz="0 1 0"/>
       <limit effort="0.0" lower="-3.14159" upper="3.14159" velocity="0.0"/>
    </joint>
    <link name="Part3">
        <inertial>
            <origin xyz="-0.395 0.0 0.0" rpy="0 0 0"/>
            <mass value="1" />
            <inertia ixx="100" ixy="0" ixz="0" iyy="100" iyz="0" izz="100" />
        </inertial>
        <visual>
            <origin xyz="-0.395 0.0 0.0" rpy="0 0 0"/>
            <geometry>
                <box size="0.79 0.81 0.31" />
            </geometry>
            <material name="Green">
                <color rgba="0.0 1.0 0.0 1.0"/>
            </material>
        </visual>
        <collision>
            <origin xyz="-0.395 0.0 0.0" rpy="0 0 0"/>
            <geometry>
                <box size="0.79 0.81 0.31" />
            </geometry>
        </collision>
    </link>
</robot>