<robot name = "robot">
    <link name="Part0">
        <inertial>
            <origin xyz="0 0 1.4500000000000002" rpy="0 0 0"/>
            <mass value="1" />
            <inertia ixx="100" ixy="0" ixz="0" iyy="100" iyz="0" izz="100" />
        </inertial>
        <visual>
            <origin xyz="0 0 1.4500000000000002" rpy="0 0 0"/>
            <geometry>
                <box size="0.86 0.98 0.26" />
            </geometry>
            <material name="Blue">
                <color rgba="0.0 0.5 1.0 1.0"/>
            </material>
        </visual>
        <collision>
            <origin xyz="0 0 1.4500000000000002" rpy="0 0 0"/>
            <geometry>
                <box size="0.86 0.98 0.26" />
            </geometry>
        </collision>
    </link>
    <joint name="Part0_Part1" type="revolute">
       <parent link="Part0"/>
       <child  link="Part1"/>
       <origin rpy="0 0 0" xyz="0.43 0.0 1.4500000000000002" />
     <axis xyz="0 0 1"/>
       <limit effort="0.0" lower="-3.14159" upper="3.14159" velocity="0.0"/>
    </joint>
    <link name="Part1">
        <inertial>
            <origin xyz="0.435 0.0 0.0" rpy="0 0 0"/>
            <mass value="1" />
            <inertia ixx="100" ixy="0" ixz="0" iyy="100" iyz="0" izz="100" />
        </inertial>
        <visual>
            <origin xyz="0.435 0.0 0.0" rpy="0 0 0"/>
            <geometry>
                <box size="0.87 0.6 0.45" />
            </geometry>
            <material name="Green">
                <color rgba="0.0 1.0 0.0 1.0"/>
            </material>
        </visual>
        <collision>
            <origin xyz="0.435 0.0 0.0" rpy="0 0 0"/>
            <geometry>
                <box size="0.87 0.6 0.45" />
            </geometry>
        </collision>
    </link>
    <joint name="Part0_Part2" type="revolute">
       <parent link="Part0"/>
       <child  link="Part2"/>
       <origin rpy="0 0 0" xyz="0.0 0.0 1.32" />
     <axis xyz="1 0 0"/>
       <limit effort="0.0" lower="-3.14159" upper="3.14159" velocity="0.0"/>
    </joint>
    <link name="Part2">
        <inertial>
            <origin xyz="0.0 0.0 -0.265" rpy="0 0 0"/>
            <mass value="1" />
            <inertia ixx="100" ixy="0" ixz="0" iyy="100" iyz="0" izz="100" />
        </inertial>
        <visual>
            <origin xyz="0.0 0.0 -0.265" rpy="0 0 0"/>
            <geometry>
                <box size="0.46 0.64 0.53" />
            </geometry>
            <material name="Green">
                <color rgba="0.0 1.0 0.0 1.0"/>
            </material>
        </visual>
        <collision>
            <origin xyz="0.0 0.0 -0.265" rpy="0 0 0"/>
            <geometry>
                <box size="0.46 0.64 0.53" />
            </geometry>
        </collision>
    </link>
    <joint name="Part0_Part3" type="revolute">
       <parent link="Part0"/>
       <child  link="Part3"/>
       <origin rpy="0 0 0" xyz="0.0 0.49 1.4500000000000002" />
     <axis xyz="1 0 0"/>
       <limit effort="0.0" lower="-3.14159" upper="3.14159" velocity="0.0"/>
    </joint>
    <link name="Part3">
        <inertial>
            <origin xyz="0.0 0.355 0.0" rpy="0 0 0"/>
            <mass value="1" />
            <inertia ixx="100" ixy="0" ixz="0" iyy="100" iyz="0" izz="100" />
        </inertial>
        <visual>
            <origin xyz="0.0 0.355 0.0" rpy="0 0 0"/>
            <geometry>
                <box size="0.97 0.71 0.48" />
            </geometry>
            <material name="Blue">
                <color rgba="0.0 0.5 1.0 1.0"/>
            </material>
        </visual>
        <collision>
            <origin xyz="0.0 0.355 0.0" rpy="0 0 0"/>
            <geometry>
                <box size="0.97 0.71 0.48" />
            </geometry>
        </collision>
    </link>
    <joint name="Part3_Part4" type="revolute">
       <parent link="Part3"/>
       <child  link="Part4"/>
       <origin rpy="0 0 0" xyz="-0.485 0.355 0.0" />
     <axis xyz="0 0 1"/>
       <limit effort="0.0" lower="-3.14159" upper="3.14159" velocity="0.0"/>
    </joint>
    <link name="Part4">
        <inertial>
            <origin xyz="-0.5 0.0 0.0" rpy="0 0 0"/>
            <mass value="1" />
            <inertia ixx="100" ixy="0" ixz="0" iyy="100" iyz="0" izz="100" />
        </inertial>
        <visual>
            <origin xyz="-0.5 0.0 0.0" rpy="0 0 0"/>
            <geometry>
                <box size="1.0 0.46 0.34" />
            </geometry>
            <material name="Blue">
                <color rgba="0.0 0.5 1.0 1.0"/>
            </material>
        </visual>
        <collision>
            <origin xyz="-0.5 0.0 0.0" rpy="0 0 0"/>
            <geometry>
                <box size="1.0 0.46 0.34" />
            </geometry>
        </collision>
    </link>
    <joint name="Part1_Part5" type="revolute">
       <parent link="Part1"/>
       <child  link="Part5"/>
       <origin rpy="0 0 0" xyz="0.87 0.0 0.0" />
     <axis xyz="1 0 0"/>
       <limit effort="0.0" lower="-3.14159" upper="3.14159" velocity="0.0"/>
    </joint>
    <link name="Part5">
        <inertial>
            <origin xyz="0.14 0.0 0.0" rpy="0 0 0"/>
            <mass value="1" />
            <inertia ixx="100" ixy="0" ixz="0" iyy="100" iyz="0" izz="100" />
        </inertial>
        <visual>
            <origin xyz="0.14 0.0 0.0" rpy="0 0 0"/>
            <geometry>
                <box size="0.28 0.7 0.56" />
            </geometry>
            <material name="Blue">
                <color rgba="0.0 0.5 1.0 1.0"/>
            </material>
        </visual>
        <collision>
            <origin xyz="0.14 0.0 0.0" rpy="0 0 0"/>
            <geometry>
                <box size="0.28 0.7 0.56" />
            </geometry>
        </collision>
    </link>
    <joint name="Part3_Part6" type="revolute">
       <parent link="Part3"/>
       <child  link="Part6"/>
       <origin rpy="0 0 0" xyz="0.0 0.71 0.0" />
     <axis xyz="0 1 0"/>
       <limit effort="0.0" lower="-3.14159" upper="3.14159" velocity="0.0"/>
    </joint>
    <link name="Part6">
        <inertial>
            <origin xyz="0.0 0.26 0.0" rpy="0 0 0"/>
            <mass value="1" />
            <inertia ixx="100" ixy="0" ixz="0" iyy="100" iyz="0" izz="100" />
        </inertial>
        <visual>
            <origin xyz="0.0 0.26 0.0" rpy="0 0 0"/>
            <geometry>
                <box size="0.49 0.52 0.88" />
            </geometry>
            <material name="Blue">
                <color rgba="0.0 0.5 1.0 1.0"/>
            </material>
        </visual>
        <collision>
            <origin xyz="0.0 0.26 0.0" rpy="0 0 0"/>
            <geometry>
                <box size="0.49 0.52 0.88" />
            </geometry>
        </collision>
    </link>
    <joint name="Part4_Part7" type="revolute">
       <parent link="Part4"/>
       <child  link="Part7"/>
       <origin rpy="0 0 0" xyz="-1.0 0.0 0.0" />
     <axis xyz="0 0 1"/>
       <limit effort="0.0" lower="-3.14159" upper="3.14159" velocity="0.0"/>
    </joint>
    <link name="Part7">
        <inertial>
            <origin xyz="-0.435 0.0 0.0" rpy="0 0 0"/>
            <mass value="1" />
            <inertia ixx="100" ixy="0" ixz="0" iyy="100" iyz="0" izz="100" />
        </inertial>
        <visual>
            <origin xyz="-0.435 0.0 0.0" rpy="0 0 0"/>
            <geometry>
                <box size="0.87 0.92 0.55" />
            </geometry>
            <material name="Blue">
                <color rgba="0.0 0.5 1.0 1.0"/>
            </material>
        </visual>
        <collision>
            <origin xyz="-0.435 0.0 0.0" rpy="0 0 0"/>
            <geometry>
                <box size="0.87 0.92 0.55" />
            </geometry>
        </collision>
    </link>
    <joint name="Part4_Part8" type="revolute">
       <parent link="Part4"/>
       <child  link="Part8"/>
       <origin rpy="0 0 0" xyz="-0.5 -0.23 0.0" />
     <axis xyz="0 1 0"/>
       <limit effort="0.0" lower="-3.14159" upper="3.14159" velocity="0.0"/>
    </joint>
    <link name="Part8">
        <inertial>
            <origin xyz="0.0 -0.15 0.0" rpy="0 0 0"/>
            <mass value="1" />
            <inertia ixx="100" ixy="0" ixz="0" iyy="100" iyz="0" izz="100" />
        </inertial>
        <visual>
            <origin xyz="0.0 -0.15 0.0" rpy="0 0 0"/>
            <geometry>
                <box size="0.66 0.3 0.46" />
            </geometry>
            <material name="Blue">
                <color rgba="0.0 0.5 1.0 1.0"/>
            </material>
        </visual>
        <collision>
            <origin xyz="0.0 -0.15 0.0" rpy="0 0 0"/>
            <geometry>
                <box size="0.66 0.3 0.46" />
            </geometry>
        </collision>
    </link>
    <joint name="Part2_Part9" type="revolute">
       <parent link="Part2"/>
       <child  link="Part9"/>
       <origin rpy="0 0 0" xyz="0.0 0.0 -0.53" />
     <axis xyz="0 1 0"/>
       <limit effort="0.0" lower="-3.14159" upper="3.14159" velocity="0.0"/>
    </joint>
    <link name="Part9">
        <inertial>
            <origin xyz="0.0 0.0 -0.395" rpy="0 0 0"/>
            <mass value="1" />
            <inertia ixx="100" ixy="0" ixz="0" iyy="100" iyz="0" izz="100" />
        </inertial>
        <visual>
            <origin xyz="0.0 0.0 -0.395" rpy="0 0 0"/>
            <geometry>
                <box size="0.86 0.89 0.79" />
            </geometry>
            <material name="Green">
                <color rgba="0.0 1.0 0.0 1.0"/>
            </material>
        </visual>
        <collision>
            <origin xyz="0.0 0.0 -0.395" rpy="0 0 0"/>
            <geometry>
                <box size="0.86 0.89 0.79" />
            </geometry>
        </collision>
    </link>
    <joint name="Part7_Part10" type="revolute">
       <parent link="Part7"/>
       <child  link="Part10"/>
       <origin rpy="0 0 0" xyz="-0.435 -0.46 0.0" />
     <axis xyz="0 1 0"/>
       <limit effort="0.0" lower="-3.14159" upper="3.14159" velocity="0.0"/>
    </joint>
    <link name="Part10">
        <inertial>
            <origin xyz="0.0 -0.315 0.0" rpy="0 0 0"/>
            <mass value="1" />
            <inertia ixx="100" ixy="0" ixz="0" iyy="100" iyz="0" izz="100" />
        </inertial>
        <visual>
            <origin xyz="0.0 -0.315 0.0" rpy="0 0 0"/>
            <geometry>
                <box size="0.85 0.63 0.29" />
            </geometry>
            <material name="Blue">
                <color rgba="0.0 0.5 1.0 1.0"/>
            </material>
        </visual>
        <collision>
            <origin xyz="0.0 -0.315 0.0" rpy="0 0 0"/>
            <geometry>
                <box size="0.85 0.63 0.29" />
            </geometry>
        </collision>
    </link>
    <joint name="Part7_Part11" type="revolute">
       <parent link="Part7"/>
       <child  link="Part11"/>
       <origin rpy="0 0 0" xyz="-0.435 0.0 0.275" />
     <axis xyz="0 0 1"/>
       <limit effort="0.0" lower="-3.14159" upper="3.14159" velocity="0.0"/>
    </joint>
    <link name="Part11">
        <inertial>
            <origin xyz="0.0 0.0 0.375" rpy="0 0 0"/>
            <mass value="1" />
            <inertia ixx="100" ixy="0" ixz="0" iyy="100" iyz="0" izz="100" />
        </inertial>
        <visual>
            <origin xyz="0.0 0.0 0.375" rpy="0 0 0"/>
            <geometry>
                <box size="0.26 0.75 0.75" />
            </geometry>
            <material name="Blue">
                <color rgba="0.0 0.5 1.0 1.0"/>
            </material>
        </visual>
        <collision>
            <origin xyz="0.0 0.0 0.375" rpy="0 0 0"/>
            <geometry>
                <box size="0.26 0.75 0.75" />
            </geometry>
        </collision>
    </link>
</robot>