<robot name = "robot">
    <link name="Part0">
        <inertial>
            <origin xyz="0 0 1.2149999999999999" rpy="0 0 0"/>
            <mass value="1" />
            <inertia ixx="100" ixy="0" ixz="0" iyy="100" iyz="0" izz="100" />
        </inertial>
        <visual>
            <origin xyz="0 0 1.2149999999999999" rpy="0 0 0"/>
            <geometry>
                <box size="0.45 0.8 0.75" />
            </geometry>
            <material name="Green">
                <color rgba="0.0 1.0 0.0 1.0"/>
            </material>
        </visual>
        <collision>
            <origin xyz="0 0 1.2149999999999999" rpy="0 0 0"/>
            <geometry>
                <box size="0.45 0.8 0.75" />
            </geometry>
        </collision>
    </link>
    <joint name="Part0_Part1" type="revolute">
       <parent link="Part0"/>
       <child  link="Part1"/>
       <origin rpy="0 0 0" xyz="0.0 0.4 1.2149999999999999" />
     <axis xyz="0 1 0"/>
       <limit effort="0.0" lower="-3.14159" upper="3.14159" velocity="0.0"/>
    </joint>
    <link name="Part1">
        <inertial>
            <origin xyz="0.0 0.14 0.0" rpy="0 0 0"/>
            <mass value="1" />
            <inertia ixx="100" ixy="0" ixz="0" iyy="100" iyz="0" izz="100" />
        </inertial>
        <visual>
            <origin xyz="0.0 0.14 0.0" rpy="0 0 0"/>
            <geometry>
                <box size="0.29 0.28 0.71" />
            </geometry>
            <material name="Green">
                <color rgba="0.0 1.0 0.0 1.0"/>
            </material>
        </visual>
        <collision>
            <origin xyz="0.0 0.14 0.0" rpy="0 0 0"/>
            <geometry>
                <box size="0.29 0.28 0.71" />
            </geometry>
        </collision>
    </link>
    <joint name="Part0_Part2" type="revolute">
       <parent link="Part0"/>
       <child  link="Part2"/>
       <origin rpy="0 0 0" xyz="0.0 -0.4 1.2149999999999999" />
     <axis xyz="0 1 0"/>
       <limit effort="0.0" lower="-3.14159" upper="3.14159" velocity="0.0"/>
    </joint>
    <link name="Part2">
        <inertial>
            <origin xyz="0.0 -0.14 0.0" rpy="0 0 0"/>
            <mass value="1" />
            <inertia ixx="100" ixy="0" ixz="0" iyy="100" iyz="0" izz="100" />
        </inertial>
        <visual>
            <origin xyz="0.0 -0.14 0.0" rpy="0 0 0"/>
            <geometry>
                <box size="0.29 0.28 0.71" />
            </geometry>
            <material name="Green">
                <color rgba="0.0 1.0 0.0 1.0"/>
            </material>
        </visual>
        <collision>
            <origin xyz="0.0 -0.14 0.0" rpy="0 0 0"/>
            <geometry>
                <box size="0.29 0.28 0.71" />
            </geometry>
        </collision>
    </link>
    <joint name="Part0_Part3" type="revolute">
       <parent link="Part0"/>
       <child  link="Part3"/>
       <origin rpy="0 0 0" xyz="0.0 0.0 0.8399999999999999" />
     <axis xyz="1 0 0"/>
       <limit effort="0.0" lower="-3.14159" upper="3.14159" velocity="0.0"/>
    </joint>
    <link name="Part3">
        <inertial>
            <origin xyz="0.0 0.0 -0.42" rpy="0 0 0"/>
            <mass value="1" />
            <inertia ixx="100" ixy="0" ixz="0" iyy="100" iyz="0" izz="100" />
        </inertial>
        <visual>
            <origin xyz="0.0 0.0 -0.42" rpy="0 0 0"/>
            <geometry>
                <box size="0.54 0.95 0.84" />
            </geometry>
            <material name="Green">
                <color rgba="0.0 1.0 0.0 1.0"/>
            </material>
        </visual>
        <collision>
            <origin xyz="0.0 0.0 -0.42" rpy="0 0 0"/>
            <geometry>
                <box size="0.54 0.95 0.84" />
            </geometry>
        </collision>
    </link>
    <joint name="Part0_Part4" type="revolute">
       <parent link="Part0"/>
       <child  link="Part4"/>
       <origin rpy="0 0 0" xyz="0.0 0.0 1.5899999999999999" />
     <axis xyz="1 0 0"/>
       <limit effort="0.0" lower="-3.14159" upper="3.14159" velocity="0.0"/>
    </joint>
    <link name="Part4">
        <inertial>
            <origin xyz="0.0 0.0 0.42" rpy="0 0 0"/>
            <mass value="1" />
            <inertia ixx="100" ixy="0" ixz="0" iyy="100" iyz="0" izz="100" />
        </inertial>
        <visual>
            <origin xyz="0.0 0.0 0.42" rpy="0 0 0"/>
            <geometry>
                <box size="0.54 0.95 0.84" />
            </geometry>
            <material name="Green">
                <color rgba="0.0 1.0 0.0 1.0"/>
            </material>
        </visual>
        <collision>
            <origin xyz="0.0 0.0 0.42" rpy="0 0 0"/>
            <geometry>
                <box size="0.54 0.95 0.84" />
            </geometry>
        </collision>
    </link>
    <joint name="Part4_Part5" type="revolute">
       <parent link="Part4"/>
       <child  link="Part5"/>
       <origin rpy="0 0 0" xyz="-0.27 0.0 0.42" />
     <axis xyz="0 1 0"/>
       <limit effort="0.0" lower="-3.14159" upper="3.14159" velocity="0.0"/>
    </joint>
    <link name="Part5">
        <inertial>
            <origin xyz="-0.165 0.0 0.0" rpy="0 0 0"/>
            <mass value="1" />
            <inertia ixx="100" ixy="0" ixz="0" iyy="100" iyz="0" izz="100" />
        </inertial>
        <visual>
            <origin xyz="-0.165 0.0 0.0" rpy="0 0 0"/>
            <geometry>
                <box size="0.33 0.99 0.96" />
            </geometry>
            <material name="Blue">
                <color rgba="0.0 0.5 1.0 1.0"/>
            </material>
        </visual>
        <collision>
            <origin xyz="-0.165 0.0 0.0" rpy="0 0 0"/>
            <geometry>
                <box size="0.33 0.99 0.96" />
            </geometry>
        </collision>
    </link>
    <joint name="Part4_Part6" type="revolute">
       <parent link="Part4"/>
       <child  link="Part6"/>
       <origin rpy="0 0 0" xyz="0.27 0.0 0.42" />
     <axis xyz="0 1 0"/>
       <limit effort="0.0" lower="-3.14159" upper="3.14159" velocity="0.0"/>
    </joint>
    <link name="Part6">
        <inertial>
            <origin xyz="0.165 0.0 0.0" rpy="0 0 0"/>
            <mass value="1" />
            <inertia ixx="100" ixy="0" ixz="0" iyy="100" iyz="0" izz="100" />
        </inertial>
        <visual>
            <origin xyz="0.165 0.0 0.0" rpy="0 0 0"/>
            <geometry>
                <box size="0.33 0.99 0.96" />
            </geometry>
            <material name="Blue">
                <color rgba="0.0 0.5 1.0 1.0"/>
            </material>
        </visual>
        <collision>
            <origin xyz="0.165 0.0 0.0" rpy="0 0 0"/>
            <geometry>
                <box size="0.33 0.99 0.96" />
            </geometry>
        </collision>
    </link>
</robot>