<robot name = "robot">
    <link name="Part0">
        <inertial>
            <origin xyz="0 0 0.32" rpy="0 0 0"/>
            <mass value="1" />
            <inertia ixx="100" ixy="0" ixz="0" iyy="100" iyz="0" izz="100" />
        </inertial>
        <visual>
            <origin xyz="0 0 0.32" rpy="0 0 0"/>
            <geometry>
                <box size="0.29 0.89 0.25" />
            </geometry>
            <material name="Green">
                <color rgba="0.0 1.0 0.0 1.0"/>
            </material>
        </visual>
        <collision>
            <origin xyz="0 0 0.32" rpy="0 0 0"/>
            <geometry>
                <box size="0.29 0.89 0.25" />
            </geometry>
        </collision>
    </link>
    <joint name="Part0_Part1" type="revolute">
       <parent link="Part0"/>
       <child  link="Part1"/>
       <origin rpy="0 0 0" xyz="-0.145 0.0 0.32" />
     <axis xyz="0 0 1"/>
       <limit effort="0.0" lower="-3.14159" upper="3.14159" velocity="0.0"/>
    </joint>
    <link name="Part1">
        <inertial>
            <origin xyz="-0.325 0.0 0.0" rpy="0 0 0"/>
            <mass value="1" />
            <inertia ixx="100" ixy="0" ixz="0" iyy="100" iyz="0" izz="100" />
        </inertial>
        <visual>
            <origin xyz="-0.325 0.0 0.0" rpy="0 0 0"/>
            <geometry>
                <box size="0.65 0.88 0.64" />
            </geometry>
            <material name="Green">
                <color rgba="0.0 1.0 0.0 1.0"/>
            </material>
        </visual>
        <collision>
            <origin xyz="-0.325 0.0 0.0" rpy="0 0 0"/>
            <geometry>
                <box size="0.65 0.88 0.64" />
            </geometry>
        </collision>
    </link>
    <joint name="Part0_Part2" type="revolute">
       <parent link="Part0"/>
       <child  link="Part2"/>
       <origin rpy="0 0 0" xyz="0.145 0.0 0.32" />
     <axis xyz="0 0 1"/>
       <limit effort="0.0" lower="-3.14159" upper="3.14159" velocity="0.0"/>
    </joint>
    <link name="Part2">
        <inertial>
            <origin xyz="0.325 0.0 0.0" rpy="0 0 0"/>
            <mass value="1" />
            <inertia ixx="100" ixy="0" ixz="0" iyy="100" iyz="0" izz="100" />
        </inertial>
        <visual>
            <origin xyz="0.325 0.0 0.0" rpy="0 0 0"/>
            <geometry>
                <box size="0.65 0.88 0.64" />
            </geometry>
            <material name="Green">
                <color rgba="0.0 1.0 0.0 1.0"/>
            </material>
        </visual>
        <collision>
            <origin xyz="0.325 0.0 0.0" rpy="0 0 0"/>
            <geometry>
                <box size="0.65 0.88 0.64" />
            </geometry>
        </collision>
    </link>
    <joint name="Part0_Part3" type="revolute">
       <parent link="Part0"/>
       <child  link="Part3"/>
       <origin rpy="0 0 0" xyz="0.0 0.445 0.32" />
     <axis xyz="0 1 0"/>
       <limit effort="0.0" lower="-3.14159" upper="3.14159" velocity="0.0"/>
    </joint>
    <link name="Part3">
        <inertial>
            <origin xyz="0.0 0.465 0.0" rpy="0 0 0"/>
            <mass value="1" />
            <inertia ixx="100" ixy="0" ixz="0" iyy="100" iyz="0" izz="100" />
        </inertial>
        <visual>
            <origin xyz="0.0 0.465 0.0" rpy="0 0 0"/>
            <geometry>
                <box size="0.68 0.93 0.63" />
            </geometry>
            <material name="Green">
                <color rgba="0.0 1.0 0.0 1.0"/>
            </material>
        </visual>
        <collision>
            <origin xyz="0.0 0.465 0.0" rpy="0 0 0"/>
            <geometry>
                <box size="0.68 0.93 0.63" />
            </geometry>
        </collision>
    </link>
    <joint name="Part0_Part4" type="revolute">
       <parent link="Part0"/>
       <child  link="Part4"/>
       <origin rpy="0 0 0" xyz="0.0 -0.445 0.32" />
     <axis xyz="0 1 0"/>
       <limit effort="0.0" lower="-3.14159" upper="3.14159" velocity="0.0"/>
    </joint>
    <link name="Part4">
        <inertial>
            <origin xyz="0.0 -0.465 0.0" rpy="0 0 0"/>
            <mass value="1" />
            <inertia ixx="100" ixy="0" ixz="0" iyy="100" iyz="0" izz="100" />
        </inertial>
        <visual>
            <origin xyz="0.0 -0.465 0.0" rpy="0 0 0"/>
            <geometry>
                <box size="0.68 0.93 0.63" />
            </geometry>
            <material name="Green">
                <color rgba="0.0 1.0 0.0 1.0"/>
            </material>
        </visual>
        <collision>
            <origin xyz="0.0 -0.465 0.0" rpy="0 0 0"/>
            <geometry>
                <box size="0.68 0.93 0.63" />
            </geometry>
        </collision>
    </link>
    <joint name="Part3_Part5" type="revolute">
       <parent link="Part3"/>
       <child  link="Part5"/>
       <origin rpy="0 0 0" xyz="-0.34 0.465 0.0" />
     <axis xyz="0 1 0"/>
       <limit effort="0.0" lower="-3.14159" upper="3.14159" velocity="0.0"/>
    </joint>
    <link name="Part5">
        <inertial>
            <origin xyz="-0.255 0.0 0.0" rpy="0 0 0"/>
            <mass value="1" />
            <inertia ixx="100" ixy="0" ixz="0" iyy="100" iyz="0" izz="100" />
        </inertial>
        <visual>
            <origin xyz="-0.255 0.0 0.0" rpy="0 0 0"/>
            <geometry>
                <box size="0.51 0.59 0.61" />
            </geometry>
            <material name="Green">
                <color rgba="0.0 1.0 0.0 1.0"/>
            </material>
        </visual>
        <collision>
            <origin xyz="-0.255 0.0 0.0" rpy="0 0 0"/>
            <geometry>
                <box size="0.51 0.59 0.61" />
            </geometry>
        </collision>
    </link>
    <joint name="Part3_Part6" type="revolute">
       <parent link="Part3"/>
       <child  link="Part6"/>
       <origin rpy="0 0 0" xyz="0.34 0.465 0.0" />
     <axis xyz="0 1 0"/>
       <limit effort="0.0" lower="-3.14159" upper="3.14159" velocity="0.0"/>
    </joint>
    <link name="Part6">
        <inertial>
            <origin xyz="0.255 0.0 0.0" rpy="0 0 0"/>
            <mass value="1" />
            <inertia ixx="100" ixy="0" ixz="0" iyy="100" iyz="0" izz="100" />
        </inertial>
        <visual>
            <origin xyz="0.255 0.0 0.0" rpy="0 0 0"/>
            <geometry>
                <box size="0.51 0.59 0.61" />
            </geometry>
            <material name="Green">
                <color rgba="0.0 1.0 0.0 1.0"/>
            </material>
        </visual>
        <collision>
            <origin xyz="0.255 0.0 0.0" rpy="0 0 0"/>
            <geometry>
                <box size="0.51 0.59 0.61" />
            </geometry>
        </collision>
    </link>
</robot>