<robot name = "robot">
    <link name="Part0">
        <inertial>
            <origin xyz="0 0 1.44" rpy="0 0 0"/>
            <mass value="1" />
            <inertia ixx="100" ixy="0" ixz="0" iyy="100" iyz="0" izz="100" />
        </inertial>
        <visual>
            <origin xyz="0 0 1.44" rpy="0 0 0"/>
            <geometry>
                <box size="0.9 0.98 0.89" />
            </geometry>
            <material name="Green">
                <color rgba="0.0 1.0 0.0 1.0"/>
            </material>
        </visual>
        <collision>
            <origin xyz="0 0 1.44" rpy="0 0 0"/>
            <geometry>
                <box size="0.9 0.98 0.89" />
            </geometry>
        </collision>
    </link>
    <joint name="Part0_Part1" type="revolute">
       <parent link="Part0"/>
       <child  link="Part1"/>
       <origin rpy="0 0 0" xyz="0.0 0.49 1.44" />
     <axis xyz="0 1 0"/>
       <limit effort="0.0" lower="-3.14159" upper="3.14159" velocity="0.0"/>
    </joint>
    <link name="Part1">
        <inertial>
            <origin xyz="0.0 0.28 0.0" rpy="0 0 0"/>
            <mass value="1" />
            <inertia ixx="100" ixy="0" ixz="0" iyy="100" iyz="0" izz="100" />
        </inertial>
        <visual>
            <origin xyz="0.0 0.28 0.0" rpy="0 0 0"/>
            <geometry>
                <box size="0.71 0.56 0.8" />
            </geometry>
            <material name="Blue">
                <color rgba="0.0 0.5 1.0 1.0"/>
            </material>
        </visual>
        <collision>
            <origin xyz="0.0 0.28 0.0" rpy="0 0 0"/>
            <geometry>
                <box size="0.71 0.56 0.8" />
            </geometry>
        </collision>
    </link>
    <joint name="Part1_Part2" type="revolute">
       <parent link="Part1"/>
       <child  link="Part2"/>
       <origin rpy="0 0 0" xyz="0.0 0.56 0.0" />
     <axis xyz="1 0 0"/>
       <limit effort="0.0" lower="-3.14159" upper="3.14159" velocity="0.0"/>
    </joint>
    <link name="Part2">
        <inertial>
            <origin xyz="0.0 0.425 0.0" rpy="0 0 0"/>
            <mass value="1" />
            <inertia ixx="100" ixy="0" ixz="0" iyy="100" iyz="0" izz="100" />
        </inertial>
        <visual>
            <origin xyz="0.0 0.425 0.0" rpy="0 0 0"/>
            <geometry>
                <box size="0.34 0.85 0.54" />
            </geometry>
            <material name="Blue">
                <color rgba="0.0 0.5 1.0 1.0"/>
            </material>
        </visual>
        <collision>
            <origin xyz="0.0 0.425 0.0" rpy="0 0 0"/>
            <geometry>
                <box size="0.34 0.85 0.54" />
            </geometry>
        </collision>
    </link>
    <joint name="Part2_Part3" type="revolute">
       <parent link="Part2"/>
       <child  link="Part3"/>
       <origin rpy="0 0 0" xyz="0.17 0.425 0.0" />
     <axis xyz="0 0 1"/>
       <limit effort="0.0" lower="-3.14159" upper="3.14159" velocity="0.0"/>
    </joint>
    <link name="Part3">
        <inertial>
            <origin xyz="0.28 0.0 0.0" rpy="0 0 0"/>
            <mass value="1" />
            <inertia ixx="100" ixy="0" ixz="0" iyy="100" iyz="0" izz="100" />
        </inertial>
        <visual>
            <origin xyz="0.28 0.0 0.0" rpy="0 0 0"/>
            <geometry>
                <box size="0.56 0.65 0.43" />
            </geometry>
            <material name="Green">
                <color rgba="0.0 1.0 0.0 1.0"/>
            </material>
        </visual>
        <collision>
            <origin xyz="0.28 0.0 0.0" rpy="0 0 0"/>
            <geometry>
                <box size="0.56 0.65 0.43" />
            </geometry>
        </collision>
    </link>
    <joint name="Part2_Part4" type="revolute">
       <parent link="Part2"/>
       <child  link="Part4"/>
       <origin rpy="0 0 0" xyz="0.0 0.425 -0.27" />
     <axis xyz="1 0 0"/>
       <limit effort="0.0" lower="-3.14159" upper="3.14159" velocity="0.0"/>
    </joint>
    <link name="Part4">
        <inertial>
            <origin xyz="0.0 0.0 -0.31" rpy="0 0 0"/>
            <mass value="1" />
            <inertia ixx="100" ixy="0" ixz="0" iyy="100" iyz="0" izz="100" />
        </inertial>
        <visual>
            <origin xyz="0.0 0.0 -0.31" rpy="0 0 0"/>
            <geometry>
                <box size="0.66 0.42 0.62" />
            </geometry>
            <material name="Green">
                <color rgba="0.0 1.0 0.0 1.0"/>
            </material>
        </visual>
        <collision>
            <origin xyz="0.0 0.0 -0.31" rpy="0 0 0"/>
            <geometry>
                <box size="0.66 0.42 0.62" />
            </geometry>
        </collision>
    </link>
    <joint name="Part4_Part5" type="revolute">
       <parent link="Part4"/>
       <child  link="Part5"/>
       <origin rpy="0 0 0" xyz="0.0 0.21 -0.31" />
     <axis xyz="1 0 0"/>
       <limit effort="0.0" lower="-3.14159" upper="3.14159" velocity="0.0"/>
    </joint>
    <link name="Part5">
        <inertial>
            <origin xyz="0.0 0.205 0.0" rpy="0 0 0"/>
            <mass value="1" />
            <inertia ixx="100" ixy="0" ixz="0" iyy="100" iyz="0" izz="100" />
        </inertial>
        <visual>
            <origin xyz="0.0 0.205 0.0" rpy="0 0 0"/>
            <geometry>
                <box size="0.59 0.41 0.59" />
            </geometry>
            <material name="Blue">
                <color rgba="0.0 0.5 1.0 1.0"/>
            </material>
        </visual>
        <collision>
            <origin xyz="0.0 0.205 0.0" rpy="0 0 0"/>
            <geometry>
                <box size="0.59 0.41 0.59" />
            </geometry>
        </collision>
    </link>
    <joint name="Part4_Part6" type="revolute">
       <parent link="Part4"/>
       <child  link="Part6"/>
       <origin rpy="0 0 0" xyz="0.0 0.0 -0.62" />
     <axis xyz="0 0 1"/>
       <limit effort="0.0" lower="-3.14159" upper="3.14159" velocity="0.0"/>
    </joint>
    <link name="Part6">
        <inertial>
            <origin xyz="0.0 0.0 -0.275" rpy="0 0 0"/>
            <mass value="1" />
            <inertia ixx="100" ixy="0" ixz="0" iyy="100" iyz="0" izz="100" />
        </inertial>
        <visual>
            <origin xyz="0.0 0.0 -0.275" rpy="0 0 0"/>
            <geometry>
                <box size="0.84 0.81 0.55" />
            </geometry>
            <material name="Blue">
                <color rgba="0.0 0.5 1.0 1.0"/>
            </material>
        </visual>
        <collision>
            <origin xyz="0.0 0.0 -0.275" rpy="0 0 0"/>
            <geometry>
                <box size="0.84 0.81 0.55" />
            </geometry>
        </collision>
    </link>
    <joint name="Part5_Part7" type="revolute">
       <parent link="Part5"/>
       <child  link="Part7"/>
       <origin rpy="0 0 0" xyz="0.0 0.41 0.0" />
     <axis xyz="1 0 0"/>
       <limit effort="0.0" lower="-3.14159" upper="3.14159" velocity="0.0"/>
    </joint>
    <link name="Part7">
        <inertial>
            <origin xyz="0.0 0.375 0.0" rpy="0 0 0"/>
            <mass value="1" />
            <inertia ixx="100" ixy="0" ixz="0" iyy="100" iyz="0" izz="100" />
        </inertial>
        <visual>
            <origin xyz="0.0 0.375 0.0" rpy="0 0 0"/>
            <geometry>
                <box size="0.49 0.75 0.44" />
            </geometry>
            <material name="Blue">
                <color rgba="0.0 0.5 1.0 1.0"/>
            </material>
        </visual>
        <collision>
            <origin xyz="0.0 0.375 0.0" rpy="0 0 0"/>
            <geometry>
                <box size="0.49 0.75 0.44" />
            </geometry>
        </collision>
    </link>
    <joint name="Part3_Part8" type="revolute">
       <parent link="Part3"/>
       <child  link="Part8"/>
       <origin rpy="0 0 0" xyz="0.56 0.0 0.0" />
     <axis xyz="0 0 1"/>
       <limit effort="0.0" lower="-3.14159" upper="3.14159" velocity="0.0"/>
    </joint>
    <link name="Part8">
        <inertial>
            <origin xyz="0.405 0.0 0.0" rpy="0 0 0"/>
            <mass value="1" />
            <inertia ixx="100" ixy="0" ixz="0" iyy="100" iyz="0" izz="100" />
        </inertial>
        <visual>
            <origin xyz="0.405 0.0 0.0" rpy="0 0 0"/>
            <geometry>
                <box size="0.81 0.32 0.59" />
            </geometry>
            <material name="Blue">
                <color rgba="0.0 0.5 1.0 1.0"/>
            </material>
        </visual>
        <collision>
            <origin xyz="0.405 0.0 0.0" rpy="0 0 0"/>
            <geometry>
                <box size="0.81 0.32 0.59" />
            </geometry>
        </collision>
    </link>
    <joint name="Part2_Part9" type="revolute">
       <parent link="Part2"/>
       <child  link="Part9"/>
       <origin rpy="0 0 0" xyz="0.0 0.425 0.27" />
     <axis xyz="0 1 0"/>
       <limit effort="0.0" lower="-3.14159" upper="3.14159" velocity="0.0"/>
    </joint>
    <link name="Part9">
        <inertial>
            <origin xyz="0.0 0.0 0.2" rpy="0 0 0"/>
            <mass value="1" />
            <inertia ixx="100" ixy="0" ixz="0" iyy="100" iyz="0" izz="100" />
        </inertial>
        <visual>
            <origin xyz="0.0 0.0 0.2" rpy="0 0 0"/>
            <geometry>
                <box size="0.27 0.46 0.4" />
            </geometry>
            <material name="Blue">
                <color rgba="0.0 0.5 1.0 1.0"/>
            </material>
        </visual>
        <collision>
            <origin xyz="0.0 0.0 0.2" rpy="0 0 0"/>
            <geometry>
                <box size="0.27 0.46 0.4" />
            </geometry>
        </collision>
    </link>
    <joint name="Part7_Part10" type="revolute">
       <parent link="Part7"/>
       <child  link="Part10"/>
       <origin rpy="0 0 0" xyz="0.245 0.375 0.0" />
     <axis xyz="0 1 0"/>
       <limit effort="0.0" lower="-3.14159" upper="3.14159" velocity="0.0"/>
    </joint>
    <link name="Part10">
        <inertial>
            <origin xyz="0.275 0.0 0.0" rpy="0 0 0"/>
            <mass value="1" />
            <inertia ixx="100" ixy="0" ixz="0" iyy="100" iyz="0" izz="100" />
        </inertial>
        <visual>
            <origin xyz="0.275 0.0 0.0" rpy="0 0 0"/>
            <geometry>
                <box size="0.55 0.71 0.99" />
            </geometry>
            <material name="Green">
                <color rgba="0.0 1.0 0.0 1.0"/>
            </material>
        </visual>
        <collision>
            <origin xyz="0.275 0.0 0.0" rpy="0 0 0"/>
            <geometry>
                <box size="0.55 0.71 0.99" />
            </geometry>
        </collision>
    </link>
    <joint name="Part9_Part11" type="revolute">
       <parent link="Part9"/>
       <child  link="Part11"/>
       <origin rpy="0 0 0" xyz="0.0 0.0 0.4" />
     <axis xyz="0 1 0"/>
       <limit effort="0.0" lower="-3.14159" upper="3.14159" velocity="0.0"/>
    </joint>
    <link name="Part11">
        <inertial>
            <origin xyz="0.0 0.0 0.205" rpy="0 0 0"/>
            <mass value="1" />
            <inertia ixx="100" ixy="0" ixz="0" iyy="100" iyz="0" izz="100" />
        </inertial>
        <visual>
            <origin xyz="0.0 0.0 0.205" rpy="0 0 0"/>
            <geometry>
                <box size="0.82 0.72 0.41" />
            </geometry>
            <material name="Blue">
                <color rgba="0.0 0.5 1.0 1.0"/>
            </material>
        </visual>
        <collision>
            <origin xyz="0.0 0.0 0.205" rpy="0 0 0"/>
            <geometry>
                <box size="0.82 0.72 0.41" />
            </geometry>
        </collision>
    </link>
</robot>