<robot name = "robot">
    <link name="Part0">
        <inertial>
            <origin xyz="0 0 0.935" rpy="0 0 0"/>
            <mass value="1" />
            <inertia ixx="100" ixy="0" ixz="0" iyy="100" iyz="0" izz="100" />
        </inertial>
        <visual>
            <origin xyz="0 0 0.935" rpy="0 0 0"/>
            <geometry>
                <box size="0.56 0.52 0.47" />
            </geometry>
            <material name="Green">
                <color rgba="0.0 1.0 0.0 1.0"/>
            </material>
        </visual>
        <collision>
            <origin xyz="0 0 0.935" rpy="0 0 0"/>
            <geometry>
                <box size="0.56 0.52 0.47" />
            </geometry>
        </collision>
    </link>
    <joint name="Part0_Part1" type="revolute">
       <parent link="Part0"/>
       <child  link="Part1"/>
       <origin rpy="0 0 0" xyz="0.28 0.0 0.935" />
     <axis xyz="1 0 0"/>
       <limit effort="0.0" lower="-3.14159" upper="3.14159" velocity="0.0"/>
    </joint>
    <link name="Part1">
        <inertial>
            <origin xyz="0.34 0.0 0.0" rpy="0 0 0"/>
            <mass value="1" />
            <inertia ixx="100" ixy="0" ixz="0" iyy="100" iyz="0" izz="100" />
        </inertial>
        <visual>
            <origin xyz="0.34 0.0 0.0" rpy="0 0 0"/>
            <geometry>
                <box size="0.68 0.34 0.77" />
            </geometry>
            <material name="Blue">
                <color rgba="0.0 0.5 1.0 1.0"/>
            </material>
        </visual>
        <collision>
            <origin xyz="0.34 0.0 0.0" rpy="0 0 0"/>
            <geometry>
                <box size="0.68 0.34 0.77" />
            </geometry>
        </collision>
    </link>
    <joint name="Part0_Part2" type="revolute">
       <parent link="Part0"/>
       <child  link="Part2"/>
       <origin rpy="0 0 0" xyz="-0.28 0.0 0.935" />
     <axis xyz="1 0 0"/>
       <limit effort="0.0" lower="-3.14159" upper="3.14159" velocity="0.0"/>
    </joint>
    <link name="Part2">
        <inertial>
            <origin xyz="-0.34 0.0 0.0" rpy="0 0 0"/>
            <mass value="1" />
            <inertia ixx="100" ixy="0" ixz="0" iyy="100" iyz="0" izz="100" />
        </inertial>
        <visual>
            <origin xyz="-0.34 0.0 0.0" rpy="0 0 0"/>
            <geometry>
                <box size="0.68 0.34 0.77" />
            </geometry>
            <material name="Blue">
                <color rgba="0.0 0.5 1.0 1.0"/>
            </material>
        </visual>
        <collision>
            <origin xyz="-0.34 0.0 0.0" rpy="0 0 0"/>
            <geometry>
                <box size="0.68 0.34 0.77" />
            </geometry>
        </collision>
    </link>
    <joint name="Part2_Part3" type="revolute">
       <parent link="Part2"/>
       <child  link="Part3"/>
       <origin rpy="0 0 0" xyz="-0.34 0.0 -0.385" />
     <axis xyz="1 0 0"/>
       <limit effort="0.0" lower="-3.14159" upper="3.14159" velocity="0.0"/>
    </joint>
    <link name="Part3">
        <inertial>
            <origin xyz="0.0 0.0 -0.275" rpy="0 0 0"/>
            <mass value="1" />
            <inertia ixx="100" ixy="0" ixz="0" iyy="100" iyz="0" izz="100" />
        </inertial>
        <visual>
            <origin xyz="0.0 0.0 -0.275" rpy="0 0 0"/>
            <geometry>
                <box size="0.76 0.42 0.55" />
            </geometry>
            <material name="Green">
                <color rgba="0.0 1.0 0.0 1.0"/>
            </material>
        </visual>
        <collision>
            <origin xyz="0.0 0.0 -0.275" rpy="0 0 0"/>
            <geometry>
                <box size="0.76 0.42 0.55" />
            </geometry>
        </collision>
    </link>
    <joint name="Part1_Part4" type="revolute">
       <parent link="Part1"/>
       <child  link="Part4"/>
       <origin rpy="0 0 0" xyz="0.34 0.0 -0.385" />
     <axis xyz="1 0 0"/>
       <limit effort="0.0" lower="-3.14159" upper="3.14159" velocity="0.0"/>
    </joint>
    <link name="Part4">
        <inertial>
            <origin xyz="0.0 0.0 -0.275" rpy="0 0 0"/>
            <mass value="1" />
            <inertia ixx="100" ixy="0" ixz="0" iyy="100" iyz="0" izz="100" />
        </inertial>
        <visual>
            <origin xyz="0.0 0.0 -0.275" rpy="0 0 0"/>
            <geometry>
                <box size="0.76 0.42 0.55" />
            </geometry>
            <material name="Green">
                <color rgba="0.0 1.0 0.0 1.0"/>
            </material>
        </visual>
        <collision>
            <origin xyz="0.0 0.0 -0.275" rpy="0 0 0"/>
            <geometry>
                <box size="0.76 0.42 0.55" />
            </geometry>
        </collision>
    </link>
    <joint name="Part3_Part5" type="revolute">
       <parent link="Part3"/>
       <child  link="Part5"/>
       <origin rpy="0 0 0" xyz="0.0 0.21 -0.275" />
     <axis xyz="1 0 0"/>
       <limit effort="0.0" lower="-3.14159" upper="3.14159" velocity="0.0"/>
    </joint>
    <link name="Part5">
        <inertial>
            <origin xyz="0.0 0.15 0.0" rpy="0 0 0"/>
            <mass value="1" />
            <inertia ixx="100" ixy="0" ixz="0" iyy="100" iyz="0" izz="100" />
        </inertial>
        <visual>
            <origin xyz="0.0 0.15 0.0" rpy="0 0 0"/>
            <geometry>
                <box size="0.44 0.3 0.25" />
            </geometry>
            <material name="Green">
                <color rgba="0.0 1.0 0.0 1.0"/>
            </material>
        </visual>
        <collision>
            <origin xyz="0.0 0.15 0.0" rpy="0 0 0"/>
            <geometry>
                <box size="0.44 0.3 0.25" />
            </geometry>
        </collision>
    </link>
    <joint name="Part4_Part6" type="revolute">
       <parent link="Part4"/>
       <child  link="Part6"/>
       <origin rpy="0 0 0" xyz="0.0 0.21 -0.275" />
     <axis xyz="1 0 0"/>
       <limit effort="0.0" lower="-3.14159" upper="3.14159" velocity="0.0"/>
    </joint>
    <link name="Part6">
        <inertial>
            <origin xyz="0.0 0.15 0.0" rpy="0 0 0"/>
            <mass value="1" />
            <inertia ixx="100" ixy="0" ixz="0" iyy="100" iyz="0" izz="100" />
        </inertial>
        <visual>
            <origin xyz="0.0 0.15 0.0" rpy="0 0 0"/>
            <geometry>
                <box size="0.44 0.3 0.25" />
            </geometry>
            <material name="Green">
                <color rgba="0.0 1.0 0.0 1.0"/>
            </material>
        </visual>
        <collision>
            <origin xyz="0.0 0.15 0.0" rpy="0 0 0"/>
            <geometry>
                <box size="0.44 0.3 0.25" />
            </geometry>
        </collision>
    </link>
</robot>