<robot name = "robot">
    <link name="Part0">
        <inertial>
            <origin xyz="0 0 0.28" rpy="0 0 0"/>
            <mass value="1" />
            <inertia ixx="100" ixy="0" ixz="0" iyy="100" iyz="0" izz="100" />
        </inertial>
        <visual>
            <origin xyz="0 0 0.28" rpy="0 0 0"/>
            <geometry>
                <box size="0.74 0.52 0.56" />
            </geometry>
            <material name="Green">
                <color rgba="0.0 1.0 0.0 1.0"/>
            </material>
        </visual>
        <collision>
            <origin xyz="0 0 0.28" rpy="0 0 0"/>
            <geometry>
                <box size="0.74 0.52 0.56" />
            </geometry>
        </collision>
    </link>
    <joint name="Part0_Part1" type="revolute">
       <parent link="Part0"/>
       <child  link="Part1"/>
       <origin rpy="0 0 0" xyz="0.0 0.0 0.56" />
     <axis xyz="0 1 0"/>
       <limit effort="0.0" lower="-3.14159" upper="3.14159" velocity="0.0"/>
    </joint>
    <link name="Part1">
        <inertial>
            <origin xyz="0.0 0.0 0.445" rpy="0 0 0"/>
            <mass value="1" />
            <inertia ixx="100" ixy="0" ixz="0" iyy="100" iyz="0" izz="100" />
        </inertial>
        <visual>
            <origin xyz="0.0 0.0 0.445" rpy="0 0 0"/>
            <geometry>
                <box size="0.92 0.26 0.89" />
            </geometry>
            <material name="Blue">
                <color rgba="0.0 0.5 1.0 1.0"/>
            </material>
        </visual>
        <collision>
            <origin xyz="0.0 0.0 0.445" rpy="0 0 0"/>
            <geometry>
                <box size="0.92 0.26 0.89" />
            </geometry>
        </collision>
    </link>
    <joint name="Part1_Part2" type="revolute">
       <parent link="Part1"/>
       <child  link="Part2"/>
       <origin rpy="0 0 0" xyz="-0.46 0.0 0.445" />
     <axis xyz="0 0 1"/>
       <limit effort="0.0" lower="-3.14159" upper="3.14159" velocity="0.0"/>
    </joint>
    <link name="Part2">
        <inertial>
            <origin xyz="-0.165 0.0 0.0" rpy="0 0 0"/>
            <mass value="1" />
            <inertia ixx="100" ixy="0" ixz="0" iyy="100" iyz="0" izz="100" />
        </inertial>
        <visual>
            <origin xyz="-0.165 0.0 0.0" rpy="0 0 0"/>
            <geometry>
                <box size="0.33 0.63 0.51" />
            </geometry>
            <material name="Blue">
                <color rgba="0.0 0.5 1.0 1.0"/>
            </material>
        </visual>
        <collision>
            <origin xyz="-0.165 0.0 0.0" rpy="0 0 0"/>
            <geometry>
                <box size="0.33 0.63 0.51" />
            </geometry>
        </collision>
    </link>
    <joint name="Part2_Part3" type="revolute">
       <parent link="Part2"/>
       <child  link="Part3"/>
       <origin rpy="0 0 0" xyz="-0.165 0.0 0.255" />
     <axis xyz="0 1 0"/>
       <limit effort="0.0" lower="-3.14159" upper="3.14159" velocity="0.0"/>
    </joint>
    <link name="Part3">
        <inertial>
            <origin xyz="0.0 0.0 0.24" rpy="0 0 0"/>
            <mass value="1" />
            <inertia ixx="100" ixy="0" ixz="0" iyy="100" iyz="0" izz="100" />
        </inertial>
        <visual>
            <origin xyz="0.0 0.0 0.24" rpy="0 0 0"/>
            <geometry>
                <box size="0.51 0.65 0.48" />
            </geometry>
            <material name="Blue">
                <color rgba="0.0 0.5 1.0 1.0"/>
            </material>
        </visual>
        <collision>
            <origin xyz="0.0 0.0 0.24" rpy="0 0 0"/>
            <geometry>
                <box size="0.51 0.65 0.48" />
            </geometry>
        </collision>
    </link>
    <joint name="Part0_Part4" type="revolute">
       <parent link="Part0"/>
       <child  link="Part4"/>
       <origin rpy="0 0 0" xyz="0.0 0.26 0.28" />
     <axis xyz="0 0 1"/>
       <limit effort="0.0" lower="-3.14159" upper="3.14159" velocity="0.0"/>
    </joint>
    <link name="Part4">
        <inertial>
            <origin xyz="0.0 0.195 0.0" rpy="0 0 0"/>
            <mass value="1" />
            <inertia ixx="100" ixy="0" ixz="0" iyy="100" iyz="0" izz="100" />
        </inertial>
        <visual>
            <origin xyz="0.0 0.195 0.0" rpy="0 0 0"/>
            <geometry>
                <box size="0.39 0.39 0.51" />
            </geometry>
            <material name="Green">
                <color rgba="0.0 1.0 0.0 1.0"/>
            </material>
        </visual>
        <collision>
            <origin xyz="0.0 0.195 0.0" rpy="0 0 0"/>
            <geometry>
                <box size="0.39 0.39 0.51" />
            </geometry>
        </collision>
    </link>
    <joint name="Part2_Part5" type="revolute">
       <parent link="Part2"/>
       <child  link="Part5"/>
       <origin rpy="0 0 0" xyz="-0.165 0.0 0.255" />
     <axis xyz="0 0 1"/>
       <limit effort="0.0" lower="-3.14159" upper="3.14159" velocity="0.0"/>
    </joint>
    <link name="Part5">
        <inertial>
            <origin xyz="0.0 0.0 0.475" rpy="0 0 0"/>
            <mass value="1" />
            <inertia ixx="100" ixy="0" ixz="0" iyy="100" iyz="0" izz="100" />
        </inertial>
        <visual>
            <origin xyz="0.0 0.0 0.475" rpy="0 0 0"/>
            <geometry>
                <box size="0.98 0.62 0.95" />
            </geometry>
            <material name="Blue">
                <color rgba="0.0 0.5 1.0 1.0"/>
            </material>
        </visual>
        <collision>
            <origin xyz="0.0 0.0 0.475" rpy="0 0 0"/>
            <geometry>
                <box size="0.98 0.62 0.95" />
            </geometry>
        </collision>
    </link>
    <joint name="Part1_Part6" type="revolute">
       <parent link="Part1"/>
       <child  link="Part6"/>
       <origin rpy="0 0 0" xyz="0.0 0.13 0.445" />
     <axis xyz="1 0 0"/>
       <limit effort="0.0" lower="-3.14159" upper="3.14159" velocity="0.0"/>
    </joint>
    <link name="Part6">
        <inertial>
            <origin xyz="0.0 0.15 0.0" rpy="0 0 0"/>
            <mass value="1" />
            <inertia ixx="100" ixy="0" ixz="0" iyy="100" iyz="0" izz="100" />
        </inertial>
        <visual>
            <origin xyz="0.0 0.15 0.0" rpy="0 0 0"/>
            <geometry>
                <box size="0.71 0.3 0.86" />
            </geometry>
            <material name="Blue">
                <color rgba="0.0 0.5 1.0 1.0"/>
            </material>
        </visual>
        <collision>
            <origin xyz="0.0 0.15 0.0" rpy="0 0 0"/>
            <geometry>
                <box size="0.71 0.3 0.86" />
            </geometry>
        </collision>
    </link>
</robot>