<robot name = "robot">
    <link name="Part0">
        <inertial>
            <origin xyz="0 0 0.87" rpy="0 0 0"/>
            <mass value="1" />
            <inertia ixx="100" ixy="0" ixz="0" iyy="100" iyz="0" izz="100" />
        </inertial>
        <visual>
            <origin xyz="0 0 0.87" rpy="0 0 0"/>
            <geometry>
                <box size="0.78 0.49 0.32" />
            </geometry>
            <material name="Blue">
                <color rgba="0.0 0.5 1.0 1.0"/>
            </material>
        </visual>
        <collision>
            <origin xyz="0 0 0.87" rpy="0 0 0"/>
            <geometry>
                <box size="0.78 0.49 0.32" />
            </geometry>
        </collision>
    </link>
    <joint name="Part0_Part1" type="revolute">
       <parent link="Part0"/>
       <child  link="Part1"/>
       <origin rpy="0 0 0" xyz="0.0 0.0 1.03" />
     <axis xyz="1 0 0"/>
       <limit effort="0.0" lower="-3.14159" upper="3.14159" velocity="0.0"/>
    </joint>
    <link name="Part1">
        <inertial>
            <origin xyz="0.0 0.0 0.375" rpy="0 0 0"/>
            <mass value="1" />
            <inertia ixx="100" ixy="0" ixz="0" iyy="100" iyz="0" izz="100" />
        </inertial>
        <visual>
            <origin xyz="0.0 0.0 0.375" rpy="0 0 0"/>
            <geometry>
                <box size="0.97 0.43 0.75" />
            </geometry>
            <material name="Green">
                <color rgba="0.0 1.0 0.0 1.0"/>
            </material>
        </visual>
        <collision>
            <origin xyz="0.0 0.0 0.375" rpy="0 0 0"/>
            <geometry>
                <box size="0.97 0.43 0.75" />
            </geometry>
        </collision>
    </link>
    <joint name="Part0_Part2" type="revolute">
       <parent link="Part0"/>
       <child  link="Part2"/>
       <origin rpy="0 0 0" xyz="0.0 -0.245 0.87" />
     <axis xyz="0 0 1"/>
       <limit effort="0.0" lower="-3.14159" upper="3.14159" velocity="0.0"/>
    </joint>
    <link name="Part2">
        <inertial>
            <origin xyz="0.0 -0.325 0.0" rpy="0 0 0"/>
            <mass value="1" />
            <inertia ixx="100" ixy="0" ixz="0" iyy="100" iyz="0" izz="100" />
        </inertial>
        <visual>
            <origin xyz="0.0 -0.325 0.0" rpy="0 0 0"/>
            <geometry>
                <box size="0.69 0.65 0.7" />
            </geometry>
            <material name="Blue">
                <color rgba="0.0 0.5 1.0 1.0"/>
            </material>
        </visual>
        <collision>
            <origin xyz="0.0 -0.325 0.0" rpy="0 0 0"/>
            <geometry>
                <box size="0.69 0.65 0.7" />
            </geometry>
        </collision>
    </link>
    <joint name="Part1_Part3" type="revolute">
       <parent link="Part1"/>
       <child  link="Part3"/>
       <origin rpy="0 0 0" xyz="0.0 0.0 0.75" />
     <axis xyz="0 0 1"/>
       <limit effort="0.0" lower="-3.14159" upper="3.14159" velocity="0.0"/>
    </joint>
    <link name="Part3">
        <inertial>
            <origin xyz="0.0 0.0 0.25" rpy="0 0 0"/>
            <mass value="1" />
            <inertia ixx="100" ixy="0" ixz="0" iyy="100" iyz="0" izz="100" />
        </inertial>
        <visual>
            <origin xyz="0.0 0.0 0.25" rpy="0 0 0"/>
            <geometry>
                <box size="0.43 0.98 0.5" />
            </geometry>
            <material name="Blue">
                <color rgba="0.0 0.5 1.0 1.0"/>
            </material>
        </visual>
        <collision>
            <origin xyz="0.0 0.0 0.25" rpy="0 0 0"/>
            <geometry>
                <box size="0.43 0.98 0.5" />
            </geometry>
        </collision>
    </link>
    <joint name="Part1_Part4" type="revolute">
       <parent link="Part1"/>
       <child  link="Part4"/>
       <origin rpy="0 0 0" xyz="-0.485 0.0 0.375" />
     <axis xyz="0 1 0"/>
       <limit effort="0.0" lower="-3.14159" upper="3.14159" velocity="0.0"/>
    </joint>
    <link name="Part4">
        <inertial>
            <origin xyz="-0.445 0.0 0.0" rpy="0 0 0"/>
            <mass value="1" />
            <inertia ixx="100" ixy="0" ixz="0" iyy="100" iyz="0" izz="100" />
        </inertial>
        <visual>
            <origin xyz="-0.445 0.0 0.0" rpy="0 0 0"/>
            <geometry>
                <box size="0.89 0.84 0.46" />
            </geometry>
            <material name="Blue">
                <color rgba="0.0 0.5 1.0 1.0"/>
            </material>
        </visual>
        <collision>
            <origin xyz="-0.445 0.0 0.0" rpy="0 0 0"/>
            <geometry>
                <box size="0.89 0.84 0.46" />
            </geometry>
        </collision>
    </link>
    <joint name="Part2_Part5" type="revolute">
       <parent link="Part2"/>
       <child  link="Part5"/>
       <origin rpy="0 0 0" xyz="0.0 -0.325 -0.35" />
     <axis xyz="0 1 0"/>
       <limit effort="0.0" lower="-3.14159" upper="3.14159" velocity="0.0"/>
    </joint>
    <link name="Part5">
        <inertial>
            <origin xyz="0.0 0.0 -0.26" rpy="0 0 0"/>
            <mass value="1" />
            <inertia ixx="100" ixy="0" ixz="0" iyy="100" iyz="0" izz="100" />
        </inertial>
        <visual>
            <origin xyz="0.0 0.0 -0.26" rpy="0 0 0"/>
            <geometry>
                <box size="0.6 0.37 0.52" />
            </geometry>
            <material name="Blue">
                <color rgba="0.0 0.5 1.0 1.0"/>
            </material>
        </visual>
        <collision>
            <origin xyz="0.0 0.0 -0.26" rpy="0 0 0"/>
            <geometry>
                <box size="0.6 0.37 0.52" />
            </geometry>
        </collision>
    </link>
    <joint name="Part1_Part6" type="revolute">
       <parent link="Part1"/>
       <child  link="Part6"/>
       <origin rpy="0 0 0" xyz="0.485 0.0 0.375" />
     <axis xyz="1 0 0"/>
       <limit effort="0.0" lower="-3.14159" upper="3.14159" velocity="0.0"/>
    </joint>
    <link name="Part6">
        <inertial>
            <origin xyz="0.345 0.0 0.0" rpy="0 0 0"/>
            <mass value="1" />
            <inertia ixx="100" ixy="0" ixz="0" iyy="100" iyz="0" izz="100" />
        </inertial>
        <visual>
            <origin xyz="0.345 0.0 0.0" rpy="0 0 0"/>
            <geometry>
                <box size="0.69 0.81 0.62" />
            </geometry>
            <material name="Green">
                <color rgba="0.0 1.0 0.0 1.0"/>
            </material>
        </visual>
        <collision>
            <origin xyz="0.345 0.0 0.0" rpy="0 0 0"/>
            <geometry>
                <box size="0.69 0.81 0.62" />
            </geometry>
        </collision>
    </link>
    <joint name="Part3_Part7" type="revolute">
       <parent link="Part3"/>
       <child  link="Part7"/>
       <origin rpy="0 0 0" xyz="0.0 0.49 0.25" />
     <axis xyz="0 0 1"/>
       <limit effort="0.0" lower="-3.14159" upper="3.14159" velocity="0.0"/>
    </joint>
    <link name="Part7">
        <inertial>
            <origin xyz="0.0 0.38 0.0" rpy="0 0 0"/>
            <mass value="1" />
            <inertia ixx="100" ixy="0" ixz="0" iyy="100" iyz="0" izz="100" />
        </inertial>
        <visual>
            <origin xyz="0.0 0.38 0.0" rpy="0 0 0"/>
            <geometry>
                <box size="0.74 0.76 0.69" />
            </geometry>
            <material name="Blue">
                <color rgba="0.0 0.5 1.0 1.0"/>
            </material>
        </visual>
        <collision>
            <origin xyz="0.0 0.38 0.0" rpy="0 0 0"/>
            <geometry>
                <box size="0.74 0.76 0.69" />
            </geometry>
        </collision>
    </link>
    <joint name="Part6_Part8" type="revolute">
       <parent link="Part6"/>
       <child  link="Part8"/>
       <origin rpy="0 0 0" xyz="0.69 0.0 0.0" />
     <axis xyz="0 0 1"/>
       <limit effort="0.0" lower="-3.14159" upper="3.14159" velocity="0.0"/>
    </joint>
    <link name="Part8">
        <inertial>
            <origin xyz="0.145 0.0 0.0" rpy="0 0 0"/>
            <mass value="1" />
            <inertia ixx="100" ixy="0" ixz="0" iyy="100" iyz="0" izz="100" />
        </inertial>
        <visual>
            <origin xyz="0.145 0.0 0.0" rpy="0 0 0"/>
            <geometry>
                <box size="0.29 0.61 0.39" />
            </geometry>
            <material name="Blue">
                <color rgba="0.0 0.5 1.0 1.0"/>
            </material>
        </visual>
        <collision>
            <origin xyz="0.145 0.0 0.0" rpy="0 0 0"/>
            <geometry>
                <box size="0.29 0.61 0.39" />
            </geometry>
        </collision>
    </link>
    <joint name="Part4_Part9" type="revolute">
       <parent link="Part4"/>
       <child  link="Part9"/>
       <origin rpy="0 0 0" xyz="-0.445 0.0 -0.23" />
     <axis xyz="0 0 1"/>
       <limit effort="0.0" lower="-3.14159" upper="3.14159" velocity="0.0"/>
    </joint>
    <link name="Part9">
        <inertial>
            <origin xyz="0.0 0.0 -0.225" rpy="0 0 0"/>
            <mass value="1" />
            <inertia ixx="100" ixy="0" ixz="0" iyy="100" iyz="0" izz="100" />
        </inertial>
        <visual>
            <origin xyz="0.0 0.0 -0.225" rpy="0 0 0"/>
            <geometry>
                <box size="0.78 0.67 0.45" />
            </geometry>
            <material name="Blue">
                <color rgba="0.0 0.5 1.0 1.0"/>
            </material>
        </visual>
        <collision>
            <origin xyz="0.0 0.0 -0.225" rpy="0 0 0"/>
            <geometry>
                <box size="0.78 0.67 0.45" />
            </geometry>
        </collision>
    </link>
    <joint name="Part4_Part10" type="revolute">
       <parent link="Part4"/>
       <child  link="Part10"/>
       <origin rpy="0 0 0" xyz="-0.445 -0.42 0.0" />
     <axis xyz="1 0 0"/>
       <limit effort="0.0" lower="-3.14159" upper="3.14159" velocity="0.0"/>
    </joint>
    <link name="Part10">
        <inertial>
            <origin xyz="0.0 -0.225 0.0" rpy="0 0 0"/>
            <mass value="1" />
            <inertia ixx="100" ixy="0" ixz="0" iyy="100" iyz="0" izz="100" />
        </inertial>
        <visual>
            <origin xyz="0.0 -0.225 0.0" rpy="0 0 0"/>
            <geometry>
                <box size="0.42 0.45 0.83" />
            </geometry>
            <material name="Blue">
                <color rgba="0.0 0.5 1.0 1.0"/>
            </material>
        </visual>
        <collision>
            <origin xyz="0.0 -0.225 0.0" rpy="0 0 0"/>
            <geometry>
                <box size="0.42 0.45 0.83" />
            </geometry>
        </collision>
    </link>
    <joint name="Part9_Part11" type="revolute">
       <parent link="Part9"/>
       <child  link="Part11"/>
       <origin rpy="0 0 0" xyz="0.0 0.0 -0.45" />
     <axis xyz="0 0 1"/>
       <limit effort="0.0" lower="-3.14159" upper="3.14159" velocity="0.0"/>
    </joint>
    <link name="Part11">
        <inertial>
            <origin xyz="0.0 0.0 -0.275" rpy="0 0 0"/>
            <mass value="1" />
            <inertia ixx="100" ixy="0" ixz="0" iyy="100" iyz="0" izz="100" />
        </inertial>
        <visual>
            <origin xyz="0.0 0.0 -0.275" rpy="0 0 0"/>
            <geometry>
                <box size="0.44 0.35 0.55" />
            </geometry>
            <material name="Blue">
                <color rgba="0.0 0.5 1.0 1.0"/>
            </material>
        </visual>
        <collision>
            <origin xyz="0.0 0.0 -0.275" rpy="0 0 0"/>
            <geometry>
                <box size="0.44 0.35 0.55" />
            </geometry>
        </collision>
    </link>
</robot>